ERROR - 2025-06-28 00:02:24 --> ErrorException: pg_query(): Query failed: ERROR:  no existe la relación «estado_licencia»
LINE 2: FROM "estado_licencia"
             ^ in C:\xampp\htdocs\dfpyme\system\Database\Postgre\Connection.php:135
Stack trace:
#0 [internal function]: CodeIgniter\Debug\Exceptions->errorHandler(2, 'pg_query(): Que...', 'C:\\xampp\\htdocs...', 135)
#1 C:\xampp\htdocs\dfpyme\system\Database\Postgre\Connection.php(135): pg_query(Resource id #190, 'SELECT "id_clie...')
#2 C:\xampp\htdocs\dfpyme\system\Database\BaseConnection.php(670): CodeIgniter\Database\Postgre\Connection->execute('SELECT "id_clie...')
#3 C:\xampp\htdocs\dfpyme\system\Database\BaseConnection.php(598): CodeIgniter\Database\BaseConnection->simpleQuery('SELECT "id_clie...')
#4 C:\xampp\htdocs\dfpyme\system\Database\BaseBuilder.php(1455): CodeIgniter\Database\BaseConnection->query('SELECT "id_clie...', Array, false)
#5 C:\xampp\htdocs\dfpyme\system\Model.php(210): CodeIgniter\Database\BaseBuilder->get()
#6 C:\xampp\htdocs\dfpyme\system\BaseModel.php(622): CodeIgniter\Model->doFirst()
#7 C:\xampp\htdocs\dfpyme\app\Commands\SyncLicencias.php(20): CodeIgniter\BaseModel->first()
#8 C:\xampp\htdocs\dfpyme\system\CLI\Commands.php(63): App\Commands\SyncLicencias->run(Array)
#9 C:\xampp\htdocs\dfpyme\system\CLI\CommandRunner.php(70): CodeIgniter\CLI\Commands->run('sync:licencias', Array)
#10 C:\xampp\htdocs\dfpyme\system\CLI\CommandRunner.php(56): CodeIgniter\CLI\CommandRunner->index(Array)
#11 C:\xampp\htdocs\dfpyme\system\CodeIgniter.php(830): CodeIgniter\CLI\CommandRunner->_remap('index', 'sync:licencias')
#12 C:\xampp\htdocs\dfpyme\system\CodeIgniter.php(419): CodeIgniter\CodeIgniter->runController(Object(CodeIgniter\CLI\CommandRunner))
#13 C:\xampp\htdocs\dfpyme\system\CodeIgniter.php(326): CodeIgniter\CodeIgniter->handleRequest(NULL, Object(Config\Cache), false)
#14 C:\xampp\htdocs\dfpyme\system\CLI\Console.php(48): CodeIgniter\CodeIgniter->run()
#15 C:\xampp\htdocs\dfpyme\spark(63): CodeIgniter\CLI\Console->run()
#16 {main}
CRITICAL - 2025-06-28 00:02:24 --> pg_query(): Query failed: ERROR:  no existe la relación «estado_licencia»
LINE 2: FROM "estado_licencia"
             ^
#0 [internal function]: CodeIgniter\Debug\Exceptions->errorHandler(2, 'pg_query(): Que...', 'C:\\xampp\\htdocs...', 135)
#1 C:\xampp\htdocs\dfpyme\system\Database\Postgre\Connection.php(135): pg_query(Resource id #190, 'SELECT "id_clie...')
#2 C:\xampp\htdocs\dfpyme\system\Database\BaseConnection.php(670): CodeIgniter\Database\Postgre\Connection->execute('SELECT "id_clie...')
#3 C:\xampp\htdocs\dfpyme\system\Database\BaseConnection.php(598): CodeIgniter\Database\BaseConnection->simpleQuery('SELECT "id_clie...')
#4 C:\xampp\htdocs\dfpyme\system\Database\BaseBuilder.php(1455): CodeIgniter\Database\BaseConnection->query('SELECT "id_clie...', Array, false)
#5 C:\xampp\htdocs\dfpyme\system\Model.php(210): CodeIgniter\Database\BaseBuilder->get()
#6 C:\xampp\htdocs\dfpyme\system\BaseModel.php(622): CodeIgniter\Model->doFirst()
#7 C:\xampp\htdocs\dfpyme\app\Commands\SyncLicencias.php(20): CodeIgniter\BaseModel->first()
#8 C:\xampp\htdocs\dfpyme\system\CLI\Commands.php(63): App\Commands\SyncLicencias->run(Array)
#9 C:\xampp\htdocs\dfpyme\system\CLI\CommandRunner.php(70): CodeIgniter\CLI\Commands->run('sync:licencias', Array)
#10 C:\xampp\htdocs\dfpyme\system\CLI\CommandRunner.php(56): CodeIgniter\CLI\CommandRunner->index(Array)
#11 C:\xampp\htdocs\dfpyme\system\CodeIgniter.php(830): CodeIgniter\CLI\CommandRunner->_remap('index', 'sync:licencias')
#12 C:\xampp\htdocs\dfpyme\system\CodeIgniter.php(419): CodeIgniter\CodeIgniter->runController(Object(CodeIgniter\CLI\CommandRunner))
#13 C:\xampp\htdocs\dfpyme\system\CodeIgniter.php(326): CodeIgniter\CodeIgniter->handleRequest(NULL, Object(Config\Cache), false)
#14 C:\xampp\htdocs\dfpyme\system\CLI\Console.php(48): CodeIgniter\CodeIgniter->run()
#15 C:\xampp\htdocs\dfpyme\spark(63): CodeIgniter\CLI\Console->run()
#16 {main}
ERROR - 2025-06-28 00:07:24 --> ErrorException: pg_query(): Query failed: ERROR:  no existe la relación «estado_licencia»
LINE 2: FROM "estado_licencia"
             ^ in C:\xampp\htdocs\dfpyme\system\Database\Postgre\Connection.php:135
Stack trace:
#0 [internal function]: CodeIgniter\Debug\Exceptions->errorHandler(2, 'pg_query(): Que...', 'C:\\xampp\\htdocs...', 135)
#1 C:\xampp\htdocs\dfpyme\system\Database\Postgre\Connection.php(135): pg_query(Resource id #190, 'SELECT "id_clie...')
#2 C:\xampp\htdocs\dfpyme\system\Database\BaseConnection.php(670): CodeIgniter\Database\Postgre\Connection->execute('SELECT "id_clie...')
#3 C:\xampp\htdocs\dfpyme\system\Database\BaseConnection.php(598): CodeIgniter\Database\BaseConnection->simpleQuery('SELECT "id_clie...')
#4 C:\xampp\htdocs\dfpyme\system\Database\BaseBuilder.php(1455): CodeIgniter\Database\BaseConnection->query('SELECT "id_clie...', Array, false)
#5 C:\xampp\htdocs\dfpyme\system\Model.php(210): CodeIgniter\Database\BaseBuilder->get()
#6 C:\xampp\htdocs\dfpyme\system\BaseModel.php(622): CodeIgniter\Model->doFirst()
#7 C:\xampp\htdocs\dfpyme\app\Commands\SyncLicencias.php(20): CodeIgniter\BaseModel->first()
#8 C:\xampp\htdocs\dfpyme\system\CLI\Commands.php(63): App\Commands\SyncLicencias->run(Array)
#9 C:\xampp\htdocs\dfpyme\system\CLI\CommandRunner.php(70): CodeIgniter\CLI\Commands->run('sync:licencias', Array)
#10 C:\xampp\htdocs\dfpyme\system\CLI\CommandRunner.php(56): CodeIgniter\CLI\CommandRunner->index(Array)
#11 C:\xampp\htdocs\dfpyme\system\CodeIgniter.php(830): CodeIgniter\CLI\CommandRunner->_remap('index', 'sync:licencias')
#12 C:\xampp\htdocs\dfpyme\system\CodeIgniter.php(419): CodeIgniter\CodeIgniter->runController(Object(CodeIgniter\CLI\CommandRunner))
#13 C:\xampp\htdocs\dfpyme\system\CodeIgniter.php(326): CodeIgniter\CodeIgniter->handleRequest(NULL, Object(Config\Cache), false)
#14 C:\xampp\htdocs\dfpyme\system\CLI\Console.php(48): CodeIgniter\CodeIgniter->run()
#15 C:\xampp\htdocs\dfpyme\spark(63): CodeIgniter\CLI\Console->run()
#16 {main}
CRITICAL - 2025-06-28 00:07:24 --> pg_query(): Query failed: ERROR:  no existe la relación «estado_licencia»
LINE 2: FROM "estado_licencia"
             ^
#0 [internal function]: CodeIgniter\Debug\Exceptions->errorHandler(2, 'pg_query(): Que...', 'C:\\xampp\\htdocs...', 135)
#1 C:\xampp\htdocs\dfpyme\system\Database\Postgre\Connection.php(135): pg_query(Resource id #190, 'SELECT "id_clie...')
#2 C:\xampp\htdocs\dfpyme\system\Database\BaseConnection.php(670): CodeIgniter\Database\Postgre\Connection->execute('SELECT "id_clie...')
#3 C:\xampp\htdocs\dfpyme\system\Database\BaseConnection.php(598): CodeIgniter\Database\BaseConnection->simpleQuery('SELECT "id_clie...')
#4 C:\xampp\htdocs\dfpyme\system\Database\BaseBuilder.php(1455): CodeIgniter\Database\BaseConnection->query('SELECT "id_clie...', Array, false)
#5 C:\xampp\htdocs\dfpyme\system\Model.php(210): CodeIgniter\Database\BaseBuilder->get()
#6 C:\xampp\htdocs\dfpyme\system\BaseModel.php(622): CodeIgniter\Model->doFirst()
#7 C:\xampp\htdocs\dfpyme\app\Commands\SyncLicencias.php(20): CodeIgniter\BaseModel->first()
#8 C:\xampp\htdocs\dfpyme\system\CLI\Commands.php(63): App\Commands\SyncLicencias->run(Array)
#9 C:\xampp\htdocs\dfpyme\system\CLI\CommandRunner.php(70): CodeIgniter\CLI\Commands->run('sync:licencias', Array)
#10 C:\xampp\htdocs\dfpyme\system\CLI\CommandRunner.php(56): CodeIgniter\CLI\CommandRunner->index(Array)
#11 C:\xampp\htdocs\dfpyme\system\CodeIgniter.php(830): CodeIgniter\CLI\CommandRunner->_remap('index', 'sync:licencias')
#12 C:\xampp\htdocs\dfpyme\system\CodeIgniter.php(419): CodeIgniter\CodeIgniter->runController(Object(CodeIgniter\CLI\CommandRunner))
#13 C:\xampp\htdocs\dfpyme\system\CodeIgniter.php(326): CodeIgniter\CodeIgniter->handleRequest(NULL, Object(Config\Cache), false)
#14 C:\xampp\htdocs\dfpyme\system\CLI\Console.php(48): CodeIgniter\CodeIgniter->run()
#15 C:\xampp\htdocs\dfpyme\spark(63): CodeIgniter\CLI\Console->run()
#16 {main}
ERROR - 2025-06-28 12:19:05 --> ErrorException: pg_query(): Query failed: ERROR:  no existe la relación «estado_licencia»
LINE 2: FROM &quot;estado_licencia&quot;
             ^ in C:\xampp\htdocs\dfpyme\system\Database\Postgre\Connection.php:135
Stack trace:
#0 [internal function]: CodeIgniter\Debug\Exceptions->errorHandler(2, 'pg_query(): Que...', 'C:\\xampp\\htdocs...', 135)
#1 C:\xampp\htdocs\dfpyme\system\Database\Postgre\Connection.php(135): pg_query(Resource id #148, 'SELECT "estado_...')
#2 C:\xampp\htdocs\dfpyme\system\Database\BaseConnection.php(670): CodeIgniter\Database\Postgre\Connection->execute('SELECT "estado_...')
#3 C:\xampp\htdocs\dfpyme\system\Database\BaseConnection.php(598): CodeIgniter\Database\BaseConnection->simpleQuery('SELECT "estado_...')
#4 C:\xampp\htdocs\dfpyme\system\Database\BaseBuilder.php(1455): CodeIgniter\Database\BaseConnection->query('SELECT "estado_...', Array, false)
#5 C:\xampp\htdocs\dfpyme\system\Model.php(210): CodeIgniter\Database\BaseBuilder->get()
#6 C:\xampp\htdocs\dfpyme\system\BaseModel.php(622): CodeIgniter\Model->doFirst()
#7 C:\xampp\htdocs\dfpyme\app\Controllers\login\loginController.php(32): CodeIgniter\BaseModel->first()
#8 C:\xampp\htdocs\dfpyme\system\CodeIgniter.php(832): App\Controllers\login\loginController->login()
#9 C:\xampp\htdocs\dfpyme\system\CodeIgniter.php(419): CodeIgniter\CodeIgniter->runController(Object(App\Controllers\login\loginController))
#10 C:\xampp\htdocs\dfpyme\system\CodeIgniter.php(326): CodeIgniter\CodeIgniter->handleRequest(NULL, Object(Config\Cache), false)
#11 C:\xampp\htdocs\dfpyme\index.php(37): CodeIgniter\CodeIgniter->run()
#12 {main}
CRITICAL - 2025-06-28 12:19:05 --> pg_query(): Query failed: ERROR:  no existe la relación «estado_licencia»
LINE 2: FROM &quot;estado_licencia&quot;
             ^
#0 [internal function]: CodeIgniter\Debug\Exceptions->errorHandler(2, 'pg_query(): Que...', 'C:\\xampp\\htdocs...', 135)
#1 C:\xampp\htdocs\dfpyme\system\Database\Postgre\Connection.php(135): pg_query(Resource id #148, 'SELECT "estado_...')
#2 C:\xampp\htdocs\dfpyme\system\Database\BaseConnection.php(670): CodeIgniter\Database\Postgre\Connection->execute('SELECT "estado_...')
#3 C:\xampp\htdocs\dfpyme\system\Database\BaseConnection.php(598): CodeIgniter\Database\BaseConnection->simpleQuery('SELECT "estado_...')
#4 C:\xampp\htdocs\dfpyme\system\Database\BaseBuilder.php(1455): CodeIgniter\Database\BaseConnection->query('SELECT "estado_...', Array, false)
#5 C:\xampp\htdocs\dfpyme\system\Model.php(210): CodeIgniter\Database\BaseBuilder->get()
#6 C:\xampp\htdocs\dfpyme\system\BaseModel.php(622): CodeIgniter\Model->doFirst()
#7 C:\xampp\htdocs\dfpyme\app\Controllers\login\loginController.php(32): CodeIgniter\BaseModel->first()
#8 C:\xampp\htdocs\dfpyme\system\CodeIgniter.php(832): App\Controllers\login\loginController->login()
#9 C:\xampp\htdocs\dfpyme\system\CodeIgniter.php(419): CodeIgniter\CodeIgniter->runController(Object(App\Controllers\login\loginController))
#10 C:\xampp\htdocs\dfpyme\system\CodeIgniter.php(326): CodeIgniter\CodeIgniter->handleRequest(NULL, Object(Config\Cache), false)
#11 C:\xampp\htdocs\dfpyme\index.php(37): CodeIgniter\CodeIgniter->run()
#12 {main}
ERROR - 2025-06-28 12:44:45 --> ErrorException: pg_query(): Query failed: ERROR:  la sintaxis de entrada no es válida para integer: «»
LINE 1: ... '10000', '0', '20309', 0, '222222222222', ('381'), '1', '')
                                                                    ^ in C:\xampp\htdocs\dfpyme\system\Database\Postgre\Connection.php:135
Stack trace:
#0 [internal function]: CodeIgniter\Debug\Exceptions->errorHandler(2, 'pg_query(): Que...', 'C:\\xampp\\htdocs...', 135)
#1 C:\xampp\htdocs\dfpyme\system\Database\Postgre\Connection.php(135): pg_query(Resource id #158, 'INSERT INTO "pa...')
#2 C:\xampp\htdocs\dfpyme\system\Database\BaseConnection.php(670): CodeIgniter\Database\Postgre\Connection->execute('INSERT INTO "pa...')
#3 C:\xampp\htdocs\dfpyme\system\Database\BaseConnection.php(598): CodeIgniter\Database\BaseConnection->simpleQuery('INSERT INTO "pa...')
#4 C:\xampp\htdocs\dfpyme\system\Database\BaseBuilder.php(1771): CodeIgniter\Database\BaseConnection->query('INSERT INTO "pa...', Array, false)
#5 C:\xampp\htdocs\dfpyme\system\Model.php(239): CodeIgniter\Database\BaseBuilder->insert()
#6 C:\xampp\htdocs\dfpyme\system\BaseModel.php(738): CodeIgniter\Model->doInsert(Array)
#7 C:\xampp\htdocs\dfpyme\system\Model.php(625): CodeIgniter\BaseModel->insert(Array, true)
#8 C:\xampp\htdocs\dfpyme\app\Controllers\factura_electronica\FacturaElectronica.php(498): CodeIgniter\Model->insert(Array)
#9 C:\xampp\htdocs\dfpyme\system\CodeIgniter.php(832): App\Controllers\factura_electronica\FacturaElectronica->pre_factura()
#10 C:\xampp\htdocs\dfpyme\system\CodeIgniter.php(419): CodeIgniter\CodeIgniter->runController(Object(App\Controllers\factura_electronica\FacturaElectronica))
#11 C:\xampp\htdocs\dfpyme\system\CodeIgniter.php(326): CodeIgniter\CodeIgniter->handleRequest(NULL, Object(Config\Cache), false)
#12 C:\xampp\htdocs\dfpyme\index.php(37): CodeIgniter\CodeIgniter->run()
#13 {main}
CRITICAL - 2025-06-28 12:44:45 --> pg_query(): Query failed: ERROR:  la sintaxis de entrada no es válida para integer: «»
LINE 1: ... '10000', '0', '20309', 0, '222222222222', ('381'), '1', '')
                                                                    ^
#0 [internal function]: CodeIgniter\Debug\Exceptions->errorHandler(2, 'pg_query(): Que...', 'C:\\xampp\\htdocs...', 135)
#1 C:\xampp\htdocs\dfpyme\system\Database\Postgre\Connection.php(135): pg_query(Resource id #158, 'INSERT INTO "pa...')
#2 C:\xampp\htdocs\dfpyme\system\Database\BaseConnection.php(670): CodeIgniter\Database\Postgre\Connection->execute('INSERT INTO "pa...')
#3 C:\xampp\htdocs\dfpyme\system\Database\BaseConnection.php(598): CodeIgniter\Database\BaseConnection->simpleQuery('INSERT INTO "pa...')
#4 C:\xampp\htdocs\dfpyme\system\Database\BaseBuilder.php(1771): CodeIgniter\Database\BaseConnection->query('INSERT INTO "pa...', Array, false)
#5 C:\xampp\htdocs\dfpyme\system\Model.php(239): CodeIgniter\Database\BaseBuilder->insert()
#6 C:\xampp\htdocs\dfpyme\system\BaseModel.php(738): CodeIgniter\Model->doInsert(Array)
#7 C:\xampp\htdocs\dfpyme\system\Model.php(625): CodeIgniter\BaseModel->insert(Array, true)
#8 C:\xampp\htdocs\dfpyme\app\Controllers\factura_electronica\FacturaElectronica.php(498): CodeIgniter\Model->insert(Array)
#9 C:\xampp\htdocs\dfpyme\system\CodeIgniter.php(832): App\Controllers\factura_electronica\FacturaElectronica->pre_factura()
#10 C:\xampp\htdocs\dfpyme\system\CodeIgniter.php(419): CodeIgniter\CodeIgniter->runController(Object(App\Controllers\factura_electronica\FacturaElectronica))
#11 C:\xampp\htdocs\dfpyme\system\CodeIgniter.php(326): CodeIgniter\CodeIgniter->handleRequest(NULL, Object(Config\Cache), false)
#12 C:\xampp\htdocs\dfpyme\index.php(37): CodeIgniter\CodeIgniter->run()
#13 {main}
CRITICAL - 2025-06-28 12:44:45 --> Uncaught CodeIgniter\Format\Exceptions\FormatException: Failed to parse json string, error: "Type is not supported". in C:\xampp\htdocs\dfpyme\system\Format\JSONFormatter.php:41
Stack trace:
#0 C:\xampp\htdocs\dfpyme\system\Format\JSONFormatter.php(41): CodeIgniter\Format\Exceptions\FormatException::forInvalidJSON('Type is not sup...')
#1 C:\xampp\htdocs\dfpyme\system\API\ResponseTrait.php(341): CodeIgniter\Format\JSONFormatter->format(Array)
#2 C:\xampp\htdocs\dfpyme\system\API\ResponseTrait.php(99): CodeIgniter\Debug\Exceptions->format(Array)
#3 C:\xampp\htdocs\dfpyme\system\Debug\Exceptions.php(115): CodeIgniter\Debug\Exceptions->respond(Array, 500)
#4 [internal function]: CodeIgniter\Debug\Exceptions->exceptionHandler(Object(ErrorException))
#5 {main}
  thrown
#0 [internal function]: CodeIgniter\Debug\Exceptions->shutdownHandler()
#1 {main}
ERROR - 2025-06-28 13:15:56 --> ErrorException: pg_query(): Query failed: ERROR:  la sintaxis de entrada no es válida para integer: «»
LINE 1: ... '10000', '0', '20310', 0, '222222222222', ('381'), '1', '')
                                                                    ^ in C:\xampp\htdocs\dfpyme\system\Database\Postgre\Connection.php:135
Stack trace:
#0 [internal function]: CodeIgniter\Debug\Exceptions->errorHandler(2, 'pg_query(): Que...', 'C:\\xampp\\htdocs...', 135)
#1 C:\xampp\htdocs\dfpyme\system\Database\Postgre\Connection.php(135): pg_query(Resource id #158, 'INSERT INTO "pa...')
#2 C:\xampp\htdocs\dfpyme\system\Database\BaseConnection.php(670): CodeIgniter\Database\Postgre\Connection->execute('INSERT INTO "pa...')
#3 C:\xampp\htdocs\dfpyme\system\Database\BaseConnection.php(598): CodeIgniter\Database\BaseConnection->simpleQuery('INSERT INTO "pa...')
#4 C:\xampp\htdocs\dfpyme\system\Database\BaseBuilder.php(1771): CodeIgniter\Database\BaseConnection->query('INSERT INTO "pa...', Array, false)
#5 C:\xampp\htdocs\dfpyme\system\Model.php(239): CodeIgniter\Database\BaseBuilder->insert()
#6 C:\xampp\htdocs\dfpyme\system\BaseModel.php(738): CodeIgniter\Model->doInsert(Array)
#7 C:\xampp\htdocs\dfpyme\system\Model.php(625): CodeIgniter\BaseModel->insert(Array, true)
#8 C:\xampp\htdocs\dfpyme\app\Controllers\factura_electronica\FacturaElectronica.php(498): CodeIgniter\Model->insert(Array)
#9 C:\xampp\htdocs\dfpyme\system\CodeIgniter.php(832): App\Controllers\factura_electronica\FacturaElectronica->pre_factura()
#10 C:\xampp\htdocs\dfpyme\system\CodeIgniter.php(419): CodeIgniter\CodeIgniter->runController(Object(App\Controllers\factura_electronica\FacturaElectronica))
#11 C:\xampp\htdocs\dfpyme\system\CodeIgniter.php(326): CodeIgniter\CodeIgniter->handleRequest(NULL, Object(Config\Cache), false)
#12 C:\xampp\htdocs\dfpyme\index.php(37): CodeIgniter\CodeIgniter->run()
#13 {main}
CRITICAL - 2025-06-28 13:15:56 --> pg_query(): Query failed: ERROR:  la sintaxis de entrada no es válida para integer: «»
LINE 1: ... '10000', '0', '20310', 0, '222222222222', ('381'), '1', '')
                                                                    ^
#0 [internal function]: CodeIgniter\Debug\Exceptions->errorHandler(2, 'pg_query(): Que...', 'C:\\xampp\\htdocs...', 135)
#1 C:\xampp\htdocs\dfpyme\system\Database\Postgre\Connection.php(135): pg_query(Resource id #158, 'INSERT INTO "pa...')
#2 C:\xampp\htdocs\dfpyme\system\Database\BaseConnection.php(670): CodeIgniter\Database\Postgre\Connection->execute('INSERT INTO "pa...')
#3 C:\xampp\htdocs\dfpyme\system\Database\BaseConnection.php(598): CodeIgniter\Database\BaseConnection->simpleQuery('INSERT INTO "pa...')
#4 C:\xampp\htdocs\dfpyme\system\Database\BaseBuilder.php(1771): CodeIgniter\Database\BaseConnection->query('INSERT INTO "pa...', Array, false)
#5 C:\xampp\htdocs\dfpyme\system\Model.php(239): CodeIgniter\Database\BaseBuilder->insert()
#6 C:\xampp\htdocs\dfpyme\system\BaseModel.php(738): CodeIgniter\Model->doInsert(Array)
#7 C:\xampp\htdocs\dfpyme\system\Model.php(625): CodeIgniter\BaseModel->insert(Array, true)
#8 C:\xampp\htdocs\dfpyme\app\Controllers\factura_electronica\FacturaElectronica.php(498): CodeIgniter\Model->insert(Array)
#9 C:\xampp\htdocs\dfpyme\system\CodeIgniter.php(832): App\Controllers\factura_electronica\FacturaElectronica->pre_factura()
#10 C:\xampp\htdocs\dfpyme\system\CodeIgniter.php(419): CodeIgniter\CodeIgniter->runController(Object(App\Controllers\factura_electronica\FacturaElectronica))
#11 C:\xampp\htdocs\dfpyme\system\CodeIgniter.php(326): CodeIgniter\CodeIgniter->handleRequest(NULL, Object(Config\Cache), false)
#12 C:\xampp\htdocs\dfpyme\index.php(37): CodeIgniter\CodeIgniter->run()
#13 {main}
CRITICAL - 2025-06-28 13:15:56 --> Uncaught CodeIgniter\Format\Exceptions\FormatException: Failed to parse json string, error: "Type is not supported". in C:\xampp\htdocs\dfpyme\system\Format\JSONFormatter.php:41
Stack trace:
#0 C:\xampp\htdocs\dfpyme\system\Format\JSONFormatter.php(41): CodeIgniter\Format\Exceptions\FormatException::forInvalidJSON('Type is not sup...')
#1 C:\xampp\htdocs\dfpyme\system\API\ResponseTrait.php(341): CodeIgniter\Format\JSONFormatter->format(Array)
#2 C:\xampp\htdocs\dfpyme\system\API\ResponseTrait.php(99): CodeIgniter\Debug\Exceptions->format(Array)
#3 C:\xampp\htdocs\dfpyme\system\Debug\Exceptions.php(115): CodeIgniter\Debug\Exceptions->respond(Array, 500)
#4 [internal function]: CodeIgniter\Debug\Exceptions->exceptionHandler(Object(ErrorException))
#5 {main}
  thrown
#0 [internal function]: CodeIgniter\Debug\Exceptions->shutdownHandler()
#1 {main}
ERROR - 2025-06-28 13:16:15 --> ErrorException: pg_query(): Query failed: ERROR:  la sintaxis de entrada no es válida para integer: «»
LINE 1: ... '10000', '0', '20311', 0, '222222222222', ('381'), '1', '')
                                                                    ^ in C:\xampp\htdocs\dfpyme\system\Database\Postgre\Connection.php:135
Stack trace:
#0 [internal function]: CodeIgniter\Debug\Exceptions->errorHandler(2, 'pg_query(): Que...', 'C:\\xampp\\htdocs...', 135)
#1 C:\xampp\htdocs\dfpyme\system\Database\Postgre\Connection.php(135): pg_query(Resource id #158, 'INSERT INTO "pa...')
#2 C:\xampp\htdocs\dfpyme\system\Database\BaseConnection.php(670): CodeIgniter\Database\Postgre\Connection->execute('INSERT INTO "pa...')
#3 C:\xampp\htdocs\dfpyme\system\Database\BaseConnection.php(598): CodeIgniter\Database\BaseConnection->simpleQuery('INSERT INTO "pa...')
#4 C:\xampp\htdocs\dfpyme\system\Database\BaseBuilder.php(1771): CodeIgniter\Database\BaseConnection->query('INSERT INTO "pa...', Array, false)
#5 C:\xampp\htdocs\dfpyme\system\Model.php(239): CodeIgniter\Database\BaseBuilder->insert()
#6 C:\xampp\htdocs\dfpyme\system\BaseModel.php(738): CodeIgniter\Model->doInsert(Array)
#7 C:\xampp\htdocs\dfpyme\system\Model.php(625): CodeIgniter\BaseModel->insert(Array, true)
#8 C:\xampp\htdocs\dfpyme\app\Controllers\factura_electronica\FacturaElectronica.php(498): CodeIgniter\Model->insert(Array)
#9 C:\xampp\htdocs\dfpyme\system\CodeIgniter.php(832): App\Controllers\factura_electronica\FacturaElectronica->pre_factura()
#10 C:\xampp\htdocs\dfpyme\system\CodeIgniter.php(419): CodeIgniter\CodeIgniter->runController(Object(App\Controllers\factura_electronica\FacturaElectronica))
#11 C:\xampp\htdocs\dfpyme\system\CodeIgniter.php(326): CodeIgniter\CodeIgniter->handleRequest(NULL, Object(Config\Cache), false)
#12 C:\xampp\htdocs\dfpyme\index.php(37): CodeIgniter\CodeIgniter->run()
#13 {main}
CRITICAL - 2025-06-28 13:16:15 --> pg_query(): Query failed: ERROR:  la sintaxis de entrada no es válida para integer: «»
LINE 1: ... '10000', '0', '20311', 0, '222222222222', ('381'), '1', '')
                                                                    ^
#0 [internal function]: CodeIgniter\Debug\Exceptions->errorHandler(2, 'pg_query(): Que...', 'C:\\xampp\\htdocs...', 135)
#1 C:\xampp\htdocs\dfpyme\system\Database\Postgre\Connection.php(135): pg_query(Resource id #158, 'INSERT INTO "pa...')
#2 C:\xampp\htdocs\dfpyme\system\Database\BaseConnection.php(670): CodeIgniter\Database\Postgre\Connection->execute('INSERT INTO "pa...')
#3 C:\xampp\htdocs\dfpyme\system\Database\BaseConnection.php(598): CodeIgniter\Database\BaseConnection->simpleQuery('INSERT INTO "pa...')
#4 C:\xampp\htdocs\dfpyme\system\Database\BaseBuilder.php(1771): CodeIgniter\Database\BaseConnection->query('INSERT INTO "pa...', Array, false)
#5 C:\xampp\htdocs\dfpyme\system\Model.php(239): CodeIgniter\Database\BaseBuilder->insert()
#6 C:\xampp\htdocs\dfpyme\system\BaseModel.php(738): CodeIgniter\Model->doInsert(Array)
#7 C:\xampp\htdocs\dfpyme\system\Model.php(625): CodeIgniter\BaseModel->insert(Array, true)
#8 C:\xampp\htdocs\dfpyme\app\Controllers\factura_electronica\FacturaElectronica.php(498): CodeIgniter\Model->insert(Array)
#9 C:\xampp\htdocs\dfpyme\system\CodeIgniter.php(832): App\Controllers\factura_electronica\FacturaElectronica->pre_factura()
#10 C:\xampp\htdocs\dfpyme\system\CodeIgniter.php(419): CodeIgniter\CodeIgniter->runController(Object(App\Controllers\factura_electronica\FacturaElectronica))
#11 C:\xampp\htdocs\dfpyme\system\CodeIgniter.php(326): CodeIgniter\CodeIgniter->handleRequest(NULL, Object(Config\Cache), false)
#12 C:\xampp\htdocs\dfpyme\index.php(37): CodeIgniter\CodeIgniter->run()
#13 {main}
CRITICAL - 2025-06-28 13:16:15 --> Uncaught CodeIgniter\Format\Exceptions\FormatException: Failed to parse json string, error: "Type is not supported". in C:\xampp\htdocs\dfpyme\system\Format\JSONFormatter.php:41
Stack trace:
#0 C:\xampp\htdocs\dfpyme\system\Format\JSONFormatter.php(41): CodeIgniter\Format\Exceptions\FormatException::forInvalidJSON('Type is not sup...')
#1 C:\xampp\htdocs\dfpyme\system\API\ResponseTrait.php(341): CodeIgniter\Format\JSONFormatter->format(Array)
#2 C:\xampp\htdocs\dfpyme\system\API\ResponseTrait.php(99): CodeIgniter\Debug\Exceptions->format(Array)
#3 C:\xampp\htdocs\dfpyme\system\Debug\Exceptions.php(115): CodeIgniter\Debug\Exceptions->respond(Array, 500)
#4 [internal function]: CodeIgniter\Debug\Exceptions->exceptionHandler(Object(ErrorException))
#5 {main}
  thrown
#0 [internal function]: CodeIgniter\Debug\Exceptions->shutdownHandler()
#1 {main}
ERROR - 2025-06-28 13:27:36 --> ErrorException: pg_query(): Query failed: ERROR:  la sintaxis de entrada no es válida para integer: «»
LINE 1: ... '14000', '0', '20313', 0, '222222222222', ('382'), '1', '')
                                                                    ^ in C:\xampp\htdocs\dfpyme\system\Database\Postgre\Connection.php:135
Stack trace:
#0 [internal function]: CodeIgniter\Debug\Exceptions->errorHandler(2, 'pg_query(): Que...', 'C:\\xampp\\htdocs...', 135)
#1 C:\xampp\htdocs\dfpyme\system\Database\Postgre\Connection.php(135): pg_query(Resource id #158, 'INSERT INTO "pa...')
#2 C:\xampp\htdocs\dfpyme\system\Database\BaseConnection.php(670): CodeIgniter\Database\Postgre\Connection->execute('INSERT INTO "pa...')
#3 C:\xampp\htdocs\dfpyme\system\Database\BaseConnection.php(598): CodeIgniter\Database\BaseConnection->simpleQuery('INSERT INTO "pa...')
#4 C:\xampp\htdocs\dfpyme\system\Database\BaseBuilder.php(1771): CodeIgniter\Database\BaseConnection->query('INSERT INTO "pa...', Array, false)
#5 C:\xampp\htdocs\dfpyme\system\Model.php(239): CodeIgniter\Database\BaseBuilder->insert()
#6 C:\xampp\htdocs\dfpyme\system\BaseModel.php(738): CodeIgniter\Model->doInsert(Array)
#7 C:\xampp\htdocs\dfpyme\system\Model.php(625): CodeIgniter\BaseModel->insert(Array, true)
#8 C:\xampp\htdocs\dfpyme\app\Controllers\factura_electronica\FacturaElectronica.php(498): CodeIgniter\Model->insert(Array)
#9 C:\xampp\htdocs\dfpyme\system\CodeIgniter.php(832): App\Controllers\factura_electronica\FacturaElectronica->pre_factura()
#10 C:\xampp\htdocs\dfpyme\system\CodeIgniter.php(419): CodeIgniter\CodeIgniter->runController(Object(App\Controllers\factura_electronica\FacturaElectronica))
#11 C:\xampp\htdocs\dfpyme\system\CodeIgniter.php(326): CodeIgniter\CodeIgniter->handleRequest(NULL, Object(Config\Cache), false)
#12 C:\xampp\htdocs\dfpyme\index.php(37): CodeIgniter\CodeIgniter->run()
#13 {main}
CRITICAL - 2025-06-28 13:27:36 --> pg_query(): Query failed: ERROR:  la sintaxis de entrada no es válida para integer: «»
LINE 1: ... '14000', '0', '20313', 0, '222222222222', ('382'), '1', '')
                                                                    ^
#0 [internal function]: CodeIgniter\Debug\Exceptions->errorHandler(2, 'pg_query(): Que...', 'C:\\xampp\\htdocs...', 135)
#1 C:\xampp\htdocs\dfpyme\system\Database\Postgre\Connection.php(135): pg_query(Resource id #158, 'INSERT INTO "pa...')
#2 C:\xampp\htdocs\dfpyme\system\Database\BaseConnection.php(670): CodeIgniter\Database\Postgre\Connection->execute('INSERT INTO "pa...')
#3 C:\xampp\htdocs\dfpyme\system\Database\BaseConnection.php(598): CodeIgniter\Database\BaseConnection->simpleQuery('INSERT INTO "pa...')
#4 C:\xampp\htdocs\dfpyme\system\Database\BaseBuilder.php(1771): CodeIgniter\Database\BaseConnection->query('INSERT INTO "pa...', Array, false)
#5 C:\xampp\htdocs\dfpyme\system\Model.php(239): CodeIgniter\Database\BaseBuilder->insert()
#6 C:\xampp\htdocs\dfpyme\system\BaseModel.php(738): CodeIgniter\Model->doInsert(Array)
#7 C:\xampp\htdocs\dfpyme\system\Model.php(625): CodeIgniter\BaseModel->insert(Array, true)
#8 C:\xampp\htdocs\dfpyme\app\Controllers\factura_electronica\FacturaElectronica.php(498): CodeIgniter\Model->insert(Array)
#9 C:\xampp\htdocs\dfpyme\system\CodeIgniter.php(832): App\Controllers\factura_electronica\FacturaElectronica->pre_factura()
#10 C:\xampp\htdocs\dfpyme\system\CodeIgniter.php(419): CodeIgniter\CodeIgniter->runController(Object(App\Controllers\factura_electronica\FacturaElectronica))
#11 C:\xampp\htdocs\dfpyme\system\CodeIgniter.php(326): CodeIgniter\CodeIgniter->handleRequest(NULL, Object(Config\Cache), false)
#12 C:\xampp\htdocs\dfpyme\index.php(37): CodeIgniter\CodeIgniter->run()
#13 {main}
CRITICAL - 2025-06-28 13:27:36 --> Uncaught CodeIgniter\Format\Exceptions\FormatException: Failed to parse json string, error: "Type is not supported". in C:\xampp\htdocs\dfpyme\system\Format\JSONFormatter.php:41
Stack trace:
#0 C:\xampp\htdocs\dfpyme\system\Format\JSONFormatter.php(41): CodeIgniter\Format\Exceptions\FormatException::forInvalidJSON('Type is not sup...')
#1 C:\xampp\htdocs\dfpyme\system\API\ResponseTrait.php(341): CodeIgniter\Format\JSONFormatter->format(Array)
#2 C:\xampp\htdocs\dfpyme\system\API\ResponseTrait.php(99): CodeIgniter\Debug\Exceptions->format(Array)
#3 C:\xampp\htdocs\dfpyme\system\Debug\Exceptions.php(115): CodeIgniter\Debug\Exceptions->respond(Array, 500)
#4 [internal function]: CodeIgniter\Debug\Exceptions->exceptionHandler(Object(ErrorException))
#5 {main}
  thrown
#0 [internal function]: CodeIgniter\Debug\Exceptions->shutdownHandler()
#1 {main}
ERROR - 2025-06-28 13:45:40 --> Error connecting to the database: pg_connect(): Unable to connect to PostgreSQL server: FATAL:  no existe la base de datos �BRAZAS�
CRITICAL - 2025-06-28 13:45:40 --> Unable to connect to the database.
Main connection [Postgre]: pg_connect(): Unable to connect to PostgreSQL server: FATAL:  no existe la base de datos �BRAZAS�
#0 C:\xampp\htdocs\dfpyme\system\Database\BaseConnection.php(577): CodeIgniter\Database\BaseConnection->initialize()
#1 C:\xampp\htdocs\dfpyme\app\Models\pedidoModel.php(94): CodeIgniter\Database\BaseConnection->query('\r\n        SELEC...')
#2 C:\xampp\htdocs\dfpyme\app\Controllers\reportes\ReportesController.php(779): App\Models\pedidoModel->update_mesa()
#3 C:\xampp\htdocs\dfpyme\system\CodeIgniter.php(832): App\Controllers\reportes\ReportesController->actualizacion_estado_mesas()
#4 C:\xampp\htdocs\dfpyme\system\CodeIgniter.php(419): CodeIgniter\CodeIgniter->runController(Object(App\Controllers\reportes\ReportesController))
#5 C:\xampp\htdocs\dfpyme\system\CodeIgniter.php(326): CodeIgniter\CodeIgniter->handleRequest(NULL, Object(Config\Cache), false)
#6 C:\xampp\htdocs\dfpyme\index.php(37): CodeIgniter\CodeIgniter->run()
#7 {main}
ERROR - 2025-06-28 13:45:41 --> Error connecting to the database: pg_connect(): Unable to connect to PostgreSQL server: FATAL:  no existe la base de datos �BRAZAS�
CRITICAL - 2025-06-28 13:45:41 --> Unable to connect to the database.
Main connection [Postgre]: pg_connect(): Unable to connect to PostgreSQL server: FATAL:  no existe la base de datos �BRAZAS�
#0 C:\xampp\htdocs\dfpyme\system\Database\BaseConnection.php(577): CodeIgniter\Database\BaseConnection->initialize()
#1 C:\xampp\htdocs\dfpyme\app\Models\pedidoModel.php(94): CodeIgniter\Database\BaseConnection->query('\r\n        SELEC...')
#2 C:\xampp\htdocs\dfpyme\app\Controllers\reportes\ReportesController.php(779): App\Models\pedidoModel->update_mesa()
#3 C:\xampp\htdocs\dfpyme\system\CodeIgniter.php(832): App\Controllers\reportes\ReportesController->actualizacion_estado_mesas()
#4 C:\xampp\htdocs\dfpyme\system\CodeIgniter.php(419): CodeIgniter\CodeIgniter->runController(Object(App\Controllers\reportes\ReportesController))
#5 C:\xampp\htdocs\dfpyme\system\CodeIgniter.php(326): CodeIgniter\CodeIgniter->handleRequest(NULL, Object(Config\Cache), false)
#6 C:\xampp\htdocs\dfpyme\index.php(37): CodeIgniter\CodeIgniter->run()
#7 {main}
ERROR - 2025-06-28 13:45:42 --> Error connecting to the database: pg_connect(): Unable to connect to PostgreSQL server: FATAL:  no existe la base de datos �BRAZAS�
CRITICAL - 2025-06-28 13:45:42 --> Unable to connect to the database.
Main connection [Postgre]: pg_connect(): Unable to connect to PostgreSQL server: FATAL:  no existe la base de datos �BRAZAS�
#0 C:\xampp\htdocs\dfpyme\system\Database\BaseConnection.php(577): CodeIgniter\Database\BaseConnection->initialize()
#1 C:\xampp\htdocs\dfpyme\app\Models\pedidoModel.php(94): CodeIgniter\Database\BaseConnection->query('\r\n        SELEC...')
#2 C:\xampp\htdocs\dfpyme\app\Controllers\reportes\ReportesController.php(779): App\Models\pedidoModel->update_mesa()
#3 C:\xampp\htdocs\dfpyme\system\CodeIgniter.php(832): App\Controllers\reportes\ReportesController->actualizacion_estado_mesas()
#4 C:\xampp\htdocs\dfpyme\system\CodeIgniter.php(419): CodeIgniter\CodeIgniter->runController(Object(App\Controllers\reportes\ReportesController))
#5 C:\xampp\htdocs\dfpyme\system\CodeIgniter.php(326): CodeIgniter\CodeIgniter->handleRequest(NULL, Object(Config\Cache), false)
#6 C:\xampp\htdocs\dfpyme\index.php(37): CodeIgniter\CodeIgniter->run()
#7 {main}
ERROR - 2025-06-28 13:45:43 --> Error connecting to the database: pg_connect(): Unable to connect to PostgreSQL server: FATAL:  no existe la base de datos �BRAZAS�
CRITICAL - 2025-06-28 13:45:43 --> Unable to connect to the database.
Main connection [Postgre]: pg_connect(): Unable to connect to PostgreSQL server: FATAL:  no existe la base de datos �BRAZAS�
#0 C:\xampp\htdocs\dfpyme\system\Database\BaseConnection.php(577): CodeIgniter\Database\BaseConnection->initialize()
#1 C:\xampp\htdocs\dfpyme\system\Database\BaseBuilder.php(1455): CodeIgniter\Database\BaseConnection->query('SELECT "numero"...', Array, false)
#2 C:\xampp\htdocs\dfpyme\system\Model.php(210): CodeIgniter\Database\BaseBuilder->get()
#3 C:\xampp\htdocs\dfpyme\system\BaseModel.php(622): CodeIgniter\Model->doFirst()
#4 C:\xampp\htdocs\dfpyme\app\Controllers\reportes\ReportesController.php(653): CodeIgniter\BaseModel->first()
#5 C:\xampp\htdocs\dfpyme\system\CodeIgniter.php(832): App\Controllers\reportes\ReportesController->total_ventas_electronicas()
#6 C:\xampp\htdocs\dfpyme\system\CodeIgniter.php(419): CodeIgniter\CodeIgniter->runController(Object(App\Controllers\reportes\ReportesController))
#7 C:\xampp\htdocs\dfpyme\system\CodeIgniter.php(326): CodeIgniter\CodeIgniter->handleRequest(NULL, Object(Config\Cache), false)
#8 C:\xampp\htdocs\dfpyme\index.php(37): CodeIgniter\CodeIgniter->run()
#9 {main}
ERROR - 2025-06-28 13:45:43 --> Error connecting to the database: pg_connect(): Unable to connect to PostgreSQL server: FATAL:  no existe la base de datos �BRAZAS�
CRITICAL - 2025-06-28 13:45:43 --> Unable to connect to the database.
Main connection [Postgre]: pg_connect(): Unable to connect to PostgreSQL server: FATAL:  no existe la base de datos �BRAZAS�
#0 C:\xampp\htdocs\dfpyme\system\Database\BaseConnection.php(577): CodeIgniter\Database\BaseConnection->initialize()
#1 C:\xampp\htdocs\dfpyme\app\Models\pedidoModel.php(94): CodeIgniter\Database\BaseConnection->query('\r\n        SELEC...')
#2 C:\xampp\htdocs\dfpyme\app\Controllers\reportes\ReportesController.php(779): App\Models\pedidoModel->update_mesa()
#3 C:\xampp\htdocs\dfpyme\system\CodeIgniter.php(832): App\Controllers\reportes\ReportesController->actualizacion_estado_mesas()
#4 C:\xampp\htdocs\dfpyme\system\CodeIgniter.php(419): CodeIgniter\CodeIgniter->runController(Object(App\Controllers\reportes\ReportesController))
#5 C:\xampp\htdocs\dfpyme\system\CodeIgniter.php(326): CodeIgniter\CodeIgniter->handleRequest(NULL, Object(Config\Cache), false)
#6 C:\xampp\htdocs\dfpyme\index.php(37): CodeIgniter\CodeIgniter->run()
#7 {main}
ERROR - 2025-06-28 13:45:44 --> Error connecting to the database: pg_connect(): Unable to connect to PostgreSQL server: FATAL:  no existe la base de datos �BRAZAS�
CRITICAL - 2025-06-28 13:45:44 --> Unable to connect to the database.
Main connection [Postgre]: pg_connect(): Unable to connect to PostgreSQL server: FATAL:  no existe la base de datos �BRAZAS�
#0 C:\xampp\htdocs\dfpyme\system\Database\BaseConnection.php(577): CodeIgniter\Database\BaseConnection->initialize()
#1 C:\xampp\htdocs\dfpyme\app\Models\pedidoModel.php(94): CodeIgniter\Database\BaseConnection->query('\r\n        SELEC...')
#2 C:\xampp\htdocs\dfpyme\app\Controllers\reportes\ReportesController.php(779): App\Models\pedidoModel->update_mesa()
#3 C:\xampp\htdocs\dfpyme\system\CodeIgniter.php(832): App\Controllers\reportes\ReportesController->actualizacion_estado_mesas()
#4 C:\xampp\htdocs\dfpyme\system\CodeIgniter.php(419): CodeIgniter\CodeIgniter->runController(Object(App\Controllers\reportes\ReportesController))
#5 C:\xampp\htdocs\dfpyme\system\CodeIgniter.php(326): CodeIgniter\CodeIgniter->handleRequest(NULL, Object(Config\Cache), false)
#6 C:\xampp\htdocs\dfpyme\index.php(37): CodeIgniter\CodeIgniter->run()
#7 {main}
ERROR - 2025-06-28 13:45:45 --> Error connecting to the database: pg_connect(): Unable to connect to PostgreSQL server: FATAL:  no existe la base de datos �BRAZAS�
CRITICAL - 2025-06-28 13:45:45 --> Unable to connect to the database.
Main connection [Postgre]: pg_connect(): Unable to connect to PostgreSQL server: FATAL:  no existe la base de datos �BRAZAS�
#0 C:\xampp\htdocs\dfpyme\system\Database\BaseConnection.php(577): CodeIgniter\Database\BaseConnection->initialize()
#1 C:\xampp\htdocs\dfpyme\app\Models\pedidoModel.php(94): CodeIgniter\Database\BaseConnection->query('\r\n        SELEC...')
#2 C:\xampp\htdocs\dfpyme\app\Controllers\reportes\ReportesController.php(779): App\Models\pedidoModel->update_mesa()
#3 C:\xampp\htdocs\dfpyme\system\CodeIgniter.php(832): App\Controllers\reportes\ReportesController->actualizacion_estado_mesas()
#4 C:\xampp\htdocs\dfpyme\system\CodeIgniter.php(419): CodeIgniter\CodeIgniter->runController(Object(App\Controllers\reportes\ReportesController))
#5 C:\xampp\htdocs\dfpyme\system\CodeIgniter.php(326): CodeIgniter\CodeIgniter->handleRequest(NULL, Object(Config\Cache), false)
#6 C:\xampp\htdocs\dfpyme\index.php(37): CodeIgniter\CodeIgniter->run()
#7 {main}
ERROR - 2025-06-28 13:45:46 --> Error connecting to the database: pg_connect(): Unable to connect to PostgreSQL server: FATAL:  no existe la base de datos �BRAZAS�
CRITICAL - 2025-06-28 13:45:46 --> Unable to connect to the database.
Main connection [Postgre]: pg_connect(): Unable to connect to PostgreSQL server: FATAL:  no existe la base de datos �BRAZAS�
#0 C:\xampp\htdocs\dfpyme\system\Database\BaseConnection.php(577): CodeIgniter\Database\BaseConnection->initialize()
#1 C:\xampp\htdocs\dfpyme\app\Models\pedidoModel.php(94): CodeIgniter\Database\BaseConnection->query('\r\n        SELEC...')
#2 C:\xampp\htdocs\dfpyme\app\Controllers\reportes\ReportesController.php(779): App\Models\pedidoModel->update_mesa()
#3 C:\xampp\htdocs\dfpyme\system\CodeIgniter.php(832): App\Controllers\reportes\ReportesController->actualizacion_estado_mesas()
#4 C:\xampp\htdocs\dfpyme\system\CodeIgniter.php(419): CodeIgniter\CodeIgniter->runController(Object(App\Controllers\reportes\ReportesController))
#5 C:\xampp\htdocs\dfpyme\system\CodeIgniter.php(326): CodeIgniter\CodeIgniter->handleRequest(NULL, Object(Config\Cache), false)
#6 C:\xampp\htdocs\dfpyme\index.php(37): CodeIgniter\CodeIgniter->run()
#7 {main}
ERROR - 2025-06-28 13:45:47 --> Error connecting to the database: pg_connect(): Unable to connect to PostgreSQL server: FATAL:  no existe la base de datos �BRAZAS�
CRITICAL - 2025-06-28 13:45:47 --> Unable to connect to the database.
Main connection [Postgre]: pg_connect(): Unable to connect to PostgreSQL server: FATAL:  no existe la base de datos �BRAZAS�
#0 C:\xampp\htdocs\dfpyme\system\Database\BaseConnection.php(577): CodeIgniter\Database\BaseConnection->initialize()
#1 C:\xampp\htdocs\dfpyme\app\Models\pedidoModel.php(94): CodeIgniter\Database\BaseConnection->query('\r\n        SELEC...')
#2 C:\xampp\htdocs\dfpyme\app\Controllers\reportes\ReportesController.php(779): App\Models\pedidoModel->update_mesa()
#3 C:\xampp\htdocs\dfpyme\system\CodeIgniter.php(832): App\Controllers\reportes\ReportesController->actualizacion_estado_mesas()
#4 C:\xampp\htdocs\dfpyme\system\CodeIgniter.php(419): CodeIgniter\CodeIgniter->runController(Object(App\Controllers\reportes\ReportesController))
#5 C:\xampp\htdocs\dfpyme\system\CodeIgniter.php(326): CodeIgniter\CodeIgniter->handleRequest(NULL, Object(Config\Cache), false)
#6 C:\xampp\htdocs\dfpyme\index.php(37): CodeIgniter\CodeIgniter->run()
#7 {main}
ERROR - 2025-06-28 13:45:48 --> Error connecting to the database: pg_connect(): Unable to connect to PostgreSQL server: FATAL:  no existe la base de datos �BRAZAS�
CRITICAL - 2025-06-28 13:45:48 --> Unable to connect to the database.
Main connection [Postgre]: pg_connect(): Unable to connect to PostgreSQL server: FATAL:  no existe la base de datos �BRAZAS�
#0 C:\xampp\htdocs\dfpyme\system\Database\BaseConnection.php(577): CodeIgniter\Database\BaseConnection->initialize()
#1 C:\xampp\htdocs\dfpyme\system\Database\BaseBuilder.php(1455): CodeIgniter\Database\BaseConnection->query('SELECT "numero"...', Array, false)
#2 C:\xampp\htdocs\dfpyme\system\Model.php(210): CodeIgniter\Database\BaseBuilder->get()
#3 C:\xampp\htdocs\dfpyme\system\BaseModel.php(622): CodeIgniter\Model->doFirst()
#4 C:\xampp\htdocs\dfpyme\app\Controllers\reportes\ReportesController.php(653): CodeIgniter\BaseModel->first()
#5 C:\xampp\htdocs\dfpyme\system\CodeIgniter.php(832): App\Controllers\reportes\ReportesController->total_ventas_electronicas()
#6 C:\xampp\htdocs\dfpyme\system\CodeIgniter.php(419): CodeIgniter\CodeIgniter->runController(Object(App\Controllers\reportes\ReportesController))
#7 C:\xampp\htdocs\dfpyme\system\CodeIgniter.php(326): CodeIgniter\CodeIgniter->handleRequest(NULL, Object(Config\Cache), false)
#8 C:\xampp\htdocs\dfpyme\index.php(37): CodeIgniter\CodeIgniter->run()
#9 {main}
ERROR - 2025-06-28 13:45:48 --> Error connecting to the database: pg_connect(): Unable to connect to PostgreSQL server: FATAL:  no existe la base de datos �BRAZAS�
CRITICAL - 2025-06-28 13:45:48 --> Unable to connect to the database.
Main connection [Postgre]: pg_connect(): Unable to connect to PostgreSQL server: FATAL:  no existe la base de datos �BRAZAS�
#0 C:\xampp\htdocs\dfpyme\system\Database\BaseConnection.php(577): CodeIgniter\Database\BaseConnection->initialize()
#1 C:\xampp\htdocs\dfpyme\app\Models\pedidoModel.php(94): CodeIgniter\Database\BaseConnection->query('\r\n        SELEC...')
#2 C:\xampp\htdocs\dfpyme\app\Controllers\reportes\ReportesController.php(779): App\Models\pedidoModel->update_mesa()
#3 C:\xampp\htdocs\dfpyme\system\CodeIgniter.php(832): App\Controllers\reportes\ReportesController->actualizacion_estado_mesas()
#4 C:\xampp\htdocs\dfpyme\system\CodeIgniter.php(419): CodeIgniter\CodeIgniter->runController(Object(App\Controllers\reportes\ReportesController))
#5 C:\xampp\htdocs\dfpyme\system\CodeIgniter.php(326): CodeIgniter\CodeIgniter->handleRequest(NULL, Object(Config\Cache), false)
#6 C:\xampp\htdocs\dfpyme\index.php(37): CodeIgniter\CodeIgniter->run()
#7 {main}
ERROR - 2025-06-28 13:45:49 --> Error connecting to the database: pg_connect(): Unable to connect to PostgreSQL server: FATAL:  no existe la base de datos �BRAZAS�
CRITICAL - 2025-06-28 13:45:49 --> Unable to connect to the database.
Main connection [Postgre]: pg_connect(): Unable to connect to PostgreSQL server: FATAL:  no existe la base de datos �BRAZAS�
#0 C:\xampp\htdocs\dfpyme\system\Database\BaseConnection.php(577): CodeIgniter\Database\BaseConnection->initialize()
#1 C:\xampp\htdocs\dfpyme\app\Models\pedidoModel.php(94): CodeIgniter\Database\BaseConnection->query('\r\n        SELEC...')
#2 C:\xampp\htdocs\dfpyme\app\Controllers\reportes\ReportesController.php(779): App\Models\pedidoModel->update_mesa()
#3 C:\xampp\htdocs\dfpyme\system\CodeIgniter.php(832): App\Controllers\reportes\ReportesController->actualizacion_estado_mesas()
#4 C:\xampp\htdocs\dfpyme\system\CodeIgniter.php(419): CodeIgniter\CodeIgniter->runController(Object(App\Controllers\reportes\ReportesController))
#5 C:\xampp\htdocs\dfpyme\system\CodeIgniter.php(326): CodeIgniter\CodeIgniter->handleRequest(NULL, Object(Config\Cache), false)
#6 C:\xampp\htdocs\dfpyme\index.php(37): CodeIgniter\CodeIgniter->run()
#7 {main}
ERROR - 2025-06-28 13:45:50 --> Error connecting to the database: pg_connect(): Unable to connect to PostgreSQL server: FATAL:  no existe la base de datos �BRAZAS�
CRITICAL - 2025-06-28 13:45:50 --> Unable to connect to the database.
Main connection [Postgre]: pg_connect(): Unable to connect to PostgreSQL server: FATAL:  no existe la base de datos �BRAZAS�
#0 C:\xampp\htdocs\dfpyme\system\Database\BaseConnection.php(577): CodeIgniter\Database\BaseConnection->initialize()
#1 C:\xampp\htdocs\dfpyme\app\Models\pedidoModel.php(94): CodeIgniter\Database\BaseConnection->query('\r\n        SELEC...')
#2 C:\xampp\htdocs\dfpyme\app\Controllers\reportes\ReportesController.php(779): App\Models\pedidoModel->update_mesa()
#3 C:\xampp\htdocs\dfpyme\system\CodeIgniter.php(832): App\Controllers\reportes\ReportesController->actualizacion_estado_mesas()
#4 C:\xampp\htdocs\dfpyme\system\CodeIgniter.php(419): CodeIgniter\CodeIgniter->runController(Object(App\Controllers\reportes\ReportesController))
#5 C:\xampp\htdocs\dfpyme\system\CodeIgniter.php(326): CodeIgniter\CodeIgniter->handleRequest(NULL, Object(Config\Cache), false)
#6 C:\xampp\htdocs\dfpyme\index.php(37): CodeIgniter\CodeIgniter->run()
#7 {main}
ERROR - 2025-06-28 13:45:51 --> Error connecting to the database: pg_connect(): Unable to connect to PostgreSQL server: FATAL:  no existe la base de datos �BRAZAS�
CRITICAL - 2025-06-28 13:45:51 --> Unable to connect to the database.
Main connection [Postgre]: pg_connect(): Unable to connect to PostgreSQL server: FATAL:  no existe la base de datos �BRAZAS�
#0 C:\xampp\htdocs\dfpyme\system\Database\BaseConnection.php(577): CodeIgniter\Database\BaseConnection->initialize()
#1 C:\xampp\htdocs\dfpyme\app\Models\pedidoModel.php(94): CodeIgniter\Database\BaseConnection->query('\r\n        SELEC...')
#2 C:\xampp\htdocs\dfpyme\app\Controllers\reportes\ReportesController.php(779): App\Models\pedidoModel->update_mesa()
#3 C:\xampp\htdocs\dfpyme\system\CodeIgniter.php(832): App\Controllers\reportes\ReportesController->actualizacion_estado_mesas()
#4 C:\xampp\htdocs\dfpyme\system\CodeIgniter.php(419): CodeIgniter\CodeIgniter->runController(Object(App\Controllers\reportes\ReportesController))
#5 C:\xampp\htdocs\dfpyme\system\CodeIgniter.php(326): CodeIgniter\CodeIgniter->handleRequest(NULL, Object(Config\Cache), false)
#6 C:\xampp\htdocs\dfpyme\index.php(37): CodeIgniter\CodeIgniter->run()
#7 {main}
ERROR - 2025-06-28 13:45:52 --> Error connecting to the database: pg_connect(): Unable to connect to PostgreSQL server: FATAL:  no existe la base de datos �BRAZAS�
CRITICAL - 2025-06-28 13:45:52 --> Unable to connect to the database.
Main connection [Postgre]: pg_connect(): Unable to connect to PostgreSQL server: FATAL:  no existe la base de datos �BRAZAS�
#0 C:\xampp\htdocs\dfpyme\system\Database\BaseConnection.php(577): CodeIgniter\Database\BaseConnection->initialize()
#1 C:\xampp\htdocs\dfpyme\app\Models\pedidoModel.php(94): CodeIgniter\Database\BaseConnection->query('\r\n        SELEC...')
#2 C:\xampp\htdocs\dfpyme\app\Controllers\reportes\ReportesController.php(779): App\Models\pedidoModel->update_mesa()
#3 C:\xampp\htdocs\dfpyme\system\CodeIgniter.php(832): App\Controllers\reportes\ReportesController->actualizacion_estado_mesas()
#4 C:\xampp\htdocs\dfpyme\system\CodeIgniter.php(419): CodeIgniter\CodeIgniter->runController(Object(App\Controllers\reportes\ReportesController))
#5 C:\xampp\htdocs\dfpyme\system\CodeIgniter.php(326): CodeIgniter\CodeIgniter->handleRequest(NULL, Object(Config\Cache), false)
#6 C:\xampp\htdocs\dfpyme\index.php(37): CodeIgniter\CodeIgniter->run()
#7 {main}
ERROR - 2025-06-28 13:45:53 --> Error connecting to the database: pg_connect(): Unable to connect to PostgreSQL server: FATAL:  no existe la base de datos �BRAZAS�
CRITICAL - 2025-06-28 13:45:53 --> Unable to connect to the database.
Main connection [Postgre]: pg_connect(): Unable to connect to PostgreSQL server: FATAL:  no existe la base de datos �BRAZAS�
#0 C:\xampp\htdocs\dfpyme\system\Database\BaseConnection.php(577): CodeIgniter\Database\BaseConnection->initialize()
#1 C:\xampp\htdocs\dfpyme\system\Database\BaseBuilder.php(1455): CodeIgniter\Database\BaseConnection->query('SELECT "numero"...', Array, false)
#2 C:\xampp\htdocs\dfpyme\system\Model.php(210): CodeIgniter\Database\BaseBuilder->get()
#3 C:\xampp\htdocs\dfpyme\system\BaseModel.php(622): CodeIgniter\Model->doFirst()
#4 C:\xampp\htdocs\dfpyme\app\Controllers\reportes\ReportesController.php(653): CodeIgniter\BaseModel->first()
#5 C:\xampp\htdocs\dfpyme\system\CodeIgniter.php(832): App\Controllers\reportes\ReportesController->total_ventas_electronicas()
#6 C:\xampp\htdocs\dfpyme\system\CodeIgniter.php(419): CodeIgniter\CodeIgniter->runController(Object(App\Controllers\reportes\ReportesController))
#7 C:\xampp\htdocs\dfpyme\system\CodeIgniter.php(326): CodeIgniter\CodeIgniter->handleRequest(NULL, Object(Config\Cache), false)
#8 C:\xampp\htdocs\dfpyme\index.php(37): CodeIgniter\CodeIgniter->run()
#9 {main}
ERROR - 2025-06-28 13:45:53 --> Error connecting to the database: pg_connect(): Unable to connect to PostgreSQL server: FATAL:  no existe la base de datos �BRAZAS�
CRITICAL - 2025-06-28 13:45:53 --> Unable to connect to the database.
Main connection [Postgre]: pg_connect(): Unable to connect to PostgreSQL server: FATAL:  no existe la base de datos �BRAZAS�
#0 C:\xampp\htdocs\dfpyme\system\Database\BaseConnection.php(577): CodeIgniter\Database\BaseConnection->initialize()
#1 C:\xampp\htdocs\dfpyme\app\Models\pedidoModel.php(94): CodeIgniter\Database\BaseConnection->query('\r\n        SELEC...')
#2 C:\xampp\htdocs\dfpyme\app\Controllers\reportes\ReportesController.php(779): App\Models\pedidoModel->update_mesa()
#3 C:\xampp\htdocs\dfpyme\system\CodeIgniter.php(832): App\Controllers\reportes\ReportesController->actualizacion_estado_mesas()
#4 C:\xampp\htdocs\dfpyme\system\CodeIgniter.php(419): CodeIgniter\CodeIgniter->runController(Object(App\Controllers\reportes\ReportesController))
#5 C:\xampp\htdocs\dfpyme\system\CodeIgniter.php(326): CodeIgniter\CodeIgniter->handleRequest(NULL, Object(Config\Cache), false)
#6 C:\xampp\htdocs\dfpyme\index.php(37): CodeIgniter\CodeIgniter->run()
#7 {main}
ERROR - 2025-06-28 13:45:54 --> Error connecting to the database: pg_connect(): Unable to connect to PostgreSQL server: FATAL:  no existe la base de datos �BRAZAS�
CRITICAL - 2025-06-28 13:45:54 --> Unable to connect to the database.
Main connection [Postgre]: pg_connect(): Unable to connect to PostgreSQL server: FATAL:  no existe la base de datos �BRAZAS�
#0 C:\xampp\htdocs\dfpyme\system\Database\BaseConnection.php(577): CodeIgniter\Database\BaseConnection->initialize()
#1 C:\xampp\htdocs\dfpyme\app\Models\pedidoModel.php(94): CodeIgniter\Database\BaseConnection->query('\r\n        SELEC...')
#2 C:\xampp\htdocs\dfpyme\app\Controllers\reportes\ReportesController.php(779): App\Models\pedidoModel->update_mesa()
#3 C:\xampp\htdocs\dfpyme\system\CodeIgniter.php(832): App\Controllers\reportes\ReportesController->actualizacion_estado_mesas()
#4 C:\xampp\htdocs\dfpyme\system\CodeIgniter.php(419): CodeIgniter\CodeIgniter->runController(Object(App\Controllers\reportes\ReportesController))
#5 C:\xampp\htdocs\dfpyme\system\CodeIgniter.php(326): CodeIgniter\CodeIgniter->handleRequest(NULL, Object(Config\Cache), false)
#6 C:\xampp\htdocs\dfpyme\index.php(37): CodeIgniter\CodeIgniter->run()
#7 {main}
ERROR - 2025-06-28 13:45:55 --> Error connecting to the database: pg_connect(): Unable to connect to PostgreSQL server: FATAL:  no existe la base de datos �BRAZAS�
CRITICAL - 2025-06-28 13:45:55 --> Unable to connect to the database.
Main connection [Postgre]: pg_connect(): Unable to connect to PostgreSQL server: FATAL:  no existe la base de datos �BRAZAS�
#0 C:\xampp\htdocs\dfpyme\system\Database\BaseConnection.php(577): CodeIgniter\Database\BaseConnection->initialize()
#1 C:\xampp\htdocs\dfpyme\app\Models\pedidoModel.php(94): CodeIgniter\Database\BaseConnection->query('\r\n        SELEC...')
#2 C:\xampp\htdocs\dfpyme\app\Controllers\reportes\ReportesController.php(779): App\Models\pedidoModel->update_mesa()
#3 C:\xampp\htdocs\dfpyme\system\CodeIgniter.php(832): App\Controllers\reportes\ReportesController->actualizacion_estado_mesas()
#4 C:\xampp\htdocs\dfpyme\system\CodeIgniter.php(419): CodeIgniter\CodeIgniter->runController(Object(App\Controllers\reportes\ReportesController))
#5 C:\xampp\htdocs\dfpyme\system\CodeIgniter.php(326): CodeIgniter\CodeIgniter->handleRequest(NULL, Object(Config\Cache), false)
#6 C:\xampp\htdocs\dfpyme\index.php(37): CodeIgniter\CodeIgniter->run()
#7 {main}
ERROR - 2025-06-28 13:45:56 --> ErrorException: pg_query(): Query failed: ERROR:  no existe la relación «pedido»
LINE 11:             pedido
                     ^ in C:\xampp\htdocs\dfpyme\system\Database\Postgre\Connection.php:135
Stack trace:
#0 [internal function]: CodeIgniter\Debug\Exceptions->errorHandler(2, 'pg_query(): Que...', 'C:\\xampp\\htdocs...', 135)
#1 C:\xampp\htdocs\dfpyme\system\Database\Postgre\Connection.php(135): pg_query(Resource id #155, '\r\n        SELEC...')
#2 C:\xampp\htdocs\dfpyme\system\Database\BaseConnection.php(670): CodeIgniter\Database\Postgre\Connection->execute('\r\n        SELEC...')
#3 C:\xampp\htdocs\dfpyme\system\Database\BaseConnection.php(598): CodeIgniter\Database\BaseConnection->simpleQuery('\r\n        SELEC...')
#4 C:\xampp\htdocs\dfpyme\app\Models\pedidoModel.php(94): CodeIgniter\Database\BaseConnection->query('\r\n        SELEC...')
#5 C:\xampp\htdocs\dfpyme\app\Controllers\reportes\ReportesController.php(779): App\Models\pedidoModel->update_mesa()
#6 C:\xampp\htdocs\dfpyme\system\CodeIgniter.php(832): App\Controllers\reportes\ReportesController->actualizacion_estado_mesas()
#7 C:\xampp\htdocs\dfpyme\system\CodeIgniter.php(419): CodeIgniter\CodeIgniter->runController(Object(App\Controllers\reportes\ReportesController))
#8 C:\xampp\htdocs\dfpyme\system\CodeIgniter.php(326): CodeIgniter\CodeIgniter->handleRequest(NULL, Object(Config\Cache), false)
#9 C:\xampp\htdocs\dfpyme\index.php(37): CodeIgniter\CodeIgniter->run()
#10 {main}
CRITICAL - 2025-06-28 13:45:56 --> pg_query(): Query failed: ERROR:  no existe la relación «pedido»
LINE 11:             pedido
                     ^
#0 [internal function]: CodeIgniter\Debug\Exceptions->errorHandler(2, 'pg_query(): Que...', 'C:\\xampp\\htdocs...', 135)
#1 C:\xampp\htdocs\dfpyme\system\Database\Postgre\Connection.php(135): pg_query(Resource id #155, '\r\n        SELEC...')
#2 C:\xampp\htdocs\dfpyme\system\Database\BaseConnection.php(670): CodeIgniter\Database\Postgre\Connection->execute('\r\n        SELEC...')
#3 C:\xampp\htdocs\dfpyme\system\Database\BaseConnection.php(598): CodeIgniter\Database\BaseConnection->simpleQuery('\r\n        SELEC...')
#4 C:\xampp\htdocs\dfpyme\app\Models\pedidoModel.php(94): CodeIgniter\Database\BaseConnection->query('\r\n        SELEC...')
#5 C:\xampp\htdocs\dfpyme\app\Controllers\reportes\ReportesController.php(779): App\Models\pedidoModel->update_mesa()
#6 C:\xampp\htdocs\dfpyme\system\CodeIgniter.php(832): App\Controllers\reportes\ReportesController->actualizacion_estado_mesas()
#7 C:\xampp\htdocs\dfpyme\system\CodeIgniter.php(419): CodeIgniter\CodeIgniter->runController(Object(App\Controllers\reportes\ReportesController))
#8 C:\xampp\htdocs\dfpyme\system\CodeIgniter.php(326): CodeIgniter\CodeIgniter->handleRequest(NULL, Object(Config\Cache), false)
#9 C:\xampp\htdocs\dfpyme\index.php(37): CodeIgniter\CodeIgniter->run()
#10 {main}
CRITICAL - 2025-06-28 13:45:56 --> Uncaught CodeIgniter\Format\Exceptions\FormatException: Failed to parse json string, error: "Type is not supported". in C:\xampp\htdocs\dfpyme\system\Format\JSONFormatter.php:41
Stack trace:
#0 C:\xampp\htdocs\dfpyme\system\Format\JSONFormatter.php(41): CodeIgniter\Format\Exceptions\FormatException::forInvalidJSON('Type is not sup...')
#1 C:\xampp\htdocs\dfpyme\system\API\ResponseTrait.php(341): CodeIgniter\Format\JSONFormatter->format(Array)
#2 C:\xampp\htdocs\dfpyme\system\API\ResponseTrait.php(99): CodeIgniter\Debug\Exceptions->format(Array)
#3 C:\xampp\htdocs\dfpyme\system\Debug\Exceptions.php(115): CodeIgniter\Debug\Exceptions->respond(Array, 500)
#4 [internal function]: CodeIgniter\Debug\Exceptions->exceptionHandler(Object(ErrorException))
#5 {main}
  thrown
#0 [internal function]: CodeIgniter\Debug\Exceptions->shutdownHandler()
#1 {main}
ERROR - 2025-06-28 13:45:57 --> ErrorException: pg_query(): Query failed: ERROR:  no existe la relación «pedido»
LINE 11:             pedido
                     ^ in C:\xampp\htdocs\dfpyme\system\Database\Postgre\Connection.php:135
Stack trace:
#0 [internal function]: CodeIgniter\Debug\Exceptions->errorHandler(2, 'pg_query(): Que...', 'C:\\xampp\\htdocs...', 135)
#1 C:\xampp\htdocs\dfpyme\system\Database\Postgre\Connection.php(135): pg_query(Resource id #155, '\r\n        SELEC...')
#2 C:\xampp\htdocs\dfpyme\system\Database\BaseConnection.php(670): CodeIgniter\Database\Postgre\Connection->execute('\r\n        SELEC...')
#3 C:\xampp\htdocs\dfpyme\system\Database\BaseConnection.php(598): CodeIgniter\Database\BaseConnection->simpleQuery('\r\n        SELEC...')
#4 C:\xampp\htdocs\dfpyme\app\Models\pedidoModel.php(94): CodeIgniter\Database\BaseConnection->query('\r\n        SELEC...')
#5 C:\xampp\htdocs\dfpyme\app\Controllers\reportes\ReportesController.php(779): App\Models\pedidoModel->update_mesa()
#6 C:\xampp\htdocs\dfpyme\system\CodeIgniter.php(832): App\Controllers\reportes\ReportesController->actualizacion_estado_mesas()
#7 C:\xampp\htdocs\dfpyme\system\CodeIgniter.php(419): CodeIgniter\CodeIgniter->runController(Object(App\Controllers\reportes\ReportesController))
#8 C:\xampp\htdocs\dfpyme\system\CodeIgniter.php(326): CodeIgniter\CodeIgniter->handleRequest(NULL, Object(Config\Cache), false)
#9 C:\xampp\htdocs\dfpyme\index.php(37): CodeIgniter\CodeIgniter->run()
#10 {main}
CRITICAL - 2025-06-28 13:45:57 --> pg_query(): Query failed: ERROR:  no existe la relación «pedido»
LINE 11:             pedido
                     ^
#0 [internal function]: CodeIgniter\Debug\Exceptions->errorHandler(2, 'pg_query(): Que...', 'C:\\xampp\\htdocs...', 135)
#1 C:\xampp\htdocs\dfpyme\system\Database\Postgre\Connection.php(135): pg_query(Resource id #155, '\r\n        SELEC...')
#2 C:\xampp\htdocs\dfpyme\system\Database\BaseConnection.php(670): CodeIgniter\Database\Postgre\Connection->execute('\r\n        SELEC...')
#3 C:\xampp\htdocs\dfpyme\system\Database\BaseConnection.php(598): CodeIgniter\Database\BaseConnection->simpleQuery('\r\n        SELEC...')
#4 C:\xampp\htdocs\dfpyme\app\Models\pedidoModel.php(94): CodeIgniter\Database\BaseConnection->query('\r\n        SELEC...')
#5 C:\xampp\htdocs\dfpyme\app\Controllers\reportes\ReportesController.php(779): App\Models\pedidoModel->update_mesa()
#6 C:\xampp\htdocs\dfpyme\system\CodeIgniter.php(832): App\Controllers\reportes\ReportesController->actualizacion_estado_mesas()
#7 C:\xampp\htdocs\dfpyme\system\CodeIgniter.php(419): CodeIgniter\CodeIgniter->runController(Object(App\Controllers\reportes\ReportesController))
#8 C:\xampp\htdocs\dfpyme\system\CodeIgniter.php(326): CodeIgniter\CodeIgniter->handleRequest(NULL, Object(Config\Cache), false)
#9 C:\xampp\htdocs\dfpyme\index.php(37): CodeIgniter\CodeIgniter->run()
#10 {main}
CRITICAL - 2025-06-28 13:45:57 --> Uncaught CodeIgniter\Format\Exceptions\FormatException: Failed to parse json string, error: "Type is not supported". in C:\xampp\htdocs\dfpyme\system\Format\JSONFormatter.php:41
Stack trace:
#0 C:\xampp\htdocs\dfpyme\system\Format\JSONFormatter.php(41): CodeIgniter\Format\Exceptions\FormatException::forInvalidJSON('Type is not sup...')
#1 C:\xampp\htdocs\dfpyme\system\API\ResponseTrait.php(341): CodeIgniter\Format\JSONFormatter->format(Array)
#2 C:\xampp\htdocs\dfpyme\system\API\ResponseTrait.php(99): CodeIgniter\Debug\Exceptions->format(Array)
#3 C:\xampp\htdocs\dfpyme\system\Debug\Exceptions.php(115): CodeIgniter\Debug\Exceptions->respond(Array, 500)
#4 [internal function]: CodeIgniter\Debug\Exceptions->exceptionHandler(Object(ErrorException))
#5 {main}
  thrown
#0 [internal function]: CodeIgniter\Debug\Exceptions->shutdownHandler()
#1 {main}
ERROR - 2025-06-28 13:45:58 --> ErrorException: pg_query(): Query failed: ERROR:  no existe la relación «apertura_registro»
LINE 2: FROM &quot;apertura_registro&quot;
             ^ in C:\xampp\htdocs\dfpyme\system\Database\Postgre\Connection.php:135
Stack trace:
#0 [internal function]: CodeIgniter\Debug\Exceptions->errorHandler(2, 'pg_query(): Que...', 'C:\\xampp\\htdocs...', 135)
#1 C:\xampp\htdocs\dfpyme\system\Database\Postgre\Connection.php(135): pg_query(Resource id #157, 'SELECT "numero"...')
#2 C:\xampp\htdocs\dfpyme\system\Database\BaseConnection.php(670): CodeIgniter\Database\Postgre\Connection->execute('SELECT "numero"...')
#3 C:\xampp\htdocs\dfpyme\system\Database\BaseConnection.php(598): CodeIgniter\Database\BaseConnection->simpleQuery('SELECT "numero"...')
#4 C:\xampp\htdocs\dfpyme\system\Database\BaseBuilder.php(1455): CodeIgniter\Database\BaseConnection->query('SELECT "numero"...', Array, false)
#5 C:\xampp\htdocs\dfpyme\system\Model.php(210): CodeIgniter\Database\BaseBuilder->get()
#6 C:\xampp\htdocs\dfpyme\system\BaseModel.php(622): CodeIgniter\Model->doFirst()
#7 C:\xampp\htdocs\dfpyme\app\Controllers\reportes\ReportesController.php(653): CodeIgniter\BaseModel->first()
#8 C:\xampp\htdocs\dfpyme\system\CodeIgniter.php(832): App\Controllers\reportes\ReportesController->total_ventas_electronicas()
#9 C:\xampp\htdocs\dfpyme\system\CodeIgniter.php(419): CodeIgniter\CodeIgniter->runController(Object(App\Controllers\reportes\ReportesController))
#10 C:\xampp\htdocs\dfpyme\system\CodeIgniter.php(326): CodeIgniter\CodeIgniter->handleRequest(NULL, Object(Config\Cache), false)
#11 C:\xampp\htdocs\dfpyme\index.php(37): CodeIgniter\CodeIgniter->run()
#12 {main}
CRITICAL - 2025-06-28 13:45:58 --> pg_query(): Query failed: ERROR:  no existe la relación «apertura_registro»
LINE 2: FROM &quot;apertura_registro&quot;
             ^
#0 [internal function]: CodeIgniter\Debug\Exceptions->errorHandler(2, 'pg_query(): Que...', 'C:\\xampp\\htdocs...', 135)
#1 C:\xampp\htdocs\dfpyme\system\Database\Postgre\Connection.php(135): pg_query(Resource id #157, 'SELECT "numero"...')
#2 C:\xampp\htdocs\dfpyme\system\Database\BaseConnection.php(670): CodeIgniter\Database\Postgre\Connection->execute('SELECT "numero"...')
#3 C:\xampp\htdocs\dfpyme\system\Database\BaseConnection.php(598): CodeIgniter\Database\BaseConnection->simpleQuery('SELECT "numero"...')
#4 C:\xampp\htdocs\dfpyme\system\Database\BaseBuilder.php(1455): CodeIgniter\Database\BaseConnection->query('SELECT "numero"...', Array, false)
#5 C:\xampp\htdocs\dfpyme\system\Model.php(210): CodeIgniter\Database\BaseBuilder->get()
#6 C:\xampp\htdocs\dfpyme\system\BaseModel.php(622): CodeIgniter\Model->doFirst()
#7 C:\xampp\htdocs\dfpyme\app\Controllers\reportes\ReportesController.php(653): CodeIgniter\BaseModel->first()
#8 C:\xampp\htdocs\dfpyme\system\CodeIgniter.php(832): App\Controllers\reportes\ReportesController->total_ventas_electronicas()
#9 C:\xampp\htdocs\dfpyme\system\CodeIgniter.php(419): CodeIgniter\CodeIgniter->runController(Object(App\Controllers\reportes\ReportesController))
#10 C:\xampp\htdocs\dfpyme\system\CodeIgniter.php(326): CodeIgniter\CodeIgniter->handleRequest(NULL, Object(Config\Cache), false)
#11 C:\xampp\htdocs\dfpyme\index.php(37): CodeIgniter\CodeIgniter->run()
#12 {main}
CRITICAL - 2025-06-28 13:45:58 --> Uncaught CodeIgniter\Format\Exceptions\FormatException: Failed to parse json string, error: "Type is not supported". in C:\xampp\htdocs\dfpyme\system\Format\JSONFormatter.php:41
Stack trace:
#0 C:\xampp\htdocs\dfpyme\system\Format\JSONFormatter.php(41): CodeIgniter\Format\Exceptions\FormatException::forInvalidJSON('Type is not sup...')
#1 C:\xampp\htdocs\dfpyme\system\API\ResponseTrait.php(341): CodeIgniter\Format\JSONFormatter->format(Array)
#2 C:\xampp\htdocs\dfpyme\system\API\ResponseTrait.php(99): CodeIgniter\Debug\Exceptions->format(Array)
#3 C:\xampp\htdocs\dfpyme\system\Debug\Exceptions.php(115): CodeIgniter\Debug\Exceptions->respond(Array, 500)
#4 [internal function]: CodeIgniter\Debug\Exceptions->exceptionHandler(Object(ErrorException))
#5 {main}
  thrown
#0 [internal function]: CodeIgniter\Debug\Exceptions->shutdownHandler()
#1 {main}
ERROR - 2025-06-28 13:45:58 --> ErrorException: pg_query(): Query failed: ERROR:  no existe la relación «pedido»
LINE 11:             pedido
                     ^ in C:\xampp\htdocs\dfpyme\system\Database\Postgre\Connection.php:135
Stack trace:
#0 [internal function]: CodeIgniter\Debug\Exceptions->errorHandler(2, 'pg_query(): Que...', 'C:\\xampp\\htdocs...', 135)
#1 C:\xampp\htdocs\dfpyme\system\Database\Postgre\Connection.php(135): pg_query(Resource id #155, '\r\n        SELEC...')
#2 C:\xampp\htdocs\dfpyme\system\Database\BaseConnection.php(670): CodeIgniter\Database\Postgre\Connection->execute('\r\n        SELEC...')
#3 C:\xampp\htdocs\dfpyme\system\Database\BaseConnection.php(598): CodeIgniter\Database\BaseConnection->simpleQuery('\r\n        SELEC...')
#4 C:\xampp\htdocs\dfpyme\app\Models\pedidoModel.php(94): CodeIgniter\Database\BaseConnection->query('\r\n        SELEC...')
#5 C:\xampp\htdocs\dfpyme\app\Controllers\reportes\ReportesController.php(779): App\Models\pedidoModel->update_mesa()
#6 C:\xampp\htdocs\dfpyme\system\CodeIgniter.php(832): App\Controllers\reportes\ReportesController->actualizacion_estado_mesas()
#7 C:\xampp\htdocs\dfpyme\system\CodeIgniter.php(419): CodeIgniter\CodeIgniter->runController(Object(App\Controllers\reportes\ReportesController))
#8 C:\xampp\htdocs\dfpyme\system\CodeIgniter.php(326): CodeIgniter\CodeIgniter->handleRequest(NULL, Object(Config\Cache), false)
#9 C:\xampp\htdocs\dfpyme\index.php(37): CodeIgniter\CodeIgniter->run()
#10 {main}
CRITICAL - 2025-06-28 13:45:58 --> pg_query(): Query failed: ERROR:  no existe la relación «pedido»
LINE 11:             pedido
                     ^
#0 [internal function]: CodeIgniter\Debug\Exceptions->errorHandler(2, 'pg_query(): Que...', 'C:\\xampp\\htdocs...', 135)
#1 C:\xampp\htdocs\dfpyme\system\Database\Postgre\Connection.php(135): pg_query(Resource id #155, '\r\n        SELEC...')
#2 C:\xampp\htdocs\dfpyme\system\Database\BaseConnection.php(670): CodeIgniter\Database\Postgre\Connection->execute('\r\n        SELEC...')
#3 C:\xampp\htdocs\dfpyme\system\Database\BaseConnection.php(598): CodeIgniter\Database\BaseConnection->simpleQuery('\r\n        SELEC...')
#4 C:\xampp\htdocs\dfpyme\app\Models\pedidoModel.php(94): CodeIgniter\Database\BaseConnection->query('\r\n        SELEC...')
#5 C:\xampp\htdocs\dfpyme\app\Controllers\reportes\ReportesController.php(779): App\Models\pedidoModel->update_mesa()
#6 C:\xampp\htdocs\dfpyme\system\CodeIgniter.php(832): App\Controllers\reportes\ReportesController->actualizacion_estado_mesas()
#7 C:\xampp\htdocs\dfpyme\system\CodeIgniter.php(419): CodeIgniter\CodeIgniter->runController(Object(App\Controllers\reportes\ReportesController))
#8 C:\xampp\htdocs\dfpyme\system\CodeIgniter.php(326): CodeIgniter\CodeIgniter->handleRequest(NULL, Object(Config\Cache), false)
#9 C:\xampp\htdocs\dfpyme\index.php(37): CodeIgniter\CodeIgniter->run()
#10 {main}
CRITICAL - 2025-06-28 13:45:58 --> Uncaught CodeIgniter\Format\Exceptions\FormatException: Failed to parse json string, error: "Type is not supported". in C:\xampp\htdocs\dfpyme\system\Format\JSONFormatter.php:41
Stack trace:
#0 C:\xampp\htdocs\dfpyme\system\Format\JSONFormatter.php(41): CodeIgniter\Format\Exceptions\FormatException::forInvalidJSON('Type is not sup...')
#1 C:\xampp\htdocs\dfpyme\system\API\ResponseTrait.php(341): CodeIgniter\Format\JSONFormatter->format(Array)
#2 C:\xampp\htdocs\dfpyme\system\API\ResponseTrait.php(99): CodeIgniter\Debug\Exceptions->format(Array)
#3 C:\xampp\htdocs\dfpyme\system\Debug\Exceptions.php(115): CodeIgniter\Debug\Exceptions->respond(Array, 500)
#4 [internal function]: CodeIgniter\Debug\Exceptions->exceptionHandler(Object(ErrorException))
#5 {main}
  thrown
#0 [internal function]: CodeIgniter\Debug\Exceptions->shutdownHandler()
#1 {main}
ERROR - 2025-06-28 13:45:59 --> ErrorException: pg_query(): Query failed: ERROR:  no existe la relación «pedido»
LINE 11:             pedido
                     ^ in C:\xampp\htdocs\dfpyme\system\Database\Postgre\Connection.php:135
Stack trace:
#0 [internal function]: CodeIgniter\Debug\Exceptions->errorHandler(2, 'pg_query(): Que...', 'C:\\xampp\\htdocs...', 135)
#1 C:\xampp\htdocs\dfpyme\system\Database\Postgre\Connection.php(135): pg_query(Resource id #155, '\r\n        SELEC...')
#2 C:\xampp\htdocs\dfpyme\system\Database\BaseConnection.php(670): CodeIgniter\Database\Postgre\Connection->execute('\r\n        SELEC...')
#3 C:\xampp\htdocs\dfpyme\system\Database\BaseConnection.php(598): CodeIgniter\Database\BaseConnection->simpleQuery('\r\n        SELEC...')
#4 C:\xampp\htdocs\dfpyme\app\Models\pedidoModel.php(94): CodeIgniter\Database\BaseConnection->query('\r\n        SELEC...')
#5 C:\xampp\htdocs\dfpyme\app\Controllers\reportes\ReportesController.php(779): App\Models\pedidoModel->update_mesa()
#6 C:\xampp\htdocs\dfpyme\system\CodeIgniter.php(832): App\Controllers\reportes\ReportesController->actualizacion_estado_mesas()
#7 C:\xampp\htdocs\dfpyme\system\CodeIgniter.php(419): CodeIgniter\CodeIgniter->runController(Object(App\Controllers\reportes\ReportesController))
#8 C:\xampp\htdocs\dfpyme\system\CodeIgniter.php(326): CodeIgniter\CodeIgniter->handleRequest(NULL, Object(Config\Cache), false)
#9 C:\xampp\htdocs\dfpyme\index.php(37): CodeIgniter\CodeIgniter->run()
#10 {main}
CRITICAL - 2025-06-28 13:45:59 --> pg_query(): Query failed: ERROR:  no existe la relación «pedido»
LINE 11:             pedido
                     ^
#0 [internal function]: CodeIgniter\Debug\Exceptions->errorHandler(2, 'pg_query(): Que...', 'C:\\xampp\\htdocs...', 135)
#1 C:\xampp\htdocs\dfpyme\system\Database\Postgre\Connection.php(135): pg_query(Resource id #155, '\r\n        SELEC...')
#2 C:\xampp\htdocs\dfpyme\system\Database\BaseConnection.php(670): CodeIgniter\Database\Postgre\Connection->execute('\r\n        SELEC...')
#3 C:\xampp\htdocs\dfpyme\system\Database\BaseConnection.php(598): CodeIgniter\Database\BaseConnection->simpleQuery('\r\n        SELEC...')
#4 C:\xampp\htdocs\dfpyme\app\Models\pedidoModel.php(94): CodeIgniter\Database\BaseConnection->query('\r\n        SELEC...')
#5 C:\xampp\htdocs\dfpyme\app\Controllers\reportes\ReportesController.php(779): App\Models\pedidoModel->update_mesa()
#6 C:\xampp\htdocs\dfpyme\system\CodeIgniter.php(832): App\Controllers\reportes\ReportesController->actualizacion_estado_mesas()
#7 C:\xampp\htdocs\dfpyme\system\CodeIgniter.php(419): CodeIgniter\CodeIgniter->runController(Object(App\Controllers\reportes\ReportesController))
#8 C:\xampp\htdocs\dfpyme\system\CodeIgniter.php(326): CodeIgniter\CodeIgniter->handleRequest(NULL, Object(Config\Cache), false)
#9 C:\xampp\htdocs\dfpyme\index.php(37): CodeIgniter\CodeIgniter->run()
#10 {main}
CRITICAL - 2025-06-28 13:45:59 --> Uncaught CodeIgniter\Format\Exceptions\FormatException: Failed to parse json string, error: "Type is not supported". in C:\xampp\htdocs\dfpyme\system\Format\JSONFormatter.php:41
Stack trace:
#0 C:\xampp\htdocs\dfpyme\system\Format\JSONFormatter.php(41): CodeIgniter\Format\Exceptions\FormatException::forInvalidJSON('Type is not sup...')
#1 C:\xampp\htdocs\dfpyme\system\API\ResponseTrait.php(341): CodeIgniter\Format\JSONFormatter->format(Array)
#2 C:\xampp\htdocs\dfpyme\system\API\ResponseTrait.php(99): CodeIgniter\Debug\Exceptions->format(Array)
#3 C:\xampp\htdocs\dfpyme\system\Debug\Exceptions.php(115): CodeIgniter\Debug\Exceptions->respond(Array, 500)
#4 [internal function]: CodeIgniter\Debug\Exceptions->exceptionHandler(Object(ErrorException))
#5 {main}
  thrown
#0 [internal function]: CodeIgniter\Debug\Exceptions->shutdownHandler()
#1 {main}
ERROR - 2025-06-28 13:46:00 --> ErrorException: pg_query(): Query failed: ERROR:  no existe la relación «pedido»
LINE 11:             pedido
                     ^ in C:\xampp\htdocs\dfpyme\system\Database\Postgre\Connection.php:135
Stack trace:
#0 [internal function]: CodeIgniter\Debug\Exceptions->errorHandler(2, 'pg_query(): Que...', 'C:\\xampp\\htdocs...', 135)
#1 C:\xampp\htdocs\dfpyme\system\Database\Postgre\Connection.php(135): pg_query(Resource id #155, '\r\n        SELEC...')
#2 C:\xampp\htdocs\dfpyme\system\Database\BaseConnection.php(670): CodeIgniter\Database\Postgre\Connection->execute('\r\n        SELEC...')
#3 C:\xampp\htdocs\dfpyme\system\Database\BaseConnection.php(598): CodeIgniter\Database\BaseConnection->simpleQuery('\r\n        SELEC...')
#4 C:\xampp\htdocs\dfpyme\app\Models\pedidoModel.php(94): CodeIgniter\Database\BaseConnection->query('\r\n        SELEC...')
#5 C:\xampp\htdocs\dfpyme\app\Controllers\reportes\ReportesController.php(779): App\Models\pedidoModel->update_mesa()
#6 C:\xampp\htdocs\dfpyme\system\CodeIgniter.php(832): App\Controllers\reportes\ReportesController->actualizacion_estado_mesas()
#7 C:\xampp\htdocs\dfpyme\system\CodeIgniter.php(419): CodeIgniter\CodeIgniter->runController(Object(App\Controllers\reportes\ReportesController))
#8 C:\xampp\htdocs\dfpyme\system\CodeIgniter.php(326): CodeIgniter\CodeIgniter->handleRequest(NULL, Object(Config\Cache), false)
#9 C:\xampp\htdocs\dfpyme\index.php(37): CodeIgniter\CodeIgniter->run()
#10 {main}
CRITICAL - 2025-06-28 13:46:00 --> pg_query(): Query failed: ERROR:  no existe la relación «pedido»
LINE 11:             pedido
                     ^
#0 [internal function]: CodeIgniter\Debug\Exceptions->errorHandler(2, 'pg_query(): Que...', 'C:\\xampp\\htdocs...', 135)
#1 C:\xampp\htdocs\dfpyme\system\Database\Postgre\Connection.php(135): pg_query(Resource id #155, '\r\n        SELEC...')
#2 C:\xampp\htdocs\dfpyme\system\Database\BaseConnection.php(670): CodeIgniter\Database\Postgre\Connection->execute('\r\n        SELEC...')
#3 C:\xampp\htdocs\dfpyme\system\Database\BaseConnection.php(598): CodeIgniter\Database\BaseConnection->simpleQuery('\r\n        SELEC...')
#4 C:\xampp\htdocs\dfpyme\app\Models\pedidoModel.php(94): CodeIgniter\Database\BaseConnection->query('\r\n        SELEC...')
#5 C:\xampp\htdocs\dfpyme\app\Controllers\reportes\ReportesController.php(779): App\Models\pedidoModel->update_mesa()
#6 C:\xampp\htdocs\dfpyme\system\CodeIgniter.php(832): App\Controllers\reportes\ReportesController->actualizacion_estado_mesas()
#7 C:\xampp\htdocs\dfpyme\system\CodeIgniter.php(419): CodeIgniter\CodeIgniter->runController(Object(App\Controllers\reportes\ReportesController))
#8 C:\xampp\htdocs\dfpyme\system\CodeIgniter.php(326): CodeIgniter\CodeIgniter->handleRequest(NULL, Object(Config\Cache), false)
#9 C:\xampp\htdocs\dfpyme\index.php(37): CodeIgniter\CodeIgniter->run()
#10 {main}
CRITICAL - 2025-06-28 13:46:00 --> Uncaught CodeIgniter\Format\Exceptions\FormatException: Failed to parse json string, error: "Type is not supported". in C:\xampp\htdocs\dfpyme\system\Format\JSONFormatter.php:41
Stack trace:
#0 C:\xampp\htdocs\dfpyme\system\Format\JSONFormatter.php(41): CodeIgniter\Format\Exceptions\FormatException::forInvalidJSON('Type is not sup...')
#1 C:\xampp\htdocs\dfpyme\system\API\ResponseTrait.php(341): CodeIgniter\Format\JSONFormatter->format(Array)
#2 C:\xampp\htdocs\dfpyme\system\API\ResponseTrait.php(99): CodeIgniter\Debug\Exceptions->format(Array)
#3 C:\xampp\htdocs\dfpyme\system\Debug\Exceptions.php(115): CodeIgniter\Debug\Exceptions->respond(Array, 500)
#4 [internal function]: CodeIgniter\Debug\Exceptions->exceptionHandler(Object(ErrorException))
#5 {main}
  thrown
#0 [internal function]: CodeIgniter\Debug\Exceptions->shutdownHandler()
#1 {main}
ERROR - 2025-06-28 13:46:01 --> ErrorException: pg_query(): Query failed: ERROR:  no existe la relación «pedido»
LINE 11:             pedido
                     ^ in C:\xampp\htdocs\dfpyme\system\Database\Postgre\Connection.php:135
Stack trace:
#0 [internal function]: CodeIgniter\Debug\Exceptions->errorHandler(2, 'pg_query(): Que...', 'C:\\xampp\\htdocs...', 135)
#1 C:\xampp\htdocs\dfpyme\system\Database\Postgre\Connection.php(135): pg_query(Resource id #155, '\r\n        SELEC...')
#2 C:\xampp\htdocs\dfpyme\system\Database\BaseConnection.php(670): CodeIgniter\Database\Postgre\Connection->execute('\r\n        SELEC...')
#3 C:\xampp\htdocs\dfpyme\system\Database\BaseConnection.php(598): CodeIgniter\Database\BaseConnection->simpleQuery('\r\n        SELEC...')
#4 C:\xampp\htdocs\dfpyme\app\Models\pedidoModel.php(94): CodeIgniter\Database\BaseConnection->query('\r\n        SELEC...')
#5 C:\xampp\htdocs\dfpyme\app\Controllers\reportes\ReportesController.php(779): App\Models\pedidoModel->update_mesa()
#6 C:\xampp\htdocs\dfpyme\system\CodeIgniter.php(832): App\Controllers\reportes\ReportesController->actualizacion_estado_mesas()
#7 C:\xampp\htdocs\dfpyme\system\CodeIgniter.php(419): CodeIgniter\CodeIgniter->runController(Object(App\Controllers\reportes\ReportesController))
#8 C:\xampp\htdocs\dfpyme\system\CodeIgniter.php(326): CodeIgniter\CodeIgniter->handleRequest(NULL, Object(Config\Cache), false)
#9 C:\xampp\htdocs\dfpyme\index.php(37): CodeIgniter\CodeIgniter->run()
#10 {main}
CRITICAL - 2025-06-28 13:46:01 --> pg_query(): Query failed: ERROR:  no existe la relación «pedido»
LINE 11:             pedido
                     ^
#0 [internal function]: CodeIgniter\Debug\Exceptions->errorHandler(2, 'pg_query(): Que...', 'C:\\xampp\\htdocs...', 135)
#1 C:\xampp\htdocs\dfpyme\system\Database\Postgre\Connection.php(135): pg_query(Resource id #155, '\r\n        SELEC...')
#2 C:\xampp\htdocs\dfpyme\system\Database\BaseConnection.php(670): CodeIgniter\Database\Postgre\Connection->execute('\r\n        SELEC...')
#3 C:\xampp\htdocs\dfpyme\system\Database\BaseConnection.php(598): CodeIgniter\Database\BaseConnection->simpleQuery('\r\n        SELEC...')
#4 C:\xampp\htdocs\dfpyme\app\Models\pedidoModel.php(94): CodeIgniter\Database\BaseConnection->query('\r\n        SELEC...')
#5 C:\xampp\htdocs\dfpyme\app\Controllers\reportes\ReportesController.php(779): App\Models\pedidoModel->update_mesa()
#6 C:\xampp\htdocs\dfpyme\system\CodeIgniter.php(832): App\Controllers\reportes\ReportesController->actualizacion_estado_mesas()
#7 C:\xampp\htdocs\dfpyme\system\CodeIgniter.php(419): CodeIgniter\CodeIgniter->runController(Object(App\Controllers\reportes\ReportesController))
#8 C:\xampp\htdocs\dfpyme\system\CodeIgniter.php(326): CodeIgniter\CodeIgniter->handleRequest(NULL, Object(Config\Cache), false)
#9 C:\xampp\htdocs\dfpyme\index.php(37): CodeIgniter\CodeIgniter->run()
#10 {main}
CRITICAL - 2025-06-28 13:46:01 --> Uncaught CodeIgniter\Format\Exceptions\FormatException: Failed to parse json string, error: "Type is not supported". in C:\xampp\htdocs\dfpyme\system\Format\JSONFormatter.php:41
Stack trace:
#0 C:\xampp\htdocs\dfpyme\system\Format\JSONFormatter.php(41): CodeIgniter\Format\Exceptions\FormatException::forInvalidJSON('Type is not sup...')
#1 C:\xampp\htdocs\dfpyme\system\API\ResponseTrait.php(341): CodeIgniter\Format\JSONFormatter->format(Array)
#2 C:\xampp\htdocs\dfpyme\system\API\ResponseTrait.php(99): CodeIgniter\Debug\Exceptions->format(Array)
#3 C:\xampp\htdocs\dfpyme\system\Debug\Exceptions.php(115): CodeIgniter\Debug\Exceptions->respond(Array, 500)
#4 [internal function]: CodeIgniter\Debug\Exceptions->exceptionHandler(Object(ErrorException))
#5 {main}
  thrown
#0 [internal function]: CodeIgniter\Debug\Exceptions->shutdownHandler()
#1 {main}
ERROR - 2025-06-28 13:46:02 --> ErrorException: pg_query(): Query failed: ERROR:  no existe la relación «pedido»
LINE 11:             pedido
                     ^ in C:\xampp\htdocs\dfpyme\system\Database\Postgre\Connection.php:135
Stack trace:
#0 [internal function]: CodeIgniter\Debug\Exceptions->errorHandler(2, 'pg_query(): Que...', 'C:\\xampp\\htdocs...', 135)
#1 C:\xampp\htdocs\dfpyme\system\Database\Postgre\Connection.php(135): pg_query(Resource id #155, '\r\n        SELEC...')
#2 C:\xampp\htdocs\dfpyme\system\Database\BaseConnection.php(670): CodeIgniter\Database\Postgre\Connection->execute('\r\n        SELEC...')
#3 C:\xampp\htdocs\dfpyme\system\Database\BaseConnection.php(598): CodeIgniter\Database\BaseConnection->simpleQuery('\r\n        SELEC...')
#4 C:\xampp\htdocs\dfpyme\app\Models\pedidoModel.php(94): CodeIgniter\Database\BaseConnection->query('\r\n        SELEC...')
#5 C:\xampp\htdocs\dfpyme\app\Controllers\reportes\ReportesController.php(779): App\Models\pedidoModel->update_mesa()
#6 C:\xampp\htdocs\dfpyme\system\CodeIgniter.php(832): App\Controllers\reportes\ReportesController->actualizacion_estado_mesas()
#7 C:\xampp\htdocs\dfpyme\system\CodeIgniter.php(419): CodeIgniter\CodeIgniter->runController(Object(App\Controllers\reportes\ReportesController))
#8 C:\xampp\htdocs\dfpyme\system\CodeIgniter.php(326): CodeIgniter\CodeIgniter->handleRequest(NULL, Object(Config\Cache), false)
#9 C:\xampp\htdocs\dfpyme\index.php(37): CodeIgniter\CodeIgniter->run()
#10 {main}
CRITICAL - 2025-06-28 13:46:02 --> pg_query(): Query failed: ERROR:  no existe la relación «pedido»
LINE 11:             pedido
                     ^
#0 [internal function]: CodeIgniter\Debug\Exceptions->errorHandler(2, 'pg_query(): Que...', 'C:\\xampp\\htdocs...', 135)
#1 C:\xampp\htdocs\dfpyme\system\Database\Postgre\Connection.php(135): pg_query(Resource id #155, '\r\n        SELEC...')
#2 C:\xampp\htdocs\dfpyme\system\Database\BaseConnection.php(670): CodeIgniter\Database\Postgre\Connection->execute('\r\n        SELEC...')
#3 C:\xampp\htdocs\dfpyme\system\Database\BaseConnection.php(598): CodeIgniter\Database\BaseConnection->simpleQuery('\r\n        SELEC...')
#4 C:\xampp\htdocs\dfpyme\app\Models\pedidoModel.php(94): CodeIgniter\Database\BaseConnection->query('\r\n        SELEC...')
#5 C:\xampp\htdocs\dfpyme\app\Controllers\reportes\ReportesController.php(779): App\Models\pedidoModel->update_mesa()
#6 C:\xampp\htdocs\dfpyme\system\CodeIgniter.php(832): App\Controllers\reportes\ReportesController->actualizacion_estado_mesas()
#7 C:\xampp\htdocs\dfpyme\system\CodeIgniter.php(419): CodeIgniter\CodeIgniter->runController(Object(App\Controllers\reportes\ReportesController))
#8 C:\xampp\htdocs\dfpyme\system\CodeIgniter.php(326): CodeIgniter\CodeIgniter->handleRequest(NULL, Object(Config\Cache), false)
#9 C:\xampp\htdocs\dfpyme\index.php(37): CodeIgniter\CodeIgniter->run()
#10 {main}
CRITICAL - 2025-06-28 13:46:02 --> Uncaught CodeIgniter\Format\Exceptions\FormatException: Failed to parse json string, error: "Type is not supported". in C:\xampp\htdocs\dfpyme\system\Format\JSONFormatter.php:41
Stack trace:
#0 C:\xampp\htdocs\dfpyme\system\Format\JSONFormatter.php(41): CodeIgniter\Format\Exceptions\FormatException::forInvalidJSON('Type is not sup...')
#1 C:\xampp\htdocs\dfpyme\system\API\ResponseTrait.php(341): CodeIgniter\Format\JSONFormatter->format(Array)
#2 C:\xampp\htdocs\dfpyme\system\API\ResponseTrait.php(99): CodeIgniter\Debug\Exceptions->format(Array)
#3 C:\xampp\htdocs\dfpyme\system\Debug\Exceptions.php(115): CodeIgniter\Debug\Exceptions->respond(Array, 500)
#4 [internal function]: CodeIgniter\Debug\Exceptions->exceptionHandler(Object(ErrorException))
#5 {main}
  thrown
#0 [internal function]: CodeIgniter\Debug\Exceptions->shutdownHandler()
#1 {main}
ERROR - 2025-06-28 13:46:03 --> ErrorException: pg_query(): Query failed: ERROR:  no existe la relación «apertura_registro»
LINE 2: FROM &quot;apertura_registro&quot;
             ^ in C:\xampp\htdocs\dfpyme\system\Database\Postgre\Connection.php:135
Stack trace:
#0 [internal function]: CodeIgniter\Debug\Exceptions->errorHandler(2, 'pg_query(): Que...', 'C:\\xampp\\htdocs...', 135)
#1 C:\xampp\htdocs\dfpyme\system\Database\Postgre\Connection.php(135): pg_query(Resource id #157, 'SELECT "numero"...')
#2 C:\xampp\htdocs\dfpyme\system\Database\BaseConnection.php(670): CodeIgniter\Database\Postgre\Connection->execute('SELECT "numero"...')
#3 C:\xampp\htdocs\dfpyme\system\Database\BaseConnection.php(598): CodeIgniter\Database\BaseConnection->simpleQuery('SELECT "numero"...')
#4 C:\xampp\htdocs\dfpyme\system\Database\BaseBuilder.php(1455): CodeIgniter\Database\BaseConnection->query('SELECT "numero"...', Array, false)
#5 C:\xampp\htdocs\dfpyme\system\Model.php(210): CodeIgniter\Database\BaseBuilder->get()
#6 C:\xampp\htdocs\dfpyme\system\BaseModel.php(622): CodeIgniter\Model->doFirst()
#7 C:\xampp\htdocs\dfpyme\app\Controllers\reportes\ReportesController.php(653): CodeIgniter\BaseModel->first()
#8 C:\xampp\htdocs\dfpyme\system\CodeIgniter.php(832): App\Controllers\reportes\ReportesController->total_ventas_electronicas()
#9 C:\xampp\htdocs\dfpyme\system\CodeIgniter.php(419): CodeIgniter\CodeIgniter->runController(Object(App\Controllers\reportes\ReportesController))
#10 C:\xampp\htdocs\dfpyme\system\CodeIgniter.php(326): CodeIgniter\CodeIgniter->handleRequest(NULL, Object(Config\Cache), false)
#11 C:\xampp\htdocs\dfpyme\index.php(37): CodeIgniter\CodeIgniter->run()
#12 {main}
CRITICAL - 2025-06-28 13:46:03 --> pg_query(): Query failed: ERROR:  no existe la relación «apertura_registro»
LINE 2: FROM &quot;apertura_registro&quot;
             ^
#0 [internal function]: CodeIgniter\Debug\Exceptions->errorHandler(2, 'pg_query(): Que...', 'C:\\xampp\\htdocs...', 135)
#1 C:\xampp\htdocs\dfpyme\system\Database\Postgre\Connection.php(135): pg_query(Resource id #157, 'SELECT "numero"...')
#2 C:\xampp\htdocs\dfpyme\system\Database\BaseConnection.php(670): CodeIgniter\Database\Postgre\Connection->execute('SELECT "numero"...')
#3 C:\xampp\htdocs\dfpyme\system\Database\BaseConnection.php(598): CodeIgniter\Database\BaseConnection->simpleQuery('SELECT "numero"...')
#4 C:\xampp\htdocs\dfpyme\system\Database\BaseBuilder.php(1455): CodeIgniter\Database\BaseConnection->query('SELECT "numero"...', Array, false)
#5 C:\xampp\htdocs\dfpyme\system\Model.php(210): CodeIgniter\Database\BaseBuilder->get()
#6 C:\xampp\htdocs\dfpyme\system\BaseModel.php(622): CodeIgniter\Model->doFirst()
#7 C:\xampp\htdocs\dfpyme\app\Controllers\reportes\ReportesController.php(653): CodeIgniter\BaseModel->first()
#8 C:\xampp\htdocs\dfpyme\system\CodeIgniter.php(832): App\Controllers\reportes\ReportesController->total_ventas_electronicas()
#9 C:\xampp\htdocs\dfpyme\system\CodeIgniter.php(419): CodeIgniter\CodeIgniter->runController(Object(App\Controllers\reportes\ReportesController))
#10 C:\xampp\htdocs\dfpyme\system\CodeIgniter.php(326): CodeIgniter\CodeIgniter->handleRequest(NULL, Object(Config\Cache), false)
#11 C:\xampp\htdocs\dfpyme\index.php(37): CodeIgniter\CodeIgniter->run()
#12 {main}
CRITICAL - 2025-06-28 13:46:03 --> Uncaught CodeIgniter\Format\Exceptions\FormatException: Failed to parse json string, error: "Type is not supported". in C:\xampp\htdocs\dfpyme\system\Format\JSONFormatter.php:41
Stack trace:
#0 C:\xampp\htdocs\dfpyme\system\Format\JSONFormatter.php(41): CodeIgniter\Format\Exceptions\FormatException::forInvalidJSON('Type is not sup...')
#1 C:\xampp\htdocs\dfpyme\system\API\ResponseTrait.php(341): CodeIgniter\Format\JSONFormatter->format(Array)
#2 C:\xampp\htdocs\dfpyme\system\API\ResponseTrait.php(99): CodeIgniter\Debug\Exceptions->format(Array)
#3 C:\xampp\htdocs\dfpyme\system\Debug\Exceptions.php(115): CodeIgniter\Debug\Exceptions->respond(Array, 500)
#4 [internal function]: CodeIgniter\Debug\Exceptions->exceptionHandler(Object(ErrorException))
#5 {main}
  thrown
#0 [internal function]: CodeIgniter\Debug\Exceptions->shutdownHandler()
#1 {main}
ERROR - 2025-06-28 13:46:03 --> ErrorException: pg_query(): Query failed: ERROR:  no existe la relación «pedido»
LINE 11:             pedido
                     ^ in C:\xampp\htdocs\dfpyme\system\Database\Postgre\Connection.php:135
Stack trace:
#0 [internal function]: CodeIgniter\Debug\Exceptions->errorHandler(2, 'pg_query(): Que...', 'C:\\xampp\\htdocs...', 135)
#1 C:\xampp\htdocs\dfpyme\system\Database\Postgre\Connection.php(135): pg_query(Resource id #155, '\r\n        SELEC...')
#2 C:\xampp\htdocs\dfpyme\system\Database\BaseConnection.php(670): CodeIgniter\Database\Postgre\Connection->execute('\r\n        SELEC...')
#3 C:\xampp\htdocs\dfpyme\system\Database\BaseConnection.php(598): CodeIgniter\Database\BaseConnection->simpleQuery('\r\n        SELEC...')
#4 C:\xampp\htdocs\dfpyme\app\Models\pedidoModel.php(94): CodeIgniter\Database\BaseConnection->query('\r\n        SELEC...')
#5 C:\xampp\htdocs\dfpyme\app\Controllers\reportes\ReportesController.php(779): App\Models\pedidoModel->update_mesa()
#6 C:\xampp\htdocs\dfpyme\system\CodeIgniter.php(832): App\Controllers\reportes\ReportesController->actualizacion_estado_mesas()
#7 C:\xampp\htdocs\dfpyme\system\CodeIgniter.php(419): CodeIgniter\CodeIgniter->runController(Object(App\Controllers\reportes\ReportesController))
#8 C:\xampp\htdocs\dfpyme\system\CodeIgniter.php(326): CodeIgniter\CodeIgniter->handleRequest(NULL, Object(Config\Cache), false)
#9 C:\xampp\htdocs\dfpyme\index.php(37): CodeIgniter\CodeIgniter->run()
#10 {main}
CRITICAL - 2025-06-28 13:46:03 --> pg_query(): Query failed: ERROR:  no existe la relación «pedido»
LINE 11:             pedido
                     ^
#0 [internal function]: CodeIgniter\Debug\Exceptions->errorHandler(2, 'pg_query(): Que...', 'C:\\xampp\\htdocs...', 135)
#1 C:\xampp\htdocs\dfpyme\system\Database\Postgre\Connection.php(135): pg_query(Resource id #155, '\r\n        SELEC...')
#2 C:\xampp\htdocs\dfpyme\system\Database\BaseConnection.php(670): CodeIgniter\Database\Postgre\Connection->execute('\r\n        SELEC...')
#3 C:\xampp\htdocs\dfpyme\system\Database\BaseConnection.php(598): CodeIgniter\Database\BaseConnection->simpleQuery('\r\n        SELEC...')
#4 C:\xampp\htdocs\dfpyme\app\Models\pedidoModel.php(94): CodeIgniter\Database\BaseConnection->query('\r\n        SELEC...')
#5 C:\xampp\htdocs\dfpyme\app\Controllers\reportes\ReportesController.php(779): App\Models\pedidoModel->update_mesa()
#6 C:\xampp\htdocs\dfpyme\system\CodeIgniter.php(832): App\Controllers\reportes\ReportesController->actualizacion_estado_mesas()
#7 C:\xampp\htdocs\dfpyme\system\CodeIgniter.php(419): CodeIgniter\CodeIgniter->runController(Object(App\Controllers\reportes\ReportesController))
#8 C:\xampp\htdocs\dfpyme\system\CodeIgniter.php(326): CodeIgniter\CodeIgniter->handleRequest(NULL, Object(Config\Cache), false)
#9 C:\xampp\htdocs\dfpyme\index.php(37): CodeIgniter\CodeIgniter->run()
#10 {main}
CRITICAL - 2025-06-28 13:46:03 --> Uncaught CodeIgniter\Format\Exceptions\FormatException: Failed to parse json string, error: "Type is not supported". in C:\xampp\htdocs\dfpyme\system\Format\JSONFormatter.php:41
Stack trace:
#0 C:\xampp\htdocs\dfpyme\system\Format\JSONFormatter.php(41): CodeIgniter\Format\Exceptions\FormatException::forInvalidJSON('Type is not sup...')
#1 C:\xampp\htdocs\dfpyme\system\API\ResponseTrait.php(341): CodeIgniter\Format\JSONFormatter->format(Array)
#2 C:\xampp\htdocs\dfpyme\system\API\ResponseTrait.php(99): CodeIgniter\Debug\Exceptions->format(Array)
#3 C:\xampp\htdocs\dfpyme\system\Debug\Exceptions.php(115): CodeIgniter\Debug\Exceptions->respond(Array, 500)
#4 [internal function]: CodeIgniter\Debug\Exceptions->exceptionHandler(Object(ErrorException))
#5 {main}
  thrown
#0 [internal function]: CodeIgniter\Debug\Exceptions->shutdownHandler()
#1 {main}
ERROR - 2025-06-28 13:46:04 --> ErrorException: pg_query(): Query failed: ERROR:  no existe la relación «pedido»
LINE 11:             pedido
                     ^ in C:\xampp\htdocs\dfpyme\system\Database\Postgre\Connection.php:135
Stack trace:
#0 [internal function]: CodeIgniter\Debug\Exceptions->errorHandler(2, 'pg_query(): Que...', 'C:\\xampp\\htdocs...', 135)
#1 C:\xampp\htdocs\dfpyme\system\Database\Postgre\Connection.php(135): pg_query(Resource id #155, '\r\n        SELEC...')
#2 C:\xampp\htdocs\dfpyme\system\Database\BaseConnection.php(670): CodeIgniter\Database\Postgre\Connection->execute('\r\n        SELEC...')
#3 C:\xampp\htdocs\dfpyme\system\Database\BaseConnection.php(598): CodeIgniter\Database\BaseConnection->simpleQuery('\r\n        SELEC...')
#4 C:\xampp\htdocs\dfpyme\app\Models\pedidoModel.php(94): CodeIgniter\Database\BaseConnection->query('\r\n        SELEC...')
#5 C:\xampp\htdocs\dfpyme\app\Controllers\reportes\ReportesController.php(779): App\Models\pedidoModel->update_mesa()
#6 C:\xampp\htdocs\dfpyme\system\CodeIgniter.php(832): App\Controllers\reportes\ReportesController->actualizacion_estado_mesas()
#7 C:\xampp\htdocs\dfpyme\system\CodeIgniter.php(419): CodeIgniter\CodeIgniter->runController(Object(App\Controllers\reportes\ReportesController))
#8 C:\xampp\htdocs\dfpyme\system\CodeIgniter.php(326): CodeIgniter\CodeIgniter->handleRequest(NULL, Object(Config\Cache), false)
#9 C:\xampp\htdocs\dfpyme\index.php(37): CodeIgniter\CodeIgniter->run()
#10 {main}
CRITICAL - 2025-06-28 13:46:04 --> pg_query(): Query failed: ERROR:  no existe la relación «pedido»
LINE 11:             pedido
                     ^
#0 [internal function]: CodeIgniter\Debug\Exceptions->errorHandler(2, 'pg_query(): Que...', 'C:\\xampp\\htdocs...', 135)
#1 C:\xampp\htdocs\dfpyme\system\Database\Postgre\Connection.php(135): pg_query(Resource id #155, '\r\n        SELEC...')
#2 C:\xampp\htdocs\dfpyme\system\Database\BaseConnection.php(670): CodeIgniter\Database\Postgre\Connection->execute('\r\n        SELEC...')
#3 C:\xampp\htdocs\dfpyme\system\Database\BaseConnection.php(598): CodeIgniter\Database\BaseConnection->simpleQuery('\r\n        SELEC...')
#4 C:\xampp\htdocs\dfpyme\app\Models\pedidoModel.php(94): CodeIgniter\Database\BaseConnection->query('\r\n        SELEC...')
#5 C:\xampp\htdocs\dfpyme\app\Controllers\reportes\ReportesController.php(779): App\Models\pedidoModel->update_mesa()
#6 C:\xampp\htdocs\dfpyme\system\CodeIgniter.php(832): App\Controllers\reportes\ReportesController->actualizacion_estado_mesas()
#7 C:\xampp\htdocs\dfpyme\system\CodeIgniter.php(419): CodeIgniter\CodeIgniter->runController(Object(App\Controllers\reportes\ReportesController))
#8 C:\xampp\htdocs\dfpyme\system\CodeIgniter.php(326): CodeIgniter\CodeIgniter->handleRequest(NULL, Object(Config\Cache), false)
#9 C:\xampp\htdocs\dfpyme\index.php(37): CodeIgniter\CodeIgniter->run()
#10 {main}
CRITICAL - 2025-06-28 13:46:04 --> Uncaught CodeIgniter\Format\Exceptions\FormatException: Failed to parse json string, error: "Type is not supported". in C:\xampp\htdocs\dfpyme\system\Format\JSONFormatter.php:41
Stack trace:
#0 C:\xampp\htdocs\dfpyme\system\Format\JSONFormatter.php(41): CodeIgniter\Format\Exceptions\FormatException::forInvalidJSON('Type is not sup...')
#1 C:\xampp\htdocs\dfpyme\system\API\ResponseTrait.php(341): CodeIgniter\Format\JSONFormatter->format(Array)
#2 C:\xampp\htdocs\dfpyme\system\API\ResponseTrait.php(99): CodeIgniter\Debug\Exceptions->format(Array)
#3 C:\xampp\htdocs\dfpyme\system\Debug\Exceptions.php(115): CodeIgniter\Debug\Exceptions->respond(Array, 500)
#4 [internal function]: CodeIgniter\Debug\Exceptions->exceptionHandler(Object(ErrorException))
#5 {main}
  thrown
#0 [internal function]: CodeIgniter\Debug\Exceptions->shutdownHandler()
#1 {main}
ERROR - 2025-06-28 13:46:05 --> ErrorException: pg_query(): Query failed: ERROR:  no existe la relación «pedido»
LINE 11:             pedido
                     ^ in C:\xampp\htdocs\dfpyme\system\Database\Postgre\Connection.php:135
Stack trace:
#0 [internal function]: CodeIgniter\Debug\Exceptions->errorHandler(2, 'pg_query(): Que...', 'C:\\xampp\\htdocs...', 135)
#1 C:\xampp\htdocs\dfpyme\system\Database\Postgre\Connection.php(135): pg_query(Resource id #155, '\r\n        SELEC...')
#2 C:\xampp\htdocs\dfpyme\system\Database\BaseConnection.php(670): CodeIgniter\Database\Postgre\Connection->execute('\r\n        SELEC...')
#3 C:\xampp\htdocs\dfpyme\system\Database\BaseConnection.php(598): CodeIgniter\Database\BaseConnection->simpleQuery('\r\n        SELEC...')
#4 C:\xampp\htdocs\dfpyme\app\Models\pedidoModel.php(94): CodeIgniter\Database\BaseConnection->query('\r\n        SELEC...')
#5 C:\xampp\htdocs\dfpyme\app\Controllers\reportes\ReportesController.php(779): App\Models\pedidoModel->update_mesa()
#6 C:\xampp\htdocs\dfpyme\system\CodeIgniter.php(832): App\Controllers\reportes\ReportesController->actualizacion_estado_mesas()
#7 C:\xampp\htdocs\dfpyme\system\CodeIgniter.php(419): CodeIgniter\CodeIgniter->runController(Object(App\Controllers\reportes\ReportesController))
#8 C:\xampp\htdocs\dfpyme\system\CodeIgniter.php(326): CodeIgniter\CodeIgniter->handleRequest(NULL, Object(Config\Cache), false)
#9 C:\xampp\htdocs\dfpyme\index.php(37): CodeIgniter\CodeIgniter->run()
#10 {main}
CRITICAL - 2025-06-28 13:46:05 --> pg_query(): Query failed: ERROR:  no existe la relación «pedido»
LINE 11:             pedido
                     ^
#0 [internal function]: CodeIgniter\Debug\Exceptions->errorHandler(2, 'pg_query(): Que...', 'C:\\xampp\\htdocs...', 135)
#1 C:\xampp\htdocs\dfpyme\system\Database\Postgre\Connection.php(135): pg_query(Resource id #155, '\r\n        SELEC...')
#2 C:\xampp\htdocs\dfpyme\system\Database\BaseConnection.php(670): CodeIgniter\Database\Postgre\Connection->execute('\r\n        SELEC...')
#3 C:\xampp\htdocs\dfpyme\system\Database\BaseConnection.php(598): CodeIgniter\Database\BaseConnection->simpleQuery('\r\n        SELEC...')
#4 C:\xampp\htdocs\dfpyme\app\Models\pedidoModel.php(94): CodeIgniter\Database\BaseConnection->query('\r\n        SELEC...')
#5 C:\xampp\htdocs\dfpyme\app\Controllers\reportes\ReportesController.php(779): App\Models\pedidoModel->update_mesa()
#6 C:\xampp\htdocs\dfpyme\system\CodeIgniter.php(832): App\Controllers\reportes\ReportesController->actualizacion_estado_mesas()
#7 C:\xampp\htdocs\dfpyme\system\CodeIgniter.php(419): CodeIgniter\CodeIgniter->runController(Object(App\Controllers\reportes\ReportesController))
#8 C:\xampp\htdocs\dfpyme\system\CodeIgniter.php(326): CodeIgniter\CodeIgniter->handleRequest(NULL, Object(Config\Cache), false)
#9 C:\xampp\htdocs\dfpyme\index.php(37): CodeIgniter\CodeIgniter->run()
#10 {main}
CRITICAL - 2025-06-28 13:46:05 --> Uncaught CodeIgniter\Format\Exceptions\FormatException: Failed to parse json string, error: "Type is not supported". in C:\xampp\htdocs\dfpyme\system\Format\JSONFormatter.php:41
Stack trace:
#0 C:\xampp\htdocs\dfpyme\system\Format\JSONFormatter.php(41): CodeIgniter\Format\Exceptions\FormatException::forInvalidJSON('Type is not sup...')
#1 C:\xampp\htdocs\dfpyme\system\API\ResponseTrait.php(341): CodeIgniter\Format\JSONFormatter->format(Array)
#2 C:\xampp\htdocs\dfpyme\system\API\ResponseTrait.php(99): CodeIgniter\Debug\Exceptions->format(Array)
#3 C:\xampp\htdocs\dfpyme\system\Debug\Exceptions.php(115): CodeIgniter\Debug\Exceptions->respond(Array, 500)
#4 [internal function]: CodeIgniter\Debug\Exceptions->exceptionHandler(Object(ErrorException))
#5 {main}
  thrown
#0 [internal function]: CodeIgniter\Debug\Exceptions->shutdownHandler()
#1 {main}
ERROR - 2025-06-28 13:46:06 --> ErrorException: pg_query(): Query failed: ERROR:  no existe la relación «pedido»
LINE 11:             pedido
                     ^ in C:\xampp\htdocs\dfpyme\system\Database\Postgre\Connection.php:135
Stack trace:
#0 [internal function]: CodeIgniter\Debug\Exceptions->errorHandler(2, 'pg_query(): Que...', 'C:\\xampp\\htdocs...', 135)
#1 C:\xampp\htdocs\dfpyme\system\Database\Postgre\Connection.php(135): pg_query(Resource id #155, '\r\n        SELEC...')
#2 C:\xampp\htdocs\dfpyme\system\Database\BaseConnection.php(670): CodeIgniter\Database\Postgre\Connection->execute('\r\n        SELEC...')
#3 C:\xampp\htdocs\dfpyme\system\Database\BaseConnection.php(598): CodeIgniter\Database\BaseConnection->simpleQuery('\r\n        SELEC...')
#4 C:\xampp\htdocs\dfpyme\app\Models\pedidoModel.php(94): CodeIgniter\Database\BaseConnection->query('\r\n        SELEC...')
#5 C:\xampp\htdocs\dfpyme\app\Controllers\reportes\ReportesController.php(779): App\Models\pedidoModel->update_mesa()
#6 C:\xampp\htdocs\dfpyme\system\CodeIgniter.php(832): App\Controllers\reportes\ReportesController->actualizacion_estado_mesas()
#7 C:\xampp\htdocs\dfpyme\system\CodeIgniter.php(419): CodeIgniter\CodeIgniter->runController(Object(App\Controllers\reportes\ReportesController))
#8 C:\xampp\htdocs\dfpyme\system\CodeIgniter.php(326): CodeIgniter\CodeIgniter->handleRequest(NULL, Object(Config\Cache), false)
#9 C:\xampp\htdocs\dfpyme\index.php(37): CodeIgniter\CodeIgniter->run()
#10 {main}
CRITICAL - 2025-06-28 13:46:06 --> pg_query(): Query failed: ERROR:  no existe la relación «pedido»
LINE 11:             pedido
                     ^
#0 [internal function]: CodeIgniter\Debug\Exceptions->errorHandler(2, 'pg_query(): Que...', 'C:\\xampp\\htdocs...', 135)
#1 C:\xampp\htdocs\dfpyme\system\Database\Postgre\Connection.php(135): pg_query(Resource id #155, '\r\n        SELEC...')
#2 C:\xampp\htdocs\dfpyme\system\Database\BaseConnection.php(670): CodeIgniter\Database\Postgre\Connection->execute('\r\n        SELEC...')
#3 C:\xampp\htdocs\dfpyme\system\Database\BaseConnection.php(598): CodeIgniter\Database\BaseConnection->simpleQuery('\r\n        SELEC...')
#4 C:\xampp\htdocs\dfpyme\app\Models\pedidoModel.php(94): CodeIgniter\Database\BaseConnection->query('\r\n        SELEC...')
#5 C:\xampp\htdocs\dfpyme\app\Controllers\reportes\ReportesController.php(779): App\Models\pedidoModel->update_mesa()
#6 C:\xampp\htdocs\dfpyme\system\CodeIgniter.php(832): App\Controllers\reportes\ReportesController->actualizacion_estado_mesas()
#7 C:\xampp\htdocs\dfpyme\system\CodeIgniter.php(419): CodeIgniter\CodeIgniter->runController(Object(App\Controllers\reportes\ReportesController))
#8 C:\xampp\htdocs\dfpyme\system\CodeIgniter.php(326): CodeIgniter\CodeIgniter->handleRequest(NULL, Object(Config\Cache), false)
#9 C:\xampp\htdocs\dfpyme\index.php(37): CodeIgniter\CodeIgniter->run()
#10 {main}
CRITICAL - 2025-06-28 13:46:06 --> Uncaught CodeIgniter\Format\Exceptions\FormatException: Failed to parse json string, error: "Type is not supported". in C:\xampp\htdocs\dfpyme\system\Format\JSONFormatter.php:41
Stack trace:
#0 C:\xampp\htdocs\dfpyme\system\Format\JSONFormatter.php(41): CodeIgniter\Format\Exceptions\FormatException::forInvalidJSON('Type is not sup...')
#1 C:\xampp\htdocs\dfpyme\system\API\ResponseTrait.php(341): CodeIgniter\Format\JSONFormatter->format(Array)
#2 C:\xampp\htdocs\dfpyme\system\API\ResponseTrait.php(99): CodeIgniter\Debug\Exceptions->format(Array)
#3 C:\xampp\htdocs\dfpyme\system\Debug\Exceptions.php(115): CodeIgniter\Debug\Exceptions->respond(Array, 500)
#4 [internal function]: CodeIgniter\Debug\Exceptions->exceptionHandler(Object(ErrorException))
#5 {main}
  thrown
#0 [internal function]: CodeIgniter\Debug\Exceptions->shutdownHandler()
#1 {main}
ERROR - 2025-06-28 13:46:07 --> ErrorException: pg_query(): Query failed: ERROR:  no existe la relación «pedido»
LINE 11:             pedido
                     ^ in C:\xampp\htdocs\dfpyme\system\Database\Postgre\Connection.php:135
Stack trace:
#0 [internal function]: CodeIgniter\Debug\Exceptions->errorHandler(2, 'pg_query(): Que...', 'C:\\xampp\\htdocs...', 135)
#1 C:\xampp\htdocs\dfpyme\system\Database\Postgre\Connection.php(135): pg_query(Resource id #155, '\r\n        SELEC...')
#2 C:\xampp\htdocs\dfpyme\system\Database\BaseConnection.php(670): CodeIgniter\Database\Postgre\Connection->execute('\r\n        SELEC...')
#3 C:\xampp\htdocs\dfpyme\system\Database\BaseConnection.php(598): CodeIgniter\Database\BaseConnection->simpleQuery('\r\n        SELEC...')
#4 C:\xampp\htdocs\dfpyme\app\Models\pedidoModel.php(94): CodeIgniter\Database\BaseConnection->query('\r\n        SELEC...')
#5 C:\xampp\htdocs\dfpyme\app\Controllers\reportes\ReportesController.php(779): App\Models\pedidoModel->update_mesa()
#6 C:\xampp\htdocs\dfpyme\system\CodeIgniter.php(832): App\Controllers\reportes\ReportesController->actualizacion_estado_mesas()
#7 C:\xampp\htdocs\dfpyme\system\CodeIgniter.php(419): CodeIgniter\CodeIgniter->runController(Object(App\Controllers\reportes\ReportesController))
#8 C:\xampp\htdocs\dfpyme\system\CodeIgniter.php(326): CodeIgniter\CodeIgniter->handleRequest(NULL, Object(Config\Cache), false)
#9 C:\xampp\htdocs\dfpyme\index.php(37): CodeIgniter\CodeIgniter->run()
#10 {main}
CRITICAL - 2025-06-28 13:46:07 --> pg_query(): Query failed: ERROR:  no existe la relación «pedido»
LINE 11:             pedido
                     ^
#0 [internal function]: CodeIgniter\Debug\Exceptions->errorHandler(2, 'pg_query(): Que...', 'C:\\xampp\\htdocs...', 135)
#1 C:\xampp\htdocs\dfpyme\system\Database\Postgre\Connection.php(135): pg_query(Resource id #155, '\r\n        SELEC...')
#2 C:\xampp\htdocs\dfpyme\system\Database\BaseConnection.php(670): CodeIgniter\Database\Postgre\Connection->execute('\r\n        SELEC...')
#3 C:\xampp\htdocs\dfpyme\system\Database\BaseConnection.php(598): CodeIgniter\Database\BaseConnection->simpleQuery('\r\n        SELEC...')
#4 C:\xampp\htdocs\dfpyme\app\Models\pedidoModel.php(94): CodeIgniter\Database\BaseConnection->query('\r\n        SELEC...')
#5 C:\xampp\htdocs\dfpyme\app\Controllers\reportes\ReportesController.php(779): App\Models\pedidoModel->update_mesa()
#6 C:\xampp\htdocs\dfpyme\system\CodeIgniter.php(832): App\Controllers\reportes\ReportesController->actualizacion_estado_mesas()
#7 C:\xampp\htdocs\dfpyme\system\CodeIgniter.php(419): CodeIgniter\CodeIgniter->runController(Object(App\Controllers\reportes\ReportesController))
#8 C:\xampp\htdocs\dfpyme\system\CodeIgniter.php(326): CodeIgniter\CodeIgniter->handleRequest(NULL, Object(Config\Cache), false)
#9 C:\xampp\htdocs\dfpyme\index.php(37): CodeIgniter\CodeIgniter->run()
#10 {main}
CRITICAL - 2025-06-28 13:46:07 --> Uncaught CodeIgniter\Format\Exceptions\FormatException: Failed to parse json string, error: "Type is not supported". in C:\xampp\htdocs\dfpyme\system\Format\JSONFormatter.php:41
Stack trace:
#0 C:\xampp\htdocs\dfpyme\system\Format\JSONFormatter.php(41): CodeIgniter\Format\Exceptions\FormatException::forInvalidJSON('Type is not sup...')
#1 C:\xampp\htdocs\dfpyme\system\API\ResponseTrait.php(341): CodeIgniter\Format\JSONFormatter->format(Array)
#2 C:\xampp\htdocs\dfpyme\system\API\ResponseTrait.php(99): CodeIgniter\Debug\Exceptions->format(Array)
#3 C:\xampp\htdocs\dfpyme\system\Debug\Exceptions.php(115): CodeIgniter\Debug\Exceptions->respond(Array, 500)
#4 [internal function]: CodeIgniter\Debug\Exceptions->exceptionHandler(Object(ErrorException))
#5 {main}
  thrown
#0 [internal function]: CodeIgniter\Debug\Exceptions->shutdownHandler()
#1 {main}
ERROR - 2025-06-28 13:46:08 --> ErrorException: pg_query(): Query failed: ERROR:  no existe la relación «apertura_registro»
LINE 2: FROM &quot;apertura_registro&quot;
             ^ in C:\xampp\htdocs\dfpyme\system\Database\Postgre\Connection.php:135
Stack trace:
#0 [internal function]: CodeIgniter\Debug\Exceptions->errorHandler(2, 'pg_query(): Que...', 'C:\\xampp\\htdocs...', 135)
#1 C:\xampp\htdocs\dfpyme\system\Database\Postgre\Connection.php(135): pg_query(Resource id #157, 'SELECT "numero"...')
#2 C:\xampp\htdocs\dfpyme\system\Database\BaseConnection.php(670): CodeIgniter\Database\Postgre\Connection->execute('SELECT "numero"...')
#3 C:\xampp\htdocs\dfpyme\system\Database\BaseConnection.php(598): CodeIgniter\Database\BaseConnection->simpleQuery('SELECT "numero"...')
#4 C:\xampp\htdocs\dfpyme\system\Database\BaseBuilder.php(1455): CodeIgniter\Database\BaseConnection->query('SELECT "numero"...', Array, false)
#5 C:\xampp\htdocs\dfpyme\system\Model.php(210): CodeIgniter\Database\BaseBuilder->get()
#6 C:\xampp\htdocs\dfpyme\system\BaseModel.php(622): CodeIgniter\Model->doFirst()
#7 C:\xampp\htdocs\dfpyme\app\Controllers\reportes\ReportesController.php(653): CodeIgniter\BaseModel->first()
#8 C:\xampp\htdocs\dfpyme\system\CodeIgniter.php(832): App\Controllers\reportes\ReportesController->total_ventas_electronicas()
#9 C:\xampp\htdocs\dfpyme\system\CodeIgniter.php(419): CodeIgniter\CodeIgniter->runController(Object(App\Controllers\reportes\ReportesController))
#10 C:\xampp\htdocs\dfpyme\system\CodeIgniter.php(326): CodeIgniter\CodeIgniter->handleRequest(NULL, Object(Config\Cache), false)
#11 C:\xampp\htdocs\dfpyme\index.php(37): CodeIgniter\CodeIgniter->run()
#12 {main}
CRITICAL - 2025-06-28 13:46:08 --> pg_query(): Query failed: ERROR:  no existe la relación «apertura_registro»
LINE 2: FROM &quot;apertura_registro&quot;
             ^
#0 [internal function]: CodeIgniter\Debug\Exceptions->errorHandler(2, 'pg_query(): Que...', 'C:\\xampp\\htdocs...', 135)
#1 C:\xampp\htdocs\dfpyme\system\Database\Postgre\Connection.php(135): pg_query(Resource id #157, 'SELECT "numero"...')
#2 C:\xampp\htdocs\dfpyme\system\Database\BaseConnection.php(670): CodeIgniter\Database\Postgre\Connection->execute('SELECT "numero"...')
#3 C:\xampp\htdocs\dfpyme\system\Database\BaseConnection.php(598): CodeIgniter\Database\BaseConnection->simpleQuery('SELECT "numero"...')
#4 C:\xampp\htdocs\dfpyme\system\Database\BaseBuilder.php(1455): CodeIgniter\Database\BaseConnection->query('SELECT "numero"...', Array, false)
#5 C:\xampp\htdocs\dfpyme\system\Model.php(210): CodeIgniter\Database\BaseBuilder->get()
#6 C:\xampp\htdocs\dfpyme\system\BaseModel.php(622): CodeIgniter\Model->doFirst()
#7 C:\xampp\htdocs\dfpyme\app\Controllers\reportes\ReportesController.php(653): CodeIgniter\BaseModel->first()
#8 C:\xampp\htdocs\dfpyme\system\CodeIgniter.php(832): App\Controllers\reportes\ReportesController->total_ventas_electronicas()
#9 C:\xampp\htdocs\dfpyme\system\CodeIgniter.php(419): CodeIgniter\CodeIgniter->runController(Object(App\Controllers\reportes\ReportesController))
#10 C:\xampp\htdocs\dfpyme\system\CodeIgniter.php(326): CodeIgniter\CodeIgniter->handleRequest(NULL, Object(Config\Cache), false)
#11 C:\xampp\htdocs\dfpyme\index.php(37): CodeIgniter\CodeIgniter->run()
#12 {main}
CRITICAL - 2025-06-28 13:46:08 --> Uncaught CodeIgniter\Format\Exceptions\FormatException: Failed to parse json string, error: "Type is not supported". in C:\xampp\htdocs\dfpyme\system\Format\JSONFormatter.php:41
Stack trace:
#0 C:\xampp\htdocs\dfpyme\system\Format\JSONFormatter.php(41): CodeIgniter\Format\Exceptions\FormatException::forInvalidJSON('Type is not sup...')
#1 C:\xampp\htdocs\dfpyme\system\API\ResponseTrait.php(341): CodeIgniter\Format\JSONFormatter->format(Array)
#2 C:\xampp\htdocs\dfpyme\system\API\ResponseTrait.php(99): CodeIgniter\Debug\Exceptions->format(Array)
#3 C:\xampp\htdocs\dfpyme\system\Debug\Exceptions.php(115): CodeIgniter\Debug\Exceptions->respond(Array, 500)
#4 [internal function]: CodeIgniter\Debug\Exceptions->exceptionHandler(Object(ErrorException))
#5 {main}
  thrown
#0 [internal function]: CodeIgniter\Debug\Exceptions->shutdownHandler()
#1 {main}
ERROR - 2025-06-28 13:46:08 --> ErrorException: pg_query(): Query failed: ERROR:  no existe la relación «pedido»
LINE 11:             pedido
                     ^ in C:\xampp\htdocs\dfpyme\system\Database\Postgre\Connection.php:135
Stack trace:
#0 [internal function]: CodeIgniter\Debug\Exceptions->errorHandler(2, 'pg_query(): Que...', 'C:\\xampp\\htdocs...', 135)
#1 C:\xampp\htdocs\dfpyme\system\Database\Postgre\Connection.php(135): pg_query(Resource id #155, '\r\n        SELEC...')
#2 C:\xampp\htdocs\dfpyme\system\Database\BaseConnection.php(670): CodeIgniter\Database\Postgre\Connection->execute('\r\n        SELEC...')
#3 C:\xampp\htdocs\dfpyme\system\Database\BaseConnection.php(598): CodeIgniter\Database\BaseConnection->simpleQuery('\r\n        SELEC...')
#4 C:\xampp\htdocs\dfpyme\app\Models\pedidoModel.php(94): CodeIgniter\Database\BaseConnection->query('\r\n        SELEC...')
#5 C:\xampp\htdocs\dfpyme\app\Controllers\reportes\ReportesController.php(779): App\Models\pedidoModel->update_mesa()
#6 C:\xampp\htdocs\dfpyme\system\CodeIgniter.php(832): App\Controllers\reportes\ReportesController->actualizacion_estado_mesas()
#7 C:\xampp\htdocs\dfpyme\system\CodeIgniter.php(419): CodeIgniter\CodeIgniter->runController(Object(App\Controllers\reportes\ReportesController))
#8 C:\xampp\htdocs\dfpyme\system\CodeIgniter.php(326): CodeIgniter\CodeIgniter->handleRequest(NULL, Object(Config\Cache), false)
#9 C:\xampp\htdocs\dfpyme\index.php(37): CodeIgniter\CodeIgniter->run()
#10 {main}
CRITICAL - 2025-06-28 13:46:08 --> pg_query(): Query failed: ERROR:  no existe la relación «pedido»
LINE 11:             pedido
                     ^
#0 [internal function]: CodeIgniter\Debug\Exceptions->errorHandler(2, 'pg_query(): Que...', 'C:\\xampp\\htdocs...', 135)
#1 C:\xampp\htdocs\dfpyme\system\Database\Postgre\Connection.php(135): pg_query(Resource id #155, '\r\n        SELEC...')
#2 C:\xampp\htdocs\dfpyme\system\Database\BaseConnection.php(670): CodeIgniter\Database\Postgre\Connection->execute('\r\n        SELEC...')
#3 C:\xampp\htdocs\dfpyme\system\Database\BaseConnection.php(598): CodeIgniter\Database\BaseConnection->simpleQuery('\r\n        SELEC...')
#4 C:\xampp\htdocs\dfpyme\app\Models\pedidoModel.php(94): CodeIgniter\Database\BaseConnection->query('\r\n        SELEC...')
#5 C:\xampp\htdocs\dfpyme\app\Controllers\reportes\ReportesController.php(779): App\Models\pedidoModel->update_mesa()
#6 C:\xampp\htdocs\dfpyme\system\CodeIgniter.php(832): App\Controllers\reportes\ReportesController->actualizacion_estado_mesas()
#7 C:\xampp\htdocs\dfpyme\system\CodeIgniter.php(419): CodeIgniter\CodeIgniter->runController(Object(App\Controllers\reportes\ReportesController))
#8 C:\xampp\htdocs\dfpyme\system\CodeIgniter.php(326): CodeIgniter\CodeIgniter->handleRequest(NULL, Object(Config\Cache), false)
#9 C:\xampp\htdocs\dfpyme\index.php(37): CodeIgniter\CodeIgniter->run()
#10 {main}
CRITICAL - 2025-06-28 13:46:08 --> Uncaught CodeIgniter\Format\Exceptions\FormatException: Failed to parse json string, error: "Type is not supported". in C:\xampp\htdocs\dfpyme\system\Format\JSONFormatter.php:41
Stack trace:
#0 C:\xampp\htdocs\dfpyme\system\Format\JSONFormatter.php(41): CodeIgniter\Format\Exceptions\FormatException::forInvalidJSON('Type is not sup...')
#1 C:\xampp\htdocs\dfpyme\system\API\ResponseTrait.php(341): CodeIgniter\Format\JSONFormatter->format(Array)
#2 C:\xampp\htdocs\dfpyme\system\API\ResponseTrait.php(99): CodeIgniter\Debug\Exceptions->format(Array)
#3 C:\xampp\htdocs\dfpyme\system\Debug\Exceptions.php(115): CodeIgniter\Debug\Exceptions->respond(Array, 500)
#4 [internal function]: CodeIgniter\Debug\Exceptions->exceptionHandler(Object(ErrorException))
#5 {main}
  thrown
#0 [internal function]: CodeIgniter\Debug\Exceptions->shutdownHandler()
#1 {main}
ERROR - 2025-06-28 13:46:09 --> ErrorException: pg_query(): Query failed: ERROR:  no existe la relación «pedido»
LINE 11:             pedido
                     ^ in C:\xampp\htdocs\dfpyme\system\Database\Postgre\Connection.php:135
Stack trace:
#0 [internal function]: CodeIgniter\Debug\Exceptions->errorHandler(2, 'pg_query(): Que...', 'C:\\xampp\\htdocs...', 135)
#1 C:\xampp\htdocs\dfpyme\system\Database\Postgre\Connection.php(135): pg_query(Resource id #155, '\r\n        SELEC...')
#2 C:\xampp\htdocs\dfpyme\system\Database\BaseConnection.php(670): CodeIgniter\Database\Postgre\Connection->execute('\r\n        SELEC...')
#3 C:\xampp\htdocs\dfpyme\system\Database\BaseConnection.php(598): CodeIgniter\Database\BaseConnection->simpleQuery('\r\n        SELEC...')
#4 C:\xampp\htdocs\dfpyme\app\Models\pedidoModel.php(94): CodeIgniter\Database\BaseConnection->query('\r\n        SELEC...')
#5 C:\xampp\htdocs\dfpyme\app\Controllers\reportes\ReportesController.php(779): App\Models\pedidoModel->update_mesa()
#6 C:\xampp\htdocs\dfpyme\system\CodeIgniter.php(832): App\Controllers\reportes\ReportesController->actualizacion_estado_mesas()
#7 C:\xampp\htdocs\dfpyme\system\CodeIgniter.php(419): CodeIgniter\CodeIgniter->runController(Object(App\Controllers\reportes\ReportesController))
#8 C:\xampp\htdocs\dfpyme\system\CodeIgniter.php(326): CodeIgniter\CodeIgniter->handleRequest(NULL, Object(Config\Cache), false)
#9 C:\xampp\htdocs\dfpyme\index.php(37): CodeIgniter\CodeIgniter->run()
#10 {main}
CRITICAL - 2025-06-28 13:46:09 --> pg_query(): Query failed: ERROR:  no existe la relación «pedido»
LINE 11:             pedido
                     ^
#0 [internal function]: CodeIgniter\Debug\Exceptions->errorHandler(2, 'pg_query(): Que...', 'C:\\xampp\\htdocs...', 135)
#1 C:\xampp\htdocs\dfpyme\system\Database\Postgre\Connection.php(135): pg_query(Resource id #155, '\r\n        SELEC...')
#2 C:\xampp\htdocs\dfpyme\system\Database\BaseConnection.php(670): CodeIgniter\Database\Postgre\Connection->execute('\r\n        SELEC...')
#3 C:\xampp\htdocs\dfpyme\system\Database\BaseConnection.php(598): CodeIgniter\Database\BaseConnection->simpleQuery('\r\n        SELEC...')
#4 C:\xampp\htdocs\dfpyme\app\Models\pedidoModel.php(94): CodeIgniter\Database\BaseConnection->query('\r\n        SELEC...')
#5 C:\xampp\htdocs\dfpyme\app\Controllers\reportes\ReportesController.php(779): App\Models\pedidoModel->update_mesa()
#6 C:\xampp\htdocs\dfpyme\system\CodeIgniter.php(832): App\Controllers\reportes\ReportesController->actualizacion_estado_mesas()
#7 C:\xampp\htdocs\dfpyme\system\CodeIgniter.php(419): CodeIgniter\CodeIgniter->runController(Object(App\Controllers\reportes\ReportesController))
#8 C:\xampp\htdocs\dfpyme\system\CodeIgniter.php(326): CodeIgniter\CodeIgniter->handleRequest(NULL, Object(Config\Cache), false)
#9 C:\xampp\htdocs\dfpyme\index.php(37): CodeIgniter\CodeIgniter->run()
#10 {main}
CRITICAL - 2025-06-28 13:46:09 --> Uncaught CodeIgniter\Format\Exceptions\FormatException: Failed to parse json string, error: "Type is not supported". in C:\xampp\htdocs\dfpyme\system\Format\JSONFormatter.php:41
Stack trace:
#0 C:\xampp\htdocs\dfpyme\system\Format\JSONFormatter.php(41): CodeIgniter\Format\Exceptions\FormatException::forInvalidJSON('Type is not sup...')
#1 C:\xampp\htdocs\dfpyme\system\API\ResponseTrait.php(341): CodeIgniter\Format\JSONFormatter->format(Array)
#2 C:\xampp\htdocs\dfpyme\system\API\ResponseTrait.php(99): CodeIgniter\Debug\Exceptions->format(Array)
#3 C:\xampp\htdocs\dfpyme\system\Debug\Exceptions.php(115): CodeIgniter\Debug\Exceptions->respond(Array, 500)
#4 [internal function]: CodeIgniter\Debug\Exceptions->exceptionHandler(Object(ErrorException))
#5 {main}
  thrown
#0 [internal function]: CodeIgniter\Debug\Exceptions->shutdownHandler()
#1 {main}
ERROR - 2025-06-28 13:46:10 --> ErrorException: pg_query(): Query failed: ERROR:  no existe la relación «pedido»
LINE 11:             pedido
                     ^ in C:\xampp\htdocs\dfpyme\system\Database\Postgre\Connection.php:135
Stack trace:
#0 [internal function]: CodeIgniter\Debug\Exceptions->errorHandler(2, 'pg_query(): Que...', 'C:\\xampp\\htdocs...', 135)
#1 C:\xampp\htdocs\dfpyme\system\Database\Postgre\Connection.php(135): pg_query(Resource id #155, '\r\n        SELEC...')
#2 C:\xampp\htdocs\dfpyme\system\Database\BaseConnection.php(670): CodeIgniter\Database\Postgre\Connection->execute('\r\n        SELEC...')
#3 C:\xampp\htdocs\dfpyme\system\Database\BaseConnection.php(598): CodeIgniter\Database\BaseConnection->simpleQuery('\r\n        SELEC...')
#4 C:\xampp\htdocs\dfpyme\app\Models\pedidoModel.php(94): CodeIgniter\Database\BaseConnection->query('\r\n        SELEC...')
#5 C:\xampp\htdocs\dfpyme\app\Controllers\reportes\ReportesController.php(779): App\Models\pedidoModel->update_mesa()
#6 C:\xampp\htdocs\dfpyme\system\CodeIgniter.php(832): App\Controllers\reportes\ReportesController->actualizacion_estado_mesas()
#7 C:\xampp\htdocs\dfpyme\system\CodeIgniter.php(419): CodeIgniter\CodeIgniter->runController(Object(App\Controllers\reportes\ReportesController))
#8 C:\xampp\htdocs\dfpyme\system\CodeIgniter.php(326): CodeIgniter\CodeIgniter->handleRequest(NULL, Object(Config\Cache), false)
#9 C:\xampp\htdocs\dfpyme\index.php(37): CodeIgniter\CodeIgniter->run()
#10 {main}
CRITICAL - 2025-06-28 13:46:10 --> pg_query(): Query failed: ERROR:  no existe la relación «pedido»
LINE 11:             pedido
                     ^
#0 [internal function]: CodeIgniter\Debug\Exceptions->errorHandler(2, 'pg_query(): Que...', 'C:\\xampp\\htdocs...', 135)
#1 C:\xampp\htdocs\dfpyme\system\Database\Postgre\Connection.php(135): pg_query(Resource id #155, '\r\n        SELEC...')
#2 C:\xampp\htdocs\dfpyme\system\Database\BaseConnection.php(670): CodeIgniter\Database\Postgre\Connection->execute('\r\n        SELEC...')
#3 C:\xampp\htdocs\dfpyme\system\Database\BaseConnection.php(598): CodeIgniter\Database\BaseConnection->simpleQuery('\r\n        SELEC...')
#4 C:\xampp\htdocs\dfpyme\app\Models\pedidoModel.php(94): CodeIgniter\Database\BaseConnection->query('\r\n        SELEC...')
#5 C:\xampp\htdocs\dfpyme\app\Controllers\reportes\ReportesController.php(779): App\Models\pedidoModel->update_mesa()
#6 C:\xampp\htdocs\dfpyme\system\CodeIgniter.php(832): App\Controllers\reportes\ReportesController->actualizacion_estado_mesas()
#7 C:\xampp\htdocs\dfpyme\system\CodeIgniter.php(419): CodeIgniter\CodeIgniter->runController(Object(App\Controllers\reportes\ReportesController))
#8 C:\xampp\htdocs\dfpyme\system\CodeIgniter.php(326): CodeIgniter\CodeIgniter->handleRequest(NULL, Object(Config\Cache), false)
#9 C:\xampp\htdocs\dfpyme\index.php(37): CodeIgniter\CodeIgniter->run()
#10 {main}
CRITICAL - 2025-06-28 13:46:10 --> Uncaught CodeIgniter\Format\Exceptions\FormatException: Failed to parse json string, error: "Type is not supported". in C:\xampp\htdocs\dfpyme\system\Format\JSONFormatter.php:41
Stack trace:
#0 C:\xampp\htdocs\dfpyme\system\Format\JSONFormatter.php(41): CodeIgniter\Format\Exceptions\FormatException::forInvalidJSON('Type is not sup...')
#1 C:\xampp\htdocs\dfpyme\system\API\ResponseTrait.php(341): CodeIgniter\Format\JSONFormatter->format(Array)
#2 C:\xampp\htdocs\dfpyme\system\API\ResponseTrait.php(99): CodeIgniter\Debug\Exceptions->format(Array)
#3 C:\xampp\htdocs\dfpyme\system\Debug\Exceptions.php(115): CodeIgniter\Debug\Exceptions->respond(Array, 500)
#4 [internal function]: CodeIgniter\Debug\Exceptions->exceptionHandler(Object(ErrorException))
#5 {main}
  thrown
#0 [internal function]: CodeIgniter\Debug\Exceptions->shutdownHandler()
#1 {main}
ERROR - 2025-06-28 13:46:11 --> ErrorException: pg_query(): Query failed: ERROR:  no existe la relación «pedido»
LINE 11:             pedido
                     ^ in C:\xampp\htdocs\dfpyme\system\Database\Postgre\Connection.php:135
Stack trace:
#0 [internal function]: CodeIgniter\Debug\Exceptions->errorHandler(2, 'pg_query(): Que...', 'C:\\xampp\\htdocs...', 135)
#1 C:\xampp\htdocs\dfpyme\system\Database\Postgre\Connection.php(135): pg_query(Resource id #155, '\r\n        SELEC...')
#2 C:\xampp\htdocs\dfpyme\system\Database\BaseConnection.php(670): CodeIgniter\Database\Postgre\Connection->execute('\r\n        SELEC...')
#3 C:\xampp\htdocs\dfpyme\system\Database\BaseConnection.php(598): CodeIgniter\Database\BaseConnection->simpleQuery('\r\n        SELEC...')
#4 C:\xampp\htdocs\dfpyme\app\Models\pedidoModel.php(94): CodeIgniter\Database\BaseConnection->query('\r\n        SELEC...')
#5 C:\xampp\htdocs\dfpyme\app\Controllers\reportes\ReportesController.php(779): App\Models\pedidoModel->update_mesa()
#6 C:\xampp\htdocs\dfpyme\system\CodeIgniter.php(832): App\Controllers\reportes\ReportesController->actualizacion_estado_mesas()
#7 C:\xampp\htdocs\dfpyme\system\CodeIgniter.php(419): CodeIgniter\CodeIgniter->runController(Object(App\Controllers\reportes\ReportesController))
#8 C:\xampp\htdocs\dfpyme\system\CodeIgniter.php(326): CodeIgniter\CodeIgniter->handleRequest(NULL, Object(Config\Cache), false)
#9 C:\xampp\htdocs\dfpyme\index.php(37): CodeIgniter\CodeIgniter->run()
#10 {main}
CRITICAL - 2025-06-28 13:46:11 --> pg_query(): Query failed: ERROR:  no existe la relación «pedido»
LINE 11:             pedido
                     ^
#0 [internal function]: CodeIgniter\Debug\Exceptions->errorHandler(2, 'pg_query(): Que...', 'C:\\xampp\\htdocs...', 135)
#1 C:\xampp\htdocs\dfpyme\system\Database\Postgre\Connection.php(135): pg_query(Resource id #155, '\r\n        SELEC...')
#2 C:\xampp\htdocs\dfpyme\system\Database\BaseConnection.php(670): CodeIgniter\Database\Postgre\Connection->execute('\r\n        SELEC...')
#3 C:\xampp\htdocs\dfpyme\system\Database\BaseConnection.php(598): CodeIgniter\Database\BaseConnection->simpleQuery('\r\n        SELEC...')
#4 C:\xampp\htdocs\dfpyme\app\Models\pedidoModel.php(94): CodeIgniter\Database\BaseConnection->query('\r\n        SELEC...')
#5 C:\xampp\htdocs\dfpyme\app\Controllers\reportes\ReportesController.php(779): App\Models\pedidoModel->update_mesa()
#6 C:\xampp\htdocs\dfpyme\system\CodeIgniter.php(832): App\Controllers\reportes\ReportesController->actualizacion_estado_mesas()
#7 C:\xampp\htdocs\dfpyme\system\CodeIgniter.php(419): CodeIgniter\CodeIgniter->runController(Object(App\Controllers\reportes\ReportesController))
#8 C:\xampp\htdocs\dfpyme\system\CodeIgniter.php(326): CodeIgniter\CodeIgniter->handleRequest(NULL, Object(Config\Cache), false)
#9 C:\xampp\htdocs\dfpyme\index.php(37): CodeIgniter\CodeIgniter->run()
#10 {main}
CRITICAL - 2025-06-28 13:46:11 --> Uncaught CodeIgniter\Format\Exceptions\FormatException: Failed to parse json string, error: "Type is not supported". in C:\xampp\htdocs\dfpyme\system\Format\JSONFormatter.php:41
Stack trace:
#0 C:\xampp\htdocs\dfpyme\system\Format\JSONFormatter.php(41): CodeIgniter\Format\Exceptions\FormatException::forInvalidJSON('Type is not sup...')
#1 C:\xampp\htdocs\dfpyme\system\API\ResponseTrait.php(341): CodeIgniter\Format\JSONFormatter->format(Array)
#2 C:\xampp\htdocs\dfpyme\system\API\ResponseTrait.php(99): CodeIgniter\Debug\Exceptions->format(Array)
#3 C:\xampp\htdocs\dfpyme\system\Debug\Exceptions.php(115): CodeIgniter\Debug\Exceptions->respond(Array, 500)
#4 [internal function]: CodeIgniter\Debug\Exceptions->exceptionHandler(Object(ErrorException))
#5 {main}
  thrown
#0 [internal function]: CodeIgniter\Debug\Exceptions->shutdownHandler()
#1 {main}
ERROR - 2025-06-28 13:46:12 --> ErrorException: pg_query(): Query failed: ERROR:  no existe la relación «pedido»
LINE 11:             pedido
                     ^ in C:\xampp\htdocs\dfpyme\system\Database\Postgre\Connection.php:135
Stack trace:
#0 [internal function]: CodeIgniter\Debug\Exceptions->errorHandler(2, 'pg_query(): Que...', 'C:\\xampp\\htdocs...', 135)
#1 C:\xampp\htdocs\dfpyme\system\Database\Postgre\Connection.php(135): pg_query(Resource id #155, '\r\n        SELEC...')
#2 C:\xampp\htdocs\dfpyme\system\Database\BaseConnection.php(670): CodeIgniter\Database\Postgre\Connection->execute('\r\n        SELEC...')
#3 C:\xampp\htdocs\dfpyme\system\Database\BaseConnection.php(598): CodeIgniter\Database\BaseConnection->simpleQuery('\r\n        SELEC...')
#4 C:\xampp\htdocs\dfpyme\app\Models\pedidoModel.php(94): CodeIgniter\Database\BaseConnection->query('\r\n        SELEC...')
#5 C:\xampp\htdocs\dfpyme\app\Controllers\reportes\ReportesController.php(779): App\Models\pedidoModel->update_mesa()
#6 C:\xampp\htdocs\dfpyme\system\CodeIgniter.php(832): App\Controllers\reportes\ReportesController->actualizacion_estado_mesas()
#7 C:\xampp\htdocs\dfpyme\system\CodeIgniter.php(419): CodeIgniter\CodeIgniter->runController(Object(App\Controllers\reportes\ReportesController))
#8 C:\xampp\htdocs\dfpyme\system\CodeIgniter.php(326): CodeIgniter\CodeIgniter->handleRequest(NULL, Object(Config\Cache), false)
#9 C:\xampp\htdocs\dfpyme\index.php(37): CodeIgniter\CodeIgniter->run()
#10 {main}
CRITICAL - 2025-06-28 13:46:12 --> pg_query(): Query failed: ERROR:  no existe la relación «pedido»
LINE 11:             pedido
                     ^
#0 [internal function]: CodeIgniter\Debug\Exceptions->errorHandler(2, 'pg_query(): Que...', 'C:\\xampp\\htdocs...', 135)
#1 C:\xampp\htdocs\dfpyme\system\Database\Postgre\Connection.php(135): pg_query(Resource id #155, '\r\n        SELEC...')
#2 C:\xampp\htdocs\dfpyme\system\Database\BaseConnection.php(670): CodeIgniter\Database\Postgre\Connection->execute('\r\n        SELEC...')
#3 C:\xampp\htdocs\dfpyme\system\Database\BaseConnection.php(598): CodeIgniter\Database\BaseConnection->simpleQuery('\r\n        SELEC...')
#4 C:\xampp\htdocs\dfpyme\app\Models\pedidoModel.php(94): CodeIgniter\Database\BaseConnection->query('\r\n        SELEC...')
#5 C:\xampp\htdocs\dfpyme\app\Controllers\reportes\ReportesController.php(779): App\Models\pedidoModel->update_mesa()
#6 C:\xampp\htdocs\dfpyme\system\CodeIgniter.php(832): App\Controllers\reportes\ReportesController->actualizacion_estado_mesas()
#7 C:\xampp\htdocs\dfpyme\system\CodeIgniter.php(419): CodeIgniter\CodeIgniter->runController(Object(App\Controllers\reportes\ReportesController))
#8 C:\xampp\htdocs\dfpyme\system\CodeIgniter.php(326): CodeIgniter\CodeIgniter->handleRequest(NULL, Object(Config\Cache), false)
#9 C:\xampp\htdocs\dfpyme\index.php(37): CodeIgniter\CodeIgniter->run()
#10 {main}
CRITICAL - 2025-06-28 13:46:12 --> Uncaught CodeIgniter\Format\Exceptions\FormatException: Failed to parse json string, error: "Type is not supported". in C:\xampp\htdocs\dfpyme\system\Format\JSONFormatter.php:41
Stack trace:
#0 C:\xampp\htdocs\dfpyme\system\Format\JSONFormatter.php(41): CodeIgniter\Format\Exceptions\FormatException::forInvalidJSON('Type is not sup...')
#1 C:\xampp\htdocs\dfpyme\system\API\ResponseTrait.php(341): CodeIgniter\Format\JSONFormatter->format(Array)
#2 C:\xampp\htdocs\dfpyme\system\API\ResponseTrait.php(99): CodeIgniter\Debug\Exceptions->format(Array)
#3 C:\xampp\htdocs\dfpyme\system\Debug\Exceptions.php(115): CodeIgniter\Debug\Exceptions->respond(Array, 500)
#4 [internal function]: CodeIgniter\Debug\Exceptions->exceptionHandler(Object(ErrorException))
#5 {main}
  thrown
#0 [internal function]: CodeIgniter\Debug\Exceptions->shutdownHandler()
#1 {main}
ERROR - 2025-06-28 13:46:13 --> ErrorException: pg_query(): Query failed: ERROR:  no existe la relación «pedido»
LINE 11:             pedido
                     ^ in C:\xampp\htdocs\dfpyme\system\Database\Postgre\Connection.php:135
Stack trace:
#0 [internal function]: CodeIgniter\Debug\Exceptions->errorHandler(2, 'pg_query(): Que...', 'C:\\xampp\\htdocs...', 135)
#1 C:\xampp\htdocs\dfpyme\system\Database\Postgre\Connection.php(135): pg_query(Resource id #155, '\r\n        SELEC...')
#2 C:\xampp\htdocs\dfpyme\system\Database\BaseConnection.php(670): CodeIgniter\Database\Postgre\Connection->execute('\r\n        SELEC...')
#3 C:\xampp\htdocs\dfpyme\system\Database\BaseConnection.php(598): CodeIgniter\Database\BaseConnection->simpleQuery('\r\n        SELEC...')
#4 C:\xampp\htdocs\dfpyme\app\Models\pedidoModel.php(94): CodeIgniter\Database\BaseConnection->query('\r\n        SELEC...')
#5 C:\xampp\htdocs\dfpyme\app\Controllers\reportes\ReportesController.php(779): App\Models\pedidoModel->update_mesa()
#6 C:\xampp\htdocs\dfpyme\system\CodeIgniter.php(832): App\Controllers\reportes\ReportesController->actualizacion_estado_mesas()
#7 C:\xampp\htdocs\dfpyme\system\CodeIgniter.php(419): CodeIgniter\CodeIgniter->runController(Object(App\Controllers\reportes\ReportesController))
#8 C:\xampp\htdocs\dfpyme\system\CodeIgniter.php(326): CodeIgniter\CodeIgniter->handleRequest(NULL, Object(Config\Cache), false)
#9 C:\xampp\htdocs\dfpyme\index.php(37): CodeIgniter\CodeIgniter->run()
#10 {main}
CRITICAL - 2025-06-28 13:46:13 --> pg_query(): Query failed: ERROR:  no existe la relación «pedido»
LINE 11:             pedido
                     ^
#0 [internal function]: CodeIgniter\Debug\Exceptions->errorHandler(2, 'pg_query(): Que...', 'C:\\xampp\\htdocs...', 135)
#1 C:\xampp\htdocs\dfpyme\system\Database\Postgre\Connection.php(135): pg_query(Resource id #155, '\r\n        SELEC...')
#2 C:\xampp\htdocs\dfpyme\system\Database\BaseConnection.php(670): CodeIgniter\Database\Postgre\Connection->execute('\r\n        SELEC...')
#3 C:\xampp\htdocs\dfpyme\system\Database\BaseConnection.php(598): CodeIgniter\Database\BaseConnection->simpleQuery('\r\n        SELEC...')
#4 C:\xampp\htdocs\dfpyme\app\Models\pedidoModel.php(94): CodeIgniter\Database\BaseConnection->query('\r\n        SELEC...')
#5 C:\xampp\htdocs\dfpyme\app\Controllers\reportes\ReportesController.php(779): App\Models\pedidoModel->update_mesa()
#6 C:\xampp\htdocs\dfpyme\system\CodeIgniter.php(832): App\Controllers\reportes\ReportesController->actualizacion_estado_mesas()
#7 C:\xampp\htdocs\dfpyme\system\CodeIgniter.php(419): CodeIgniter\CodeIgniter->runController(Object(App\Controllers\reportes\ReportesController))
#8 C:\xampp\htdocs\dfpyme\system\CodeIgniter.php(326): CodeIgniter\CodeIgniter->handleRequest(NULL, Object(Config\Cache), false)
#9 C:\xampp\htdocs\dfpyme\index.php(37): CodeIgniter\CodeIgniter->run()
#10 {main}
CRITICAL - 2025-06-28 13:46:13 --> Uncaught CodeIgniter\Format\Exceptions\FormatException: Failed to parse json string, error: "Type is not supported". in C:\xampp\htdocs\dfpyme\system\Format\JSONFormatter.php:41
Stack trace:
#0 C:\xampp\htdocs\dfpyme\system\Format\JSONFormatter.php(41): CodeIgniter\Format\Exceptions\FormatException::forInvalidJSON('Type is not sup...')
#1 C:\xampp\htdocs\dfpyme\system\API\ResponseTrait.php(341): CodeIgniter\Format\JSONFormatter->format(Array)
#2 C:\xampp\htdocs\dfpyme\system\API\ResponseTrait.php(99): CodeIgniter\Debug\Exceptions->format(Array)
#3 C:\xampp\htdocs\dfpyme\system\Debug\Exceptions.php(115): CodeIgniter\Debug\Exceptions->respond(Array, 500)
#4 [internal function]: CodeIgniter\Debug\Exceptions->exceptionHandler(Object(ErrorException))
#5 {main}
  thrown
#0 [internal function]: CodeIgniter\Debug\Exceptions->shutdownHandler()
#1 {main}
ERROR - 2025-06-28 13:46:13 --> ErrorException: pg_query(): Query failed: ERROR:  no existe la relación «apertura_registro»
LINE 2: FROM &quot;apertura_registro&quot;
             ^ in C:\xampp\htdocs\dfpyme\system\Database\Postgre\Connection.php:135
Stack trace:
#0 [internal function]: CodeIgniter\Debug\Exceptions->errorHandler(2, 'pg_query(): Que...', 'C:\\xampp\\htdocs...', 135)
#1 C:\xampp\htdocs\dfpyme\system\Database\Postgre\Connection.php(135): pg_query(Resource id #157, 'SELECT "numero"...')
#2 C:\xampp\htdocs\dfpyme\system\Database\BaseConnection.php(670): CodeIgniter\Database\Postgre\Connection->execute('SELECT "numero"...')
#3 C:\xampp\htdocs\dfpyme\system\Database\BaseConnection.php(598): CodeIgniter\Database\BaseConnection->simpleQuery('SELECT "numero"...')
#4 C:\xampp\htdocs\dfpyme\system\Database\BaseBuilder.php(1455): CodeIgniter\Database\BaseConnection->query('SELECT "numero"...', Array, false)
#5 C:\xampp\htdocs\dfpyme\system\Model.php(210): CodeIgniter\Database\BaseBuilder->get()
#6 C:\xampp\htdocs\dfpyme\system\BaseModel.php(622): CodeIgniter\Model->doFirst()
#7 C:\xampp\htdocs\dfpyme\app\Controllers\reportes\ReportesController.php(653): CodeIgniter\BaseModel->first()
#8 C:\xampp\htdocs\dfpyme\system\CodeIgniter.php(832): App\Controllers\reportes\ReportesController->total_ventas_electronicas()
#9 C:\xampp\htdocs\dfpyme\system\CodeIgniter.php(419): CodeIgniter\CodeIgniter->runController(Object(App\Controllers\reportes\ReportesController))
#10 C:\xampp\htdocs\dfpyme\system\CodeIgniter.php(326): CodeIgniter\CodeIgniter->handleRequest(NULL, Object(Config\Cache), false)
#11 C:\xampp\htdocs\dfpyme\index.php(37): CodeIgniter\CodeIgniter->run()
#12 {main}
CRITICAL - 2025-06-28 13:46:13 --> pg_query(): Query failed: ERROR:  no existe la relación «apertura_registro»
LINE 2: FROM &quot;apertura_registro&quot;
             ^
#0 [internal function]: CodeIgniter\Debug\Exceptions->errorHandler(2, 'pg_query(): Que...', 'C:\\xampp\\htdocs...', 135)
#1 C:\xampp\htdocs\dfpyme\system\Database\Postgre\Connection.php(135): pg_query(Resource id #157, 'SELECT "numero"...')
#2 C:\xampp\htdocs\dfpyme\system\Database\BaseConnection.php(670): CodeIgniter\Database\Postgre\Connection->execute('SELECT "numero"...')
#3 C:\xampp\htdocs\dfpyme\system\Database\BaseConnection.php(598): CodeIgniter\Database\BaseConnection->simpleQuery('SELECT "numero"...')
#4 C:\xampp\htdocs\dfpyme\system\Database\BaseBuilder.php(1455): CodeIgniter\Database\BaseConnection->query('SELECT "numero"...', Array, false)
#5 C:\xampp\htdocs\dfpyme\system\Model.php(210): CodeIgniter\Database\BaseBuilder->get()
#6 C:\xampp\htdocs\dfpyme\system\BaseModel.php(622): CodeIgniter\Model->doFirst()
#7 C:\xampp\htdocs\dfpyme\app\Controllers\reportes\ReportesController.php(653): CodeIgniter\BaseModel->first()
#8 C:\xampp\htdocs\dfpyme\system\CodeIgniter.php(832): App\Controllers\reportes\ReportesController->total_ventas_electronicas()
#9 C:\xampp\htdocs\dfpyme\system\CodeIgniter.php(419): CodeIgniter\CodeIgniter->runController(Object(App\Controllers\reportes\ReportesController))
#10 C:\xampp\htdocs\dfpyme\system\CodeIgniter.php(326): CodeIgniter\CodeIgniter->handleRequest(NULL, Object(Config\Cache), false)
#11 C:\xampp\htdocs\dfpyme\index.php(37): CodeIgniter\CodeIgniter->run()
#12 {main}
CRITICAL - 2025-06-28 13:46:13 --> Uncaught CodeIgniter\Format\Exceptions\FormatException: Failed to parse json string, error: "Type is not supported". in C:\xampp\htdocs\dfpyme\system\Format\JSONFormatter.php:41
Stack trace:
#0 C:\xampp\htdocs\dfpyme\system\Format\JSONFormatter.php(41): CodeIgniter\Format\Exceptions\FormatException::forInvalidJSON('Type is not sup...')
#1 C:\xampp\htdocs\dfpyme\system\API\ResponseTrait.php(341): CodeIgniter\Format\JSONFormatter->format(Array)
#2 C:\xampp\htdocs\dfpyme\system\API\ResponseTrait.php(99): CodeIgniter\Debug\Exceptions->format(Array)
#3 C:\xampp\htdocs\dfpyme\system\Debug\Exceptions.php(115): CodeIgniter\Debug\Exceptions->respond(Array, 500)
#4 [internal function]: CodeIgniter\Debug\Exceptions->exceptionHandler(Object(ErrorException))
#5 {main}
  thrown
#0 [internal function]: CodeIgniter\Debug\Exceptions->shutdownHandler()
#1 {main}
ERROR - 2025-06-28 13:46:14 --> ErrorException: pg_query(): Query failed: ERROR:  no existe la relación «pedido»
LINE 11:             pedido
                     ^ in C:\xampp\htdocs\dfpyme\system\Database\Postgre\Connection.php:135
Stack trace:
#0 [internal function]: CodeIgniter\Debug\Exceptions->errorHandler(2, 'pg_query(): Que...', 'C:\\xampp\\htdocs...', 135)
#1 C:\xampp\htdocs\dfpyme\system\Database\Postgre\Connection.php(135): pg_query(Resource id #155, '\r\n        SELEC...')
#2 C:\xampp\htdocs\dfpyme\system\Database\BaseConnection.php(670): CodeIgniter\Database\Postgre\Connection->execute('\r\n        SELEC...')
#3 C:\xampp\htdocs\dfpyme\system\Database\BaseConnection.php(598): CodeIgniter\Database\BaseConnection->simpleQuery('\r\n        SELEC...')
#4 C:\xampp\htdocs\dfpyme\app\Models\pedidoModel.php(94): CodeIgniter\Database\BaseConnection->query('\r\n        SELEC...')
#5 C:\xampp\htdocs\dfpyme\app\Controllers\reportes\ReportesController.php(779): App\Models\pedidoModel->update_mesa()
#6 C:\xampp\htdocs\dfpyme\system\CodeIgniter.php(832): App\Controllers\reportes\ReportesController->actualizacion_estado_mesas()
#7 C:\xampp\htdocs\dfpyme\system\CodeIgniter.php(419): CodeIgniter\CodeIgniter->runController(Object(App\Controllers\reportes\ReportesController))
#8 C:\xampp\htdocs\dfpyme\system\CodeIgniter.php(326): CodeIgniter\CodeIgniter->handleRequest(NULL, Object(Config\Cache), false)
#9 C:\xampp\htdocs\dfpyme\index.php(37): CodeIgniter\CodeIgniter->run()
#10 {main}
CRITICAL - 2025-06-28 13:46:14 --> pg_query(): Query failed: ERROR:  no existe la relación «pedido»
LINE 11:             pedido
                     ^
#0 [internal function]: CodeIgniter\Debug\Exceptions->errorHandler(2, 'pg_query(): Que...', 'C:\\xampp\\htdocs...', 135)
#1 C:\xampp\htdocs\dfpyme\system\Database\Postgre\Connection.php(135): pg_query(Resource id #155, '\r\n        SELEC...')
#2 C:\xampp\htdocs\dfpyme\system\Database\BaseConnection.php(670): CodeIgniter\Database\Postgre\Connection->execute('\r\n        SELEC...')
#3 C:\xampp\htdocs\dfpyme\system\Database\BaseConnection.php(598): CodeIgniter\Database\BaseConnection->simpleQuery('\r\n        SELEC...')
#4 C:\xampp\htdocs\dfpyme\app\Models\pedidoModel.php(94): CodeIgniter\Database\BaseConnection->query('\r\n        SELEC...')
#5 C:\xampp\htdocs\dfpyme\app\Controllers\reportes\ReportesController.php(779): App\Models\pedidoModel->update_mesa()
#6 C:\xampp\htdocs\dfpyme\system\CodeIgniter.php(832): App\Controllers\reportes\ReportesController->actualizacion_estado_mesas()
#7 C:\xampp\htdocs\dfpyme\system\CodeIgniter.php(419): CodeIgniter\CodeIgniter->runController(Object(App\Controllers\reportes\ReportesController))
#8 C:\xampp\htdocs\dfpyme\system\CodeIgniter.php(326): CodeIgniter\CodeIgniter->handleRequest(NULL, Object(Config\Cache), false)
#9 C:\xampp\htdocs\dfpyme\index.php(37): CodeIgniter\CodeIgniter->run()
#10 {main}
CRITICAL - 2025-06-28 13:46:14 --> Uncaught CodeIgniter\Format\Exceptions\FormatException: Failed to parse json string, error: "Type is not supported". in C:\xampp\htdocs\dfpyme\system\Format\JSONFormatter.php:41
Stack trace:
#0 C:\xampp\htdocs\dfpyme\system\Format\JSONFormatter.php(41): CodeIgniter\Format\Exceptions\FormatException::forInvalidJSON('Type is not sup...')
#1 C:\xampp\htdocs\dfpyme\system\API\ResponseTrait.php(341): CodeIgniter\Format\JSONFormatter->format(Array)
#2 C:\xampp\htdocs\dfpyme\system\API\ResponseTrait.php(99): CodeIgniter\Debug\Exceptions->format(Array)
#3 C:\xampp\htdocs\dfpyme\system\Debug\Exceptions.php(115): CodeIgniter\Debug\Exceptions->respond(Array, 500)
#4 [internal function]: CodeIgniter\Debug\Exceptions->exceptionHandler(Object(ErrorException))
#5 {main}
  thrown
#0 [internal function]: CodeIgniter\Debug\Exceptions->shutdownHandler()
#1 {main}
ERROR - 2025-06-28 13:46:15 --> ErrorException: pg_query(): Query failed: ERROR:  no existe la relación «pedido»
LINE 11:             pedido
                     ^ in C:\xampp\htdocs\dfpyme\system\Database\Postgre\Connection.php:135
Stack trace:
#0 [internal function]: CodeIgniter\Debug\Exceptions->errorHandler(2, 'pg_query(): Que...', 'C:\\xampp\\htdocs...', 135)
#1 C:\xampp\htdocs\dfpyme\system\Database\Postgre\Connection.php(135): pg_query(Resource id #155, '\r\n        SELEC...')
#2 C:\xampp\htdocs\dfpyme\system\Database\BaseConnection.php(670): CodeIgniter\Database\Postgre\Connection->execute('\r\n        SELEC...')
#3 C:\xampp\htdocs\dfpyme\system\Database\BaseConnection.php(598): CodeIgniter\Database\BaseConnection->simpleQuery('\r\n        SELEC...')
#4 C:\xampp\htdocs\dfpyme\app\Models\pedidoModel.php(94): CodeIgniter\Database\BaseConnection->query('\r\n        SELEC...')
#5 C:\xampp\htdocs\dfpyme\app\Controllers\reportes\ReportesController.php(779): App\Models\pedidoModel->update_mesa()
#6 C:\xampp\htdocs\dfpyme\system\CodeIgniter.php(832): App\Controllers\reportes\ReportesController->actualizacion_estado_mesas()
#7 C:\xampp\htdocs\dfpyme\system\CodeIgniter.php(419): CodeIgniter\CodeIgniter->runController(Object(App\Controllers\reportes\ReportesController))
#8 C:\xampp\htdocs\dfpyme\system\CodeIgniter.php(326): CodeIgniter\CodeIgniter->handleRequest(NULL, Object(Config\Cache), false)
#9 C:\xampp\htdocs\dfpyme\index.php(37): CodeIgniter\CodeIgniter->run()
#10 {main}
CRITICAL - 2025-06-28 13:46:15 --> pg_query(): Query failed: ERROR:  no existe la relación «pedido»
LINE 11:             pedido
                     ^
#0 [internal function]: CodeIgniter\Debug\Exceptions->errorHandler(2, 'pg_query(): Que...', 'C:\\xampp\\htdocs...', 135)
#1 C:\xampp\htdocs\dfpyme\system\Database\Postgre\Connection.php(135): pg_query(Resource id #155, '\r\n        SELEC...')
#2 C:\xampp\htdocs\dfpyme\system\Database\BaseConnection.php(670): CodeIgniter\Database\Postgre\Connection->execute('\r\n        SELEC...')
#3 C:\xampp\htdocs\dfpyme\system\Database\BaseConnection.php(598): CodeIgniter\Database\BaseConnection->simpleQuery('\r\n        SELEC...')
#4 C:\xampp\htdocs\dfpyme\app\Models\pedidoModel.php(94): CodeIgniter\Database\BaseConnection->query('\r\n        SELEC...')
#5 C:\xampp\htdocs\dfpyme\app\Controllers\reportes\ReportesController.php(779): App\Models\pedidoModel->update_mesa()
#6 C:\xampp\htdocs\dfpyme\system\CodeIgniter.php(832): App\Controllers\reportes\ReportesController->actualizacion_estado_mesas()
#7 C:\xampp\htdocs\dfpyme\system\CodeIgniter.php(419): CodeIgniter\CodeIgniter->runController(Object(App\Controllers\reportes\ReportesController))
#8 C:\xampp\htdocs\dfpyme\system\CodeIgniter.php(326): CodeIgniter\CodeIgniter->handleRequest(NULL, Object(Config\Cache), false)
#9 C:\xampp\htdocs\dfpyme\index.php(37): CodeIgniter\CodeIgniter->run()
#10 {main}
CRITICAL - 2025-06-28 13:46:15 --> Uncaught CodeIgniter\Format\Exceptions\FormatException: Failed to parse json string, error: "Type is not supported". in C:\xampp\htdocs\dfpyme\system\Format\JSONFormatter.php:41
Stack trace:
#0 C:\xampp\htdocs\dfpyme\system\Format\JSONFormatter.php(41): CodeIgniter\Format\Exceptions\FormatException::forInvalidJSON('Type is not sup...')
#1 C:\xampp\htdocs\dfpyme\system\API\ResponseTrait.php(341): CodeIgniter\Format\JSONFormatter->format(Array)
#2 C:\xampp\htdocs\dfpyme\system\API\ResponseTrait.php(99): CodeIgniter\Debug\Exceptions->format(Array)
#3 C:\xampp\htdocs\dfpyme\system\Debug\Exceptions.php(115): CodeIgniter\Debug\Exceptions->respond(Array, 500)
#4 [internal function]: CodeIgniter\Debug\Exceptions->exceptionHandler(Object(ErrorException))
#5 {main}
  thrown
#0 [internal function]: CodeIgniter\Debug\Exceptions->shutdownHandler()
#1 {main}
ERROR - 2025-06-28 14:00:10 --> ErrorException: pg_query(): Query failed: ERROR:  no existe la relación «estado_licencia»
LINE 2: FROM &quot;estado_licencia&quot;
             ^ in C:\xampp\htdocs\dfpyme\system\Database\Postgre\Connection.php:135
Stack trace:
#0 [internal function]: CodeIgniter\Debug\Exceptions->errorHandler(2, 'pg_query(): Que...', 'C:\\xampp\\htdocs...', 135)
#1 C:\xampp\htdocs\dfpyme\system\Database\Postgre\Connection.php(135): pg_query(Resource id #148, 'SELECT "estado_...')
#2 C:\xampp\htdocs\dfpyme\system\Database\BaseConnection.php(670): CodeIgniter\Database\Postgre\Connection->execute('SELECT "estado_...')
#3 C:\xampp\htdocs\dfpyme\system\Database\BaseConnection.php(598): CodeIgniter\Database\BaseConnection->simpleQuery('SELECT "estado_...')
#4 C:\xampp\htdocs\dfpyme\system\Database\BaseBuilder.php(1455): CodeIgniter\Database\BaseConnection->query('SELECT "estado_...', Array, false)
#5 C:\xampp\htdocs\dfpyme\system\Model.php(210): CodeIgniter\Database\BaseBuilder->get()
#6 C:\xampp\htdocs\dfpyme\system\BaseModel.php(622): CodeIgniter\Model->doFirst()
#7 C:\xampp\htdocs\dfpyme\app\Controllers\login\loginController.php(32): CodeIgniter\BaseModel->first()
#8 C:\xampp\htdocs\dfpyme\system\CodeIgniter.php(832): App\Controllers\login\loginController->login()
#9 C:\xampp\htdocs\dfpyme\system\CodeIgniter.php(419): CodeIgniter\CodeIgniter->runController(Object(App\Controllers\login\loginController))
#10 C:\xampp\htdocs\dfpyme\system\CodeIgniter.php(326): CodeIgniter\CodeIgniter->handleRequest(NULL, Object(Config\Cache), false)
#11 C:\xampp\htdocs\dfpyme\index.php(37): CodeIgniter\CodeIgniter->run()
#12 {main}
CRITICAL - 2025-06-28 14:00:10 --> pg_query(): Query failed: ERROR:  no existe la relación «estado_licencia»
LINE 2: FROM &quot;estado_licencia&quot;
             ^
#0 [internal function]: CodeIgniter\Debug\Exceptions->errorHandler(2, 'pg_query(): Que...', 'C:\\xampp\\htdocs...', 135)
#1 C:\xampp\htdocs\dfpyme\system\Database\Postgre\Connection.php(135): pg_query(Resource id #148, 'SELECT "estado_...')
#2 C:\xampp\htdocs\dfpyme\system\Database\BaseConnection.php(670): CodeIgniter\Database\Postgre\Connection->execute('SELECT "estado_...')
#3 C:\xampp\htdocs\dfpyme\system\Database\BaseConnection.php(598): CodeIgniter\Database\BaseConnection->simpleQuery('SELECT "estado_...')
#4 C:\xampp\htdocs\dfpyme\system\Database\BaseBuilder.php(1455): CodeIgniter\Database\BaseConnection->query('SELECT "estado_...', Array, false)
#5 C:\xampp\htdocs\dfpyme\system\Model.php(210): CodeIgniter\Database\BaseBuilder->get()
#6 C:\xampp\htdocs\dfpyme\system\BaseModel.php(622): CodeIgniter\Model->doFirst()
#7 C:\xampp\htdocs\dfpyme\app\Controllers\login\loginController.php(32): CodeIgniter\BaseModel->first()
#8 C:\xampp\htdocs\dfpyme\system\CodeIgniter.php(832): App\Controllers\login\loginController->login()
#9 C:\xampp\htdocs\dfpyme\system\CodeIgniter.php(419): CodeIgniter\CodeIgniter->runController(Object(App\Controllers\login\loginController))
#10 C:\xampp\htdocs\dfpyme\system\CodeIgniter.php(326): CodeIgniter\CodeIgniter->handleRequest(NULL, Object(Config\Cache), false)
#11 C:\xampp\htdocs\dfpyme\index.php(37): CodeIgniter\CodeIgniter->run()
#12 {main}
ERROR - 2025-06-28 14:00:29 --> ErrorException: pg_query(): Query failed: ERROR:  no existe la relación «estado_licencia»
LINE 2: FROM &quot;estado_licencia&quot;
             ^ in C:\xampp\htdocs\dfpyme\system\Database\Postgre\Connection.php:135
Stack trace:
#0 [internal function]: CodeIgniter\Debug\Exceptions->errorHandler(2, 'pg_query(): Que...', 'C:\\xampp\\htdocs...', 135)
#1 C:\xampp\htdocs\dfpyme\system\Database\Postgre\Connection.php(135): pg_query(Resource id #148, 'SELECT "estado_...')
#2 C:\xampp\htdocs\dfpyme\system\Database\BaseConnection.php(670): CodeIgniter\Database\Postgre\Connection->execute('SELECT "estado_...')
#3 C:\xampp\htdocs\dfpyme\system\Database\BaseConnection.php(598): CodeIgniter\Database\BaseConnection->simpleQuery('SELECT "estado_...')
#4 C:\xampp\htdocs\dfpyme\system\Database\BaseBuilder.php(1455): CodeIgniter\Database\BaseConnection->query('SELECT "estado_...', Array, false)
#5 C:\xampp\htdocs\dfpyme\system\Model.php(210): CodeIgniter\Database\BaseBuilder->get()
#6 C:\xampp\htdocs\dfpyme\system\BaseModel.php(622): CodeIgniter\Model->doFirst()
#7 C:\xampp\htdocs\dfpyme\app\Controllers\login\loginController.php(32): CodeIgniter\BaseModel->first()
#8 C:\xampp\htdocs\dfpyme\system\CodeIgniter.php(832): App\Controllers\login\loginController->login()
#9 C:\xampp\htdocs\dfpyme\system\CodeIgniter.php(419): CodeIgniter\CodeIgniter->runController(Object(App\Controllers\login\loginController))
#10 C:\xampp\htdocs\dfpyme\system\CodeIgniter.php(326): CodeIgniter\CodeIgniter->handleRequest(NULL, Object(Config\Cache), false)
#11 C:\xampp\htdocs\dfpyme\index.php(37): CodeIgniter\CodeIgniter->run()
#12 {main}
CRITICAL - 2025-06-28 14:00:29 --> pg_query(): Query failed: ERROR:  no existe la relación «estado_licencia»
LINE 2: FROM &quot;estado_licencia&quot;
             ^
#0 [internal function]: CodeIgniter\Debug\Exceptions->errorHandler(2, 'pg_query(): Que...', 'C:\\xampp\\htdocs...', 135)
#1 C:\xampp\htdocs\dfpyme\system\Database\Postgre\Connection.php(135): pg_query(Resource id #148, 'SELECT "estado_...')
#2 C:\xampp\htdocs\dfpyme\system\Database\BaseConnection.php(670): CodeIgniter\Database\Postgre\Connection->execute('SELECT "estado_...')
#3 C:\xampp\htdocs\dfpyme\system\Database\BaseConnection.php(598): CodeIgniter\Database\BaseConnection->simpleQuery('SELECT "estado_...')
#4 C:\xampp\htdocs\dfpyme\system\Database\BaseBuilder.php(1455): CodeIgniter\Database\BaseConnection->query('SELECT "estado_...', Array, false)
#5 C:\xampp\htdocs\dfpyme\system\Model.php(210): CodeIgniter\Database\BaseBuilder->get()
#6 C:\xampp\htdocs\dfpyme\system\BaseModel.php(622): CodeIgniter\Model->doFirst()
#7 C:\xampp\htdocs\dfpyme\app\Controllers\login\loginController.php(32): CodeIgniter\BaseModel->first()
#8 C:\xampp\htdocs\dfpyme\system\CodeIgniter.php(832): App\Controllers\login\loginController->login()
#9 C:\xampp\htdocs\dfpyme\system\CodeIgniter.php(419): CodeIgniter\CodeIgniter->runController(Object(App\Controllers\login\loginController))
#10 C:\xampp\htdocs\dfpyme\system\CodeIgniter.php(326): CodeIgniter\CodeIgniter->handleRequest(NULL, Object(Config\Cache), false)
#11 C:\xampp\htdocs\dfpyme\index.php(37): CodeIgniter\CodeIgniter->run()
#12 {main}
CRITICAL - 2025-06-28 14:01:12 --> Trying to access array offset on value of type null
#0 C:\xampp\htdocs\dfpyme\app\Controllers\factura_electronica\FacturaElectronica.php(31): CodeIgniter\Debug\Exceptions->errorHandler(2, 'Trying to acces...', 'C:\\xampp\\htdocs...', 31)
#1 C:\xampp\htdocs\dfpyme\system\CodeIgniter.php(832): App\Controllers\factura_electronica\FacturaElectronica->pre_factura()
#2 C:\xampp\htdocs\dfpyme\system\CodeIgniter.php(419): CodeIgniter\CodeIgniter->runController(Object(App\Controllers\factura_electronica\FacturaElectronica))
#3 C:\xampp\htdocs\dfpyme\system\CodeIgniter.php(326): CodeIgniter\CodeIgniter->handleRequest(NULL, Object(Config\Cache), false)
#4 C:\xampp\htdocs\dfpyme\index.php(37): CodeIgniter\CodeIgniter->run()
#5 {main}
ERROR - 2025-06-28 14:51:16 --> ErrorException: pg_query(): Query failed: ERROR:  llave duplicada viola restricción de unicidad «pk_entrada_salidas»
DETAIL:  Ya existe la llave (id)=(12). in C:\xampp\htdocs\dfpyme\system\Database\Postgre\Connection.php:135
Stack trace:
#0 [internal function]: CodeIgniter\Debug\Exceptions->errorHandler(2, 'pg_query(): Que...', 'C:\\xampp\\htdocs...', 135)
#1 C:\xampp\htdocs\dfpyme\system\Database\Postgre\Connection.php(135): pg_query(Resource id #158, 'INSERT INTO "en...')
#2 C:\xampp\htdocs\dfpyme\system\Database\BaseConnection.php(670): CodeIgniter\Database\Postgre\Connection->execute('INSERT INTO "en...')
#3 C:\xampp\htdocs\dfpyme\system\Database\BaseConnection.php(598): CodeIgniter\Database\BaseConnection->simpleQuery('INSERT INTO "en...')
#4 C:\xampp\htdocs\dfpyme\system\Database\BaseBuilder.php(1771): CodeIgniter\Database\BaseConnection->query('INSERT INTO "en...', Array, false)
#5 C:\xampp\htdocs\dfpyme\system\Model.php(239): CodeIgniter\Database\BaseBuilder->insert()
#6 C:\xampp\htdocs\dfpyme\system\BaseModel.php(738): CodeIgniter\Model->doInsert(Array)
#7 C:\xampp\htdocs\dfpyme\system\Model.php(625): CodeIgniter\BaseModel->insert(Array, true)
#8 C:\xampp\htdocs\dfpyme\app\Controllers\factura_electronica\FacturaElectronica.php(177): CodeIgniter\Model->insert(Array)
#9 C:\xampp\htdocs\dfpyme\system\CodeIgniter.php(832): App\Controllers\factura_electronica\FacturaElectronica->pre_factura()
#10 C:\xampp\htdocs\dfpyme\system\CodeIgniter.php(419): CodeIgniter\CodeIgniter->runController(Object(App\Controllers\factura_electronica\FacturaElectronica))
#11 C:\xampp\htdocs\dfpyme\system\CodeIgniter.php(326): CodeIgniter\CodeIgniter->handleRequest(NULL, Object(Config\Cache), false)
#12 C:\xampp\htdocs\dfpyme\index.php(37): CodeIgniter\CodeIgniter->run()
#13 {main}
CRITICAL - 2025-06-28 14:51:16 --> pg_query(): Query failed: ERROR:  llave duplicada viola restricción de unicidad «pk_entrada_salidas»
DETAIL:  Ya existe la llave (id)=(12).
#0 [internal function]: CodeIgniter\Debug\Exceptions->errorHandler(2, 'pg_query(): Que...', 'C:\\xampp\\htdocs...', 135)
#1 C:\xampp\htdocs\dfpyme\system\Database\Postgre\Connection.php(135): pg_query(Resource id #158, 'INSERT INTO "en...')
#2 C:\xampp\htdocs\dfpyme\system\Database\BaseConnection.php(670): CodeIgniter\Database\Postgre\Connection->execute('INSERT INTO "en...')
#3 C:\xampp\htdocs\dfpyme\system\Database\BaseConnection.php(598): CodeIgniter\Database\BaseConnection->simpleQuery('INSERT INTO "en...')
#4 C:\xampp\htdocs\dfpyme\system\Database\BaseBuilder.php(1771): CodeIgniter\Database\BaseConnection->query('INSERT INTO "en...', Array, false)
#5 C:\xampp\htdocs\dfpyme\system\Model.php(239): CodeIgniter\Database\BaseBuilder->insert()
#6 C:\xampp\htdocs\dfpyme\system\BaseModel.php(738): CodeIgniter\Model->doInsert(Array)
#7 C:\xampp\htdocs\dfpyme\system\Model.php(625): CodeIgniter\BaseModel->insert(Array, true)
#8 C:\xampp\htdocs\dfpyme\app\Controllers\factura_electronica\FacturaElectronica.php(177): CodeIgniter\Model->insert(Array)
#9 C:\xampp\htdocs\dfpyme\system\CodeIgniter.php(832): App\Controllers\factura_electronica\FacturaElectronica->pre_factura()
#10 C:\xampp\htdocs\dfpyme\system\CodeIgniter.php(419): CodeIgniter\CodeIgniter->runController(Object(App\Controllers\factura_electronica\FacturaElectronica))
#11 C:\xampp\htdocs\dfpyme\system\CodeIgniter.php(326): CodeIgniter\CodeIgniter->handleRequest(NULL, Object(Config\Cache), false)
#12 C:\xampp\htdocs\dfpyme\index.php(37): CodeIgniter\CodeIgniter->run()
#13 {main}
CRITICAL - 2025-06-28 14:51:16 --> Uncaught CodeIgniter\Format\Exceptions\FormatException: Failed to parse json string, error: "Type is not supported". in C:\xampp\htdocs\dfpyme\system\Format\JSONFormatter.php:41
Stack trace:
#0 C:\xampp\htdocs\dfpyme\system\Format\JSONFormatter.php(41): CodeIgniter\Format\Exceptions\FormatException::forInvalidJSON('Type is not sup...')
#1 C:\xampp\htdocs\dfpyme\system\API\ResponseTrait.php(341): CodeIgniter\Format\JSONFormatter->format(Array)
#2 C:\xampp\htdocs\dfpyme\system\API\ResponseTrait.php(99): CodeIgniter\Debug\Exceptions->format(Array)
#3 C:\xampp\htdocs\dfpyme\system\Debug\Exceptions.php(115): CodeIgniter\Debug\Exceptions->respond(Array, 500)
#4 [internal function]: CodeIgniter\Debug\Exceptions->exceptionHandler(Object(ErrorException))
#5 {main}
  thrown
#0 [internal function]: CodeIgniter\Debug\Exceptions->shutdownHandler()
#1 {main}
ERROR - 2025-06-28 14:51:34 --> ErrorException: pg_query(): Query failed: ERROR:  llave duplicada viola restricción de unicidad «pk_entrada_salidas»
DETAIL:  Ya existe la llave (id)=(13). in C:\xampp\htdocs\dfpyme\system\Database\Postgre\Connection.php:135
Stack trace:
#0 [internal function]: CodeIgniter\Debug\Exceptions->errorHandler(2, 'pg_query(): Que...', 'C:\\xampp\\htdocs...', 135)
#1 C:\xampp\htdocs\dfpyme\system\Database\Postgre\Connection.php(135): pg_query(Resource id #158, 'INSERT INTO "en...')
#2 C:\xampp\htdocs\dfpyme\system\Database\BaseConnection.php(670): CodeIgniter\Database\Postgre\Connection->execute('INSERT INTO "en...')
#3 C:\xampp\htdocs\dfpyme\system\Database\BaseConnection.php(598): CodeIgniter\Database\BaseConnection->simpleQuery('INSERT INTO "en...')
#4 C:\xampp\htdocs\dfpyme\system\Database\BaseBuilder.php(1771): CodeIgniter\Database\BaseConnection->query('INSERT INTO "en...', Array, false)
#5 C:\xampp\htdocs\dfpyme\system\Model.php(239): CodeIgniter\Database\BaseBuilder->insert()
#6 C:\xampp\htdocs\dfpyme\system\BaseModel.php(738): CodeIgniter\Model->doInsert(Array)
#7 C:\xampp\htdocs\dfpyme\system\Model.php(625): CodeIgniter\BaseModel->insert(Array, true)
#8 C:\xampp\htdocs\dfpyme\app\Controllers\factura_electronica\FacturaElectronica.php(177): CodeIgniter\Model->insert(Array)
#9 C:\xampp\htdocs\dfpyme\system\CodeIgniter.php(832): App\Controllers\factura_electronica\FacturaElectronica->pre_factura()
#10 C:\xampp\htdocs\dfpyme\system\CodeIgniter.php(419): CodeIgniter\CodeIgniter->runController(Object(App\Controllers\factura_electronica\FacturaElectronica))
#11 C:\xampp\htdocs\dfpyme\system\CodeIgniter.php(326): CodeIgniter\CodeIgniter->handleRequest(NULL, Object(Config\Cache), false)
#12 C:\xampp\htdocs\dfpyme\index.php(37): CodeIgniter\CodeIgniter->run()
#13 {main}
CRITICAL - 2025-06-28 14:51:34 --> pg_query(): Query failed: ERROR:  llave duplicada viola restricción de unicidad «pk_entrada_salidas»
DETAIL:  Ya existe la llave (id)=(13).
#0 [internal function]: CodeIgniter\Debug\Exceptions->errorHandler(2, 'pg_query(): Que...', 'C:\\xampp\\htdocs...', 135)
#1 C:\xampp\htdocs\dfpyme\system\Database\Postgre\Connection.php(135): pg_query(Resource id #158, 'INSERT INTO "en...')
#2 C:\xampp\htdocs\dfpyme\system\Database\BaseConnection.php(670): CodeIgniter\Database\Postgre\Connection->execute('INSERT INTO "en...')
#3 C:\xampp\htdocs\dfpyme\system\Database\BaseConnection.php(598): CodeIgniter\Database\BaseConnection->simpleQuery('INSERT INTO "en...')
#4 C:\xampp\htdocs\dfpyme\system\Database\BaseBuilder.php(1771): CodeIgniter\Database\BaseConnection->query('INSERT INTO "en...', Array, false)
#5 C:\xampp\htdocs\dfpyme\system\Model.php(239): CodeIgniter\Database\BaseBuilder->insert()
#6 C:\xampp\htdocs\dfpyme\system\BaseModel.php(738): CodeIgniter\Model->doInsert(Array)
#7 C:\xampp\htdocs\dfpyme\system\Model.php(625): CodeIgniter\BaseModel->insert(Array, true)
#8 C:\xampp\htdocs\dfpyme\app\Controllers\factura_electronica\FacturaElectronica.php(177): CodeIgniter\Model->insert(Array)
#9 C:\xampp\htdocs\dfpyme\system\CodeIgniter.php(832): App\Controllers\factura_electronica\FacturaElectronica->pre_factura()
#10 C:\xampp\htdocs\dfpyme\system\CodeIgniter.php(419): CodeIgniter\CodeIgniter->runController(Object(App\Controllers\factura_electronica\FacturaElectronica))
#11 C:\xampp\htdocs\dfpyme\system\CodeIgniter.php(326): CodeIgniter\CodeIgniter->handleRequest(NULL, Object(Config\Cache), false)
#12 C:\xampp\htdocs\dfpyme\index.php(37): CodeIgniter\CodeIgniter->run()
#13 {main}
CRITICAL - 2025-06-28 14:51:34 --> Uncaught CodeIgniter\Format\Exceptions\FormatException: Failed to parse json string, error: "Type is not supported". in C:\xampp\htdocs\dfpyme\system\Format\JSONFormatter.php:41
Stack trace:
#0 C:\xampp\htdocs\dfpyme\system\Format\JSONFormatter.php(41): CodeIgniter\Format\Exceptions\FormatException::forInvalidJSON('Type is not sup...')
#1 C:\xampp\htdocs\dfpyme\system\API\ResponseTrait.php(341): CodeIgniter\Format\JSONFormatter->format(Array)
#2 C:\xampp\htdocs\dfpyme\system\API\ResponseTrait.php(99): CodeIgniter\Debug\Exceptions->format(Array)
#3 C:\xampp\htdocs\dfpyme\system\Debug\Exceptions.php(115): CodeIgniter\Debug\Exceptions->respond(Array, 500)
#4 [internal function]: CodeIgniter\Debug\Exceptions->exceptionHandler(Object(ErrorException))
#5 {main}
  thrown
#0 [internal function]: CodeIgniter\Debug\Exceptions->shutdownHandler()
#1 {main}
ERROR - 2025-06-28 14:53:13 --> ErrorException: pg_query(): Query failed: ERROR:  el valor null para la columna «fecha_limite» viola la restricción not null
DETAIL:  La fila que falla contiene (9121, 222222222222, f, INVOIC, 01, 10, 2, 1, 9120, 2025-06-28, 14:53:13, null, 0, 11900, 11900, COP, 0, null, 10, null, UBL 2.1, DIAN 2.1, , 1, t, 2025-06-28 14:53:13.4571, 294, 0, , , , null). in C:\xampp\htdocs\dfpyme\system\Database\Postgre\Connection.php:135
Stack trace:
#0 [internal function]: CodeIgniter\Debug\Exceptions->errorHandler(2, 'pg_query(): Que...', 'C:\\xampp\\htdocs...', 135)
#1 C:\xampp\htdocs\dfpyme\system\Database\Postgre\Connection.php(135): pg_query(Resource id #158, 'INSERT INTO "do...')
#2 C:\xampp\htdocs\dfpyme\system\Database\BaseConnection.php(670): CodeIgniter\Database\Postgre\Connection->execute('INSERT INTO "do...')
#3 C:\xampp\htdocs\dfpyme\system\Database\BaseConnection.php(598): CodeIgniter\Database\BaseConnection->simpleQuery('INSERT INTO "do...')
#4 C:\xampp\htdocs\dfpyme\system\Database\BaseBuilder.php(1771): CodeIgniter\Database\BaseConnection->query('INSERT INTO "do...', Array, false)
#5 C:\xampp\htdocs\dfpyme\app\Models\facturaElectronicaModel.php(50): CodeIgniter\Database\BaseBuilder->insert(Array)
#6 C:\xampp\htdocs\dfpyme\app\Controllers\factura_electronica\FacturaElectronica.php(158): App\Models\facturaElectronicaModel->insertar(Array)
#7 C:\xampp\htdocs\dfpyme\system\CodeIgniter.php(832): App\Controllers\factura_electronica\FacturaElectronica->pre_factura()
#8 C:\xampp\htdocs\dfpyme\system\CodeIgniter.php(419): CodeIgniter\CodeIgniter->runController(Object(App\Controllers\factura_electronica\FacturaElectronica))
#9 C:\xampp\htdocs\dfpyme\system\CodeIgniter.php(326): CodeIgniter\CodeIgniter->handleRequest(NULL, Object(Config\Cache), false)
#10 C:\xampp\htdocs\dfpyme\index.php(37): CodeIgniter\CodeIgniter->run()
#11 {main}
CRITICAL - 2025-06-28 14:53:13 --> pg_query(): Query failed: ERROR:  el valor null para la columna «fecha_limite» viola la restricción not null
DETAIL:  La fila que falla contiene (9121, 222222222222, f, INVOIC, 01, 10, 2, 1, 9120, 2025-06-28, 14:53:13, null, 0, 11900, 11900, COP, 0, null, 10, null, UBL 2.1, DIAN 2.1, , 1, t, 2025-06-28 14:53:13.4571, 294, 0, , , , null).
#0 [internal function]: CodeIgniter\Debug\Exceptions->errorHandler(2, 'pg_query(): Que...', 'C:\\xampp\\htdocs...', 135)
#1 C:\xampp\htdocs\dfpyme\system\Database\Postgre\Connection.php(135): pg_query(Resource id #158, 'INSERT INTO "do...')
#2 C:\xampp\htdocs\dfpyme\system\Database\BaseConnection.php(670): CodeIgniter\Database\Postgre\Connection->execute('INSERT INTO "do...')
#3 C:\xampp\htdocs\dfpyme\system\Database\BaseConnection.php(598): CodeIgniter\Database\BaseConnection->simpleQuery('INSERT INTO "do...')
#4 C:\xampp\htdocs\dfpyme\system\Database\BaseBuilder.php(1771): CodeIgniter\Database\BaseConnection->query('INSERT INTO "do...', Array, false)
#5 C:\xampp\htdocs\dfpyme\app\Models\facturaElectronicaModel.php(50): CodeIgniter\Database\BaseBuilder->insert(Array)
#6 C:\xampp\htdocs\dfpyme\app\Controllers\factura_electronica\FacturaElectronica.php(158): App\Models\facturaElectronicaModel->insertar(Array)
#7 C:\xampp\htdocs\dfpyme\system\CodeIgniter.php(832): App\Controllers\factura_electronica\FacturaElectronica->pre_factura()
#8 C:\xampp\htdocs\dfpyme\system\CodeIgniter.php(419): CodeIgniter\CodeIgniter->runController(Object(App\Controllers\factura_electronica\FacturaElectronica))
#9 C:\xampp\htdocs\dfpyme\system\CodeIgniter.php(326): CodeIgniter\CodeIgniter->handleRequest(NULL, Object(Config\Cache), false)
#10 C:\xampp\htdocs\dfpyme\index.php(37): CodeIgniter\CodeIgniter->run()
#11 {main}
ERROR - 2025-06-28 14:53:55 --> ErrorException: pg_query(): Query failed: ERROR:  el valor null para la columna «metodo_pago» viola la restricción not null
DETAIL:  La fila que falla contiene (9122, 222222222222, f, INVOIC, 01, 10, 2, 1, 9121, 2025-06-28, 14:53:55, 2025-06-28, 0, 11900, 11900, COP, 0, null, 10, null, UBL 2.1, DIAN 2.1, , 1, t, 2025-06-28 14:53:55.1615, 294, 0, , , , null). in C:\xampp\htdocs\dfpyme\system\Database\Postgre\Connection.php:135
Stack trace:
#0 [internal function]: CodeIgniter\Debug\Exceptions->errorHandler(2, 'pg_query(): Que...', 'C:\\xampp\\htdocs...', 135)
#1 C:\xampp\htdocs\dfpyme\system\Database\Postgre\Connection.php(135): pg_query(Resource id #158, 'INSERT INTO "do...')
#2 C:\xampp\htdocs\dfpyme\system\Database\BaseConnection.php(670): CodeIgniter\Database\Postgre\Connection->execute('INSERT INTO "do...')
#3 C:\xampp\htdocs\dfpyme\system\Database\BaseConnection.php(598): CodeIgniter\Database\BaseConnection->simpleQuery('INSERT INTO "do...')
#4 C:\xampp\htdocs\dfpyme\system\Database\BaseBuilder.php(1771): CodeIgniter\Database\BaseConnection->query('INSERT INTO "do...', Array, false)
#5 C:\xampp\htdocs\dfpyme\app\Models\facturaElectronicaModel.php(50): CodeIgniter\Database\BaseBuilder->insert(Array)
#6 C:\xampp\htdocs\dfpyme\app\Controllers\factura_electronica\FacturaElectronica.php(159): App\Models\facturaElectronicaModel->insertar(Array)
#7 C:\xampp\htdocs\dfpyme\system\CodeIgniter.php(832): App\Controllers\factura_electronica\FacturaElectronica->pre_factura()
#8 C:\xampp\htdocs\dfpyme\system\CodeIgniter.php(419): CodeIgniter\CodeIgniter->runController(Object(App\Controllers\factura_electronica\FacturaElectronica))
#9 C:\xampp\htdocs\dfpyme\system\CodeIgniter.php(326): CodeIgniter\CodeIgniter->handleRequest(NULL, Object(Config\Cache), false)
#10 C:\xampp\htdocs\dfpyme\index.php(37): CodeIgniter\CodeIgniter->run()
#11 {main}
CRITICAL - 2025-06-28 14:53:55 --> pg_query(): Query failed: ERROR:  el valor null para la columna «metodo_pago» viola la restricción not null
DETAIL:  La fila que falla contiene (9122, 222222222222, f, INVOIC, 01, 10, 2, 1, 9121, 2025-06-28, 14:53:55, 2025-06-28, 0, 11900, 11900, COP, 0, null, 10, null, UBL 2.1, DIAN 2.1, , 1, t, 2025-06-28 14:53:55.1615, 294, 0, , , , null).
#0 [internal function]: CodeIgniter\Debug\Exceptions->errorHandler(2, 'pg_query(): Que...', 'C:\\xampp\\htdocs...', 135)
#1 C:\xampp\htdocs\dfpyme\system\Database\Postgre\Connection.php(135): pg_query(Resource id #158, 'INSERT INTO "do...')
#2 C:\xampp\htdocs\dfpyme\system\Database\BaseConnection.php(670): CodeIgniter\Database\Postgre\Connection->execute('INSERT INTO "do...')
#3 C:\xampp\htdocs\dfpyme\system\Database\BaseConnection.php(598): CodeIgniter\Database\BaseConnection->simpleQuery('INSERT INTO "do...')
#4 C:\xampp\htdocs\dfpyme\system\Database\BaseBuilder.php(1771): CodeIgniter\Database\BaseConnection->query('INSERT INTO "do...', Array, false)
#5 C:\xampp\htdocs\dfpyme\app\Models\facturaElectronicaModel.php(50): CodeIgniter\Database\BaseBuilder->insert(Array)
#6 C:\xampp\htdocs\dfpyme\app\Controllers\factura_electronica\FacturaElectronica.php(159): App\Models\facturaElectronicaModel->insertar(Array)
#7 C:\xampp\htdocs\dfpyme\system\CodeIgniter.php(832): App\Controllers\factura_electronica\FacturaElectronica->pre_factura()
#8 C:\xampp\htdocs\dfpyme\system\CodeIgniter.php(419): CodeIgniter\CodeIgniter->runController(Object(App\Controllers\factura_electronica\FacturaElectronica))
#9 C:\xampp\htdocs\dfpyme\system\CodeIgniter.php(326): CodeIgniter\CodeIgniter->handleRequest(NULL, Object(Config\Cache), false)
#10 C:\xampp\htdocs\dfpyme\index.php(37): CodeIgniter\CodeIgniter->run()
#11 {main}
ERROR - 2025-06-28 14:54:14 --> ErrorException: pg_query(): Query failed: ERROR:  el valor null para la columna «fecha_pago» viola la restricción not null
DETAIL:  La fila que falla contiene (9123, 222222222222, f, INVOIC, 01, 10, 2, 1, 9122, 2025-06-28, 14:54:14, 2025-06-28, 0, 11900, 11900, COP, 0, 1, 10, null, UBL 2.1, DIAN 2.1, , 1, t, 2025-06-28 14:54:14.2936, 294, 0, , , , null). in C:\xampp\htdocs\dfpyme\system\Database\Postgre\Connection.php:135
Stack trace:
#0 [internal function]: CodeIgniter\Debug\Exceptions->errorHandler(2, 'pg_query(): Que...', 'C:\\xampp\\htdocs...', 135)
#1 C:\xampp\htdocs\dfpyme\system\Database\Postgre\Connection.php(135): pg_query(Resource id #158, 'INSERT INTO "do...')
#2 C:\xampp\htdocs\dfpyme\system\Database\BaseConnection.php(670): CodeIgniter\Database\Postgre\Connection->execute('INSERT INTO "do...')
#3 C:\xampp\htdocs\dfpyme\system\Database\BaseConnection.php(598): CodeIgniter\Database\BaseConnection->simpleQuery('INSERT INTO "do...')
#4 C:\xampp\htdocs\dfpyme\system\Database\BaseBuilder.php(1771): CodeIgniter\Database\BaseConnection->query('INSERT INTO "do...', Array, false)
#5 C:\xampp\htdocs\dfpyme\app\Models\facturaElectronicaModel.php(50): CodeIgniter\Database\BaseBuilder->insert(Array)
#6 C:\xampp\htdocs\dfpyme\app\Controllers\factura_electronica\FacturaElectronica.php(160): App\Models\facturaElectronicaModel->insertar(Array)
#7 C:\xampp\htdocs\dfpyme\system\CodeIgniter.php(832): App\Controllers\factura_electronica\FacturaElectronica->pre_factura()
#8 C:\xampp\htdocs\dfpyme\system\CodeIgniter.php(419): CodeIgniter\CodeIgniter->runController(Object(App\Controllers\factura_electronica\FacturaElectronica))
#9 C:\xampp\htdocs\dfpyme\system\CodeIgniter.php(326): CodeIgniter\CodeIgniter->handleRequest(NULL, Object(Config\Cache), false)
#10 C:\xampp\htdocs\dfpyme\index.php(37): CodeIgniter\CodeIgniter->run()
#11 {main}
CRITICAL - 2025-06-28 14:54:14 --> pg_query(): Query failed: ERROR:  el valor null para la columna «fecha_pago» viola la restricción not null
DETAIL:  La fila que falla contiene (9123, 222222222222, f, INVOIC, 01, 10, 2, 1, 9122, 2025-06-28, 14:54:14, 2025-06-28, 0, 11900, 11900, COP, 0, 1, 10, null, UBL 2.1, DIAN 2.1, , 1, t, 2025-06-28 14:54:14.2936, 294, 0, , , , null).
#0 [internal function]: CodeIgniter\Debug\Exceptions->errorHandler(2, 'pg_query(): Que...', 'C:\\xampp\\htdocs...', 135)
#1 C:\xampp\htdocs\dfpyme\system\Database\Postgre\Connection.php(135): pg_query(Resource id #158, 'INSERT INTO "do...')
#2 C:\xampp\htdocs\dfpyme\system\Database\BaseConnection.php(670): CodeIgniter\Database\Postgre\Connection->execute('INSERT INTO "do...')
#3 C:\xampp\htdocs\dfpyme\system\Database\BaseConnection.php(598): CodeIgniter\Database\BaseConnection->simpleQuery('INSERT INTO "do...')
#4 C:\xampp\htdocs\dfpyme\system\Database\BaseBuilder.php(1771): CodeIgniter\Database\BaseConnection->query('INSERT INTO "do...', Array, false)
#5 C:\xampp\htdocs\dfpyme\app\Models\facturaElectronicaModel.php(50): CodeIgniter\Database\BaseBuilder->insert(Array)
#6 C:\xampp\htdocs\dfpyme\app\Controllers\factura_electronica\FacturaElectronica.php(160): App\Models\facturaElectronicaModel->insertar(Array)
#7 C:\xampp\htdocs\dfpyme\system\CodeIgniter.php(832): App\Controllers\factura_electronica\FacturaElectronica->pre_factura()
#8 C:\xampp\htdocs\dfpyme\system\CodeIgniter.php(419): CodeIgniter\CodeIgniter->runController(Object(App\Controllers\factura_electronica\FacturaElectronica))
#9 C:\xampp\htdocs\dfpyme\system\CodeIgniter.php(326): CodeIgniter\CodeIgniter->handleRequest(NULL, Object(Config\Cache), false)
#10 C:\xampp\htdocs\dfpyme\index.php(37): CodeIgniter\CodeIgniter->run()
#11 {main}
ERROR - 2025-06-28 14:54:34 --> ErrorException: pg_query(): Query failed: ERROR:  llave duplicada viola restricción de unicidad «pk_entrada_salidas»
DETAIL:  Ya existe la llave (id)=(14). in C:\xampp\htdocs\dfpyme\system\Database\Postgre\Connection.php:135
Stack trace:
#0 [internal function]: CodeIgniter\Debug\Exceptions->errorHandler(2, 'pg_query(): Que...', 'C:\\xampp\\htdocs...', 135)
#1 C:\xampp\htdocs\dfpyme\system\Database\Postgre\Connection.php(135): pg_query(Resource id #158, 'INSERT INTO "en...')
#2 C:\xampp\htdocs\dfpyme\system\Database\BaseConnection.php(670): CodeIgniter\Database\Postgre\Connection->execute('INSERT INTO "en...')
#3 C:\xampp\htdocs\dfpyme\system\Database\BaseConnection.php(598): CodeIgniter\Database\BaseConnection->simpleQuery('INSERT INTO "en...')
#4 C:\xampp\htdocs\dfpyme\system\Database\BaseBuilder.php(1771): CodeIgniter\Database\BaseConnection->query('INSERT INTO "en...', Array, false)
#5 C:\xampp\htdocs\dfpyme\system\Model.php(239): CodeIgniter\Database\BaseBuilder->insert()
#6 C:\xampp\htdocs\dfpyme\system\BaseModel.php(738): CodeIgniter\Model->doInsert(Array)
#7 C:\xampp\htdocs\dfpyme\system\Model.php(625): CodeIgniter\BaseModel->insert(Array, true)
#8 C:\xampp\htdocs\dfpyme\app\Controllers\factura_electronica\FacturaElectronica.php(179): CodeIgniter\Model->insert(Array)
#9 C:\xampp\htdocs\dfpyme\system\CodeIgniter.php(832): App\Controllers\factura_electronica\FacturaElectronica->pre_factura()
#10 C:\xampp\htdocs\dfpyme\system\CodeIgniter.php(419): CodeIgniter\CodeIgniter->runController(Object(App\Controllers\factura_electronica\FacturaElectronica))
#11 C:\xampp\htdocs\dfpyme\system\CodeIgniter.php(326): CodeIgniter\CodeIgniter->handleRequest(NULL, Object(Config\Cache), false)
#12 C:\xampp\htdocs\dfpyme\index.php(37): CodeIgniter\CodeIgniter->run()
#13 {main}
CRITICAL - 2025-06-28 14:54:34 --> pg_query(): Query failed: ERROR:  llave duplicada viola restricción de unicidad «pk_entrada_salidas»
DETAIL:  Ya existe la llave (id)=(14).
#0 [internal function]: CodeIgniter\Debug\Exceptions->errorHandler(2, 'pg_query(): Que...', 'C:\\xampp\\htdocs...', 135)
#1 C:\xampp\htdocs\dfpyme\system\Database\Postgre\Connection.php(135): pg_query(Resource id #158, 'INSERT INTO "en...')
#2 C:\xampp\htdocs\dfpyme\system\Database\BaseConnection.php(670): CodeIgniter\Database\Postgre\Connection->execute('INSERT INTO "en...')
#3 C:\xampp\htdocs\dfpyme\system\Database\BaseConnection.php(598): CodeIgniter\Database\BaseConnection->simpleQuery('INSERT INTO "en...')
#4 C:\xampp\htdocs\dfpyme\system\Database\BaseBuilder.php(1771): CodeIgniter\Database\BaseConnection->query('INSERT INTO "en...', Array, false)
#5 C:\xampp\htdocs\dfpyme\system\Model.php(239): CodeIgniter\Database\BaseBuilder->insert()
#6 C:\xampp\htdocs\dfpyme\system\BaseModel.php(738): CodeIgniter\Model->doInsert(Array)
#7 C:\xampp\htdocs\dfpyme\system\Model.php(625): CodeIgniter\BaseModel->insert(Array, true)
#8 C:\xampp\htdocs\dfpyme\app\Controllers\factura_electronica\FacturaElectronica.php(179): CodeIgniter\Model->insert(Array)
#9 C:\xampp\htdocs\dfpyme\system\CodeIgniter.php(832): App\Controllers\factura_electronica\FacturaElectronica->pre_factura()
#10 C:\xampp\htdocs\dfpyme\system\CodeIgniter.php(419): CodeIgniter\CodeIgniter->runController(Object(App\Controllers\factura_electronica\FacturaElectronica))
#11 C:\xampp\htdocs\dfpyme\system\CodeIgniter.php(326): CodeIgniter\CodeIgniter->handleRequest(NULL, Object(Config\Cache), false)
#12 C:\xampp\htdocs\dfpyme\index.php(37): CodeIgniter\CodeIgniter->run()
#13 {main}
ERROR - 2025-06-28 14:57:03 --> ErrorException: pg_query(): Query failed: ERROR:  no existe la relación «estado_pago_consumo»
LINE 2: FROM &quot;estado_pago_consumo&quot;
             ^ in C:\xampp\htdocs\dfpyme\system\Database\Postgre\Connection.php:135
Stack trace:
#0 [internal function]: CodeIgniter\Debug\Exceptions->errorHandler(2, 'pg_query(): Que...', 'C:\\xampp\\htdocs...', 135)
#1 C:\xampp\htdocs\dfpyme\system\Database\Postgre\Connection.php(135): pg_query(Resource id #158, 'SELECT "estado"...')
#2 C:\xampp\htdocs\dfpyme\system\Database\BaseConnection.php(670): CodeIgniter\Database\Postgre\Connection->execute('SELECT "estado"...')
#3 C:\xampp\htdocs\dfpyme\system\Database\BaseConnection.php(598): CodeIgniter\Database\BaseConnection->simpleQuery('SELECT "estado"...')
#4 C:\xampp\htdocs\dfpyme\system\Database\BaseBuilder.php(1455): CodeIgniter\Database\BaseConnection->query('SELECT "estado"...', Array, false)
#5 C:\xampp\htdocs\dfpyme\system\Model.php(210): CodeIgniter\Database\BaseBuilder->get()
#6 C:\xampp\htdocs\dfpyme\system\BaseModel.php(622): CodeIgniter\Model->doFirst()
#7 C:\xampp\htdocs\dfpyme\app\Controllers\factura_electronica\FacturaElectronica.php(29): CodeIgniter\BaseModel->first()
#8 C:\xampp\htdocs\dfpyme\system\CodeIgniter.php(832): App\Controllers\factura_electronica\FacturaElectronica->pre_factura()
#9 C:\xampp\htdocs\dfpyme\system\CodeIgniter.php(419): CodeIgniter\CodeIgniter->runController(Object(App\Controllers\factura_electronica\FacturaElectronica))
#10 C:\xampp\htdocs\dfpyme\system\CodeIgniter.php(326): CodeIgniter\CodeIgniter->handleRequest(NULL, Object(Config\Cache), false)
#11 C:\xampp\htdocs\dfpyme\index.php(37): CodeIgniter\CodeIgniter->run()
#12 {main}
CRITICAL - 2025-06-28 14:57:03 --> pg_query(): Query failed: ERROR:  no existe la relación «estado_pago_consumo»
LINE 2: FROM &quot;estado_pago_consumo&quot;
             ^
#0 [internal function]: CodeIgniter\Debug\Exceptions->errorHandler(2, 'pg_query(): Que...', 'C:\\xampp\\htdocs...', 135)
#1 C:\xampp\htdocs\dfpyme\system\Database\Postgre\Connection.php(135): pg_query(Resource id #158, 'SELECT "estado"...')
#2 C:\xampp\htdocs\dfpyme\system\Database\BaseConnection.php(670): CodeIgniter\Database\Postgre\Connection->execute('SELECT "estado"...')
#3 C:\xampp\htdocs\dfpyme\system\Database\BaseConnection.php(598): CodeIgniter\Database\BaseConnection->simpleQuery('SELECT "estado"...')
#4 C:\xampp\htdocs\dfpyme\system\Database\BaseBuilder.php(1455): CodeIgniter\Database\BaseConnection->query('SELECT "estado"...', Array, false)
#5 C:\xampp\htdocs\dfpyme\system\Model.php(210): CodeIgniter\Database\BaseBuilder->get()
#6 C:\xampp\htdocs\dfpyme\system\BaseModel.php(622): CodeIgniter\Model->doFirst()
#7 C:\xampp\htdocs\dfpyme\app\Controllers\factura_electronica\FacturaElectronica.php(29): CodeIgniter\BaseModel->first()
#8 C:\xampp\htdocs\dfpyme\system\CodeIgniter.php(832): App\Controllers\factura_electronica\FacturaElectronica->pre_factura()
#9 C:\xampp\htdocs\dfpyme\system\CodeIgniter.php(419): CodeIgniter\CodeIgniter->runController(Object(App\Controllers\factura_electronica\FacturaElectronica))
#10 C:\xampp\htdocs\dfpyme\system\CodeIgniter.php(326): CodeIgniter\CodeIgniter->handleRequest(NULL, Object(Config\Cache), false)
#11 C:\xampp\htdocs\dfpyme\index.php(37): CodeIgniter\CodeIgniter->run()
#12 {main}
CRITICAL - 2025-06-28 14:57:03 --> Uncaught CodeIgniter\Format\Exceptions\FormatException: Failed to parse json string, error: "Type is not supported". in C:\xampp\htdocs\dfpyme\system\Format\JSONFormatter.php:41
Stack trace:
#0 C:\xampp\htdocs\dfpyme\system\Format\JSONFormatter.php(41): CodeIgniter\Format\Exceptions\FormatException::forInvalidJSON('Type is not sup...')
#1 C:\xampp\htdocs\dfpyme\system\API\ResponseTrait.php(341): CodeIgniter\Format\JSONFormatter->format(Array)
#2 C:\xampp\htdocs\dfpyme\system\API\ResponseTrait.php(99): CodeIgniter\Debug\Exceptions->format(Array)
#3 C:\xampp\htdocs\dfpyme\system\Debug\Exceptions.php(115): CodeIgniter\Debug\Exceptions->respond(Array, 500)
#4 [internal function]: CodeIgniter\Debug\Exceptions->exceptionHandler(Object(ErrorException))
#5 {main}
  thrown
#0 [internal function]: CodeIgniter\Debug\Exceptions->shutdownHandler()
#1 {main}
ERROR - 2025-06-28 22:17:15 --> ErrorException: pg_query(): Query failed: ERROR:  no existe la relación «estado_pago_consumo»
LINE 2: FROM &quot;estado_pago_consumo&quot;
             ^ in C:\xampp\htdocs\dfpyme\system\Database\Postgre\Connection.php:135
Stack trace:
#0 [internal function]: CodeIgniter\Debug\Exceptions->errorHandler(2, 'pg_query(): Que...', 'C:\\xampp\\htdocs...', 135)
#1 C:\xampp\htdocs\dfpyme\system\Database\Postgre\Connection.php(135): pg_query(Resource id #158, 'SELECT "estado"...')
#2 C:\xampp\htdocs\dfpyme\system\Database\BaseConnection.php(670): CodeIgniter\Database\Postgre\Connection->execute('SELECT "estado"...')
#3 C:\xampp\htdocs\dfpyme\system\Database\BaseConnection.php(598): CodeIgniter\Database\BaseConnection->simpleQuery('SELECT "estado"...')
#4 C:\xampp\htdocs\dfpyme\system\Database\BaseBuilder.php(1455): CodeIgniter\Database\BaseConnection->query('SELECT "estado"...', Array, false)
#5 C:\xampp\htdocs\dfpyme\system\Model.php(210): CodeIgniter\Database\BaseBuilder->get()
#6 C:\xampp\htdocs\dfpyme\system\BaseModel.php(622): CodeIgniter\Model->doFirst()
#7 C:\xampp\htdocs\dfpyme\app\Controllers\factura_electronica\FacturaElectronica.php(29): CodeIgniter\BaseModel->first()
#8 C:\xampp\htdocs\dfpyme\system\CodeIgniter.php(832): App\Controllers\factura_electronica\FacturaElectronica->pre_factura()
#9 C:\xampp\htdocs\dfpyme\system\CodeIgniter.php(419): CodeIgniter\CodeIgniter->runController(Object(App\Controllers\factura_electronica\FacturaElectronica))
#10 C:\xampp\htdocs\dfpyme\system\CodeIgniter.php(326): CodeIgniter\CodeIgniter->handleRequest(NULL, Object(Config\Cache), false)
#11 C:\xampp\htdocs\dfpyme\index.php(37): CodeIgniter\CodeIgniter->run()
#12 {main}
CRITICAL - 2025-06-28 22:17:15 --> pg_query(): Query failed: ERROR:  no existe la relación «estado_pago_consumo»
LINE 2: FROM &quot;estado_pago_consumo&quot;
             ^
#0 [internal function]: CodeIgniter\Debug\Exceptions->errorHandler(2, 'pg_query(): Que...', 'C:\\xampp\\htdocs...', 135)
#1 C:\xampp\htdocs\dfpyme\system\Database\Postgre\Connection.php(135): pg_query(Resource id #158, 'SELECT "estado"...')
#2 C:\xampp\htdocs\dfpyme\system\Database\BaseConnection.php(670): CodeIgniter\Database\Postgre\Connection->execute('SELECT "estado"...')
#3 C:\xampp\htdocs\dfpyme\system\Database\BaseConnection.php(598): CodeIgniter\Database\BaseConnection->simpleQuery('SELECT "estado"...')
#4 C:\xampp\htdocs\dfpyme\system\Database\BaseBuilder.php(1455): CodeIgniter\Database\BaseConnection->query('SELECT "estado"...', Array, false)
#5 C:\xampp\htdocs\dfpyme\system\Model.php(210): CodeIgniter\Database\BaseBuilder->get()
#6 C:\xampp\htdocs\dfpyme\system\BaseModel.php(622): CodeIgniter\Model->doFirst()
#7 C:\xampp\htdocs\dfpyme\app\Controllers\factura_electronica\FacturaElectronica.php(29): CodeIgniter\BaseModel->first()
#8 C:\xampp\htdocs\dfpyme\system\CodeIgniter.php(832): App\Controllers\factura_electronica\FacturaElectronica->pre_factura()
#9 C:\xampp\htdocs\dfpyme\system\CodeIgniter.php(419): CodeIgniter\CodeIgniter->runController(Object(App\Controllers\factura_electronica\FacturaElectronica))
#10 C:\xampp\htdocs\dfpyme\system\CodeIgniter.php(326): CodeIgniter\CodeIgniter->handleRequest(NULL, Object(Config\Cache), false)
#11 C:\xampp\htdocs\dfpyme\index.php(37): CodeIgniter\CodeIgniter->run()
#12 {main}
CRITICAL - 2025-06-28 22:17:15 --> Uncaught CodeIgniter\Format\Exceptions\FormatException: Failed to parse json string, error: "Type is not supported". in C:\xampp\htdocs\dfpyme\system\Format\JSONFormatter.php:41
Stack trace:
#0 C:\xampp\htdocs\dfpyme\system\Format\JSONFormatter.php(41): CodeIgniter\Format\Exceptions\FormatException::forInvalidJSON('Type is not sup...')
#1 C:\xampp\htdocs\dfpyme\system\API\ResponseTrait.php(341): CodeIgniter\Format\JSONFormatter->format(Array)
#2 C:\xampp\htdocs\dfpyme\system\API\ResponseTrait.php(99): CodeIgniter\Debug\Exceptions->format(Array)
#3 C:\xampp\htdocs\dfpyme\system\Debug\Exceptions.php(115): CodeIgniter\Debug\Exceptions->respond(Array, 500)
#4 [internal function]: CodeIgniter\Debug\Exceptions->exceptionHandler(Object(ErrorException))
#5 {main}
  thrown
#0 [internal function]: CodeIgniter\Debug\Exceptions->shutdownHandler()
#1 {main}
ERROR - 2025-06-28 22:21:00 --> ErrorException: pg_query(): Query failed: ERROR:  no existe la columna «abreviacion»
LINE 1: SELECT &quot;abreviacion&quot;
               ^ in C:\xampp\htdocs\dfpyme\system\Database\Postgre\Connection.php:135
Stack trace:
#0 [internal function]: CodeIgniter\Debug\Exceptions->errorHandler(2, 'pg_query(): Que...', 'C:\\xampp\\htdocs...', 135)
#1 C:\xampp\htdocs\dfpyme\system\Database\Postgre\Connection.php(135): pg_query(Resource id #148, 'SELECT "abrevia...')
#2 C:\xampp\htdocs\dfpyme\system\Database\BaseConnection.php(670): CodeIgniter\Database\Postgre\Connection->execute('SELECT "abrevia...')
#3 C:\xampp\htdocs\dfpyme\system\Database\BaseConnection.php(598): CodeIgniter\Database\BaseConnection->simpleQuery('SELECT "abrevia...')
#4 C:\xampp\htdocs\dfpyme\system\Database\BaseBuilder.php(1455): CodeIgniter\Database\BaseConnection->query('SELECT "abrevia...', Array, false)
#5 C:\xampp\htdocs\dfpyme\system\Model.php(210): CodeIgniter\Database\BaseBuilder->get()
#6 C:\xampp\htdocs\dfpyme\system\BaseModel.php(622): CodeIgniter\Model->doFirst()
#7 C:\xampp\htdocs\dfpyme\app\Controllers\producto\productoController.php(79): CodeIgniter\BaseModel->first()
#8 C:\xampp\htdocs\dfpyme\system\CodeIgniter.php(832): App\Controllers\producto\productoController->index()
#9 C:\xampp\htdocs\dfpyme\system\CodeIgniter.php(419): CodeIgniter\CodeIgniter->runController(Object(App\Controllers\producto\productoController))
#10 C:\xampp\htdocs\dfpyme\system\CodeIgniter.php(326): CodeIgniter\CodeIgniter->handleRequest(NULL, Object(Config\Cache), false)
#11 C:\xampp\htdocs\dfpyme\index.php(37): CodeIgniter\CodeIgniter->run()
#12 {main}
CRITICAL - 2025-06-28 22:21:00 --> pg_query(): Query failed: ERROR:  no existe la columna «abreviacion»
LINE 1: SELECT &quot;abreviacion&quot;
               ^
#0 [internal function]: CodeIgniter\Debug\Exceptions->errorHandler(2, 'pg_query(): Que...', 'C:\\xampp\\htdocs...', 135)
#1 C:\xampp\htdocs\dfpyme\system\Database\Postgre\Connection.php(135): pg_query(Resource id #148, 'SELECT "abrevia...')
#2 C:\xampp\htdocs\dfpyme\system\Database\BaseConnection.php(670): CodeIgniter\Database\Postgre\Connection->execute('SELECT "abrevia...')
#3 C:\xampp\htdocs\dfpyme\system\Database\BaseConnection.php(598): CodeIgniter\Database\BaseConnection->simpleQuery('SELECT "abrevia...')
#4 C:\xampp\htdocs\dfpyme\system\Database\BaseBuilder.php(1455): CodeIgniter\Database\BaseConnection->query('SELECT "abrevia...', Array, false)
#5 C:\xampp\htdocs\dfpyme\system\Model.php(210): CodeIgniter\Database\BaseBuilder->get()
#6 C:\xampp\htdocs\dfpyme\system\BaseModel.php(622): CodeIgniter\Model->doFirst()
#7 C:\xampp\htdocs\dfpyme\app\Controllers\producto\productoController.php(79): CodeIgniter\BaseModel->first()
#8 C:\xampp\htdocs\dfpyme\system\CodeIgniter.php(832): App\Controllers\producto\productoController->index()
#9 C:\xampp\htdocs\dfpyme\system\CodeIgniter.php(419): CodeIgniter\CodeIgniter->runController(Object(App\Controllers\producto\productoController))
#10 C:\xampp\htdocs\dfpyme\system\CodeIgniter.php(326): CodeIgniter\CodeIgniter->handleRequest(NULL, Object(Config\Cache), false)
#11 C:\xampp\htdocs\dfpyme\index.php(37): CodeIgniter\CodeIgniter->run()
#12 {main}
CRITICAL - 2025-06-28 22:21:00 --> Uncaught CodeIgniter\Format\Exceptions\FormatException: Failed to parse json string, error: "Type is not supported". in C:\xampp\htdocs\dfpyme\system\Format\JSONFormatter.php:41
Stack trace:
#0 C:\xampp\htdocs\dfpyme\system\Format\JSONFormatter.php(41): CodeIgniter\Format\Exceptions\FormatException::forInvalidJSON('Type is not sup...')
#1 C:\xampp\htdocs\dfpyme\system\API\ResponseTrait.php(341): CodeIgniter\Format\JSONFormatter->format(Array)
#2 C:\xampp\htdocs\dfpyme\system\API\ResponseTrait.php(99): CodeIgniter\Debug\Exceptions->format(Array)
#3 C:\xampp\htdocs\dfpyme\system\Debug\Exceptions.php(115): CodeIgniter\Debug\Exceptions->respond(Array, 500)
#4 [internal function]: CodeIgniter\Debug\Exceptions->exceptionHandler(Object(ErrorException))
#5 {main}
  thrown
#0 [internal function]: CodeIgniter\Debug\Exceptions->shutdownHandler()
#1 {main}
CRITICAL - 2025-06-28 22:28:08 --> Undefined variable $totalTime
#0 C:\xampp\htdocs\dfpyme\system\Debug\Toolbar\Views\toolbar.tpl.php(40): CodeIgniter\Debug\Exceptions->errorHandler(2, 'Undefined varia...', 'C:\\xampp\\htdocs...', 40)
#1 C:\xampp\htdocs\dfpyme\system\Debug\Toolbar.php(501): include('C:\\xampp\\htdocs...')
#2 C:\xampp\htdocs\dfpyme\system\Debug\Toolbar.php(464): CodeIgniter\Debug\Toolbar->format(Array, 'html')
#3 C:\xampp\htdocs\dfpyme\app\Config\Events.php(48): CodeIgniter\Debug\Toolbar->respond()
#4 C:\xampp\htdocs\dfpyme\system\Events\Events.php(149): CodeIgniter\Events\Events::Config\{closure}()
#5 C:\xampp\htdocs\dfpyme\system\CodeIgniter.php(308): CodeIgniter\Events\Events::trigger('pre_system')
#6 C:\xampp\htdocs\dfpyme\index.php(37): CodeIgniter\CodeIgniter->run()
#7 {main}
