ERROR - 2025-02-06 08:22:36 --> ErrorException: pg_query(): Query failed: ERROR:  no existe la relación «usuario_sistema»
LINE 2: FROM &quot;usuario_sistema&quot;
             ^ in C:\xampp\htdocs\dfpyme\system\Database\Postgre\Connection.php:135
Stack trace:
#0 [internal function]: CodeIgniter\Debug\Exceptions->errorHandler(2, 'pg_query(): Que...', 'C:\\xampp\\htdocs...', 135)
#1 C:\xampp\htdocs\dfpyme\system\Database\Postgre\Connection.php(135): pg_query(Resource id #148, 'SELECT 1\nFROM "...')
#2 C:\xampp\htdocs\dfpyme\system\Database\BaseConnection.php(670): CodeIgniter\Database\Postgre\Connection->execute('SELECT 1\nFROM "...')
#3 C:\xampp\htdocs\dfpyme\system\Database\BaseConnection.php(598): CodeIgniter\Database\BaseConnection->simpleQuery('SELECT 1\nFROM "...')
#4 C:\xampp\htdocs\dfpyme\system\Database\BaseBuilder.php(1455): CodeIgniter\Database\BaseConnection->query('SELECT 1\nFROM "...', Array, false)
#5 C:\xampp\htdocs\dfpyme\system\Validation\Rules.php(104): CodeIgniter\Database\BaseBuilder->get()
#6 C:\xampp\htdocs\dfpyme\system\Validation\Validation.php(292): CodeIgniter\Validation\Rules->is_not_unique('8888', 'pinusuario_sist...', Array, NULL)
#7 C:\xampp\htdocs\dfpyme\system\Validation\Validation.php(157): CodeIgniter\Validation\Validation->processRules('pin', 'pin', '8888', Array, Array)
#8 C:\xampp\htdocs\dfpyme\system\Controller.php(160): CodeIgniter\Validation\Validation->run()
#9 C:\xampp\htdocs\dfpyme\app\Controllers\login\loginController.php(19): CodeIgniter\Controller->validate(Array)
#10 C:\xampp\htdocs\dfpyme\system\CodeIgniter.php(832): App\Controllers\login\loginController->login()
#11 C:\xampp\htdocs\dfpyme\system\CodeIgniter.php(419): CodeIgniter\CodeIgniter->runController(Object(App\Controllers\login\loginController))
#12 C:\xampp\htdocs\dfpyme\system\CodeIgniter.php(326): CodeIgniter\CodeIgniter->handleRequest(NULL, Object(Config\Cache), false)
#13 C:\xampp\htdocs\dfpyme\index.php(37): CodeIgniter\CodeIgniter->run()
#14 {main}
CRITICAL - 2025-02-06 08:22:36 --> pg_query(): Query failed: ERROR:  no existe la relación «usuario_sistema»
LINE 2: FROM &quot;usuario_sistema&quot;
             ^
#0 [internal function]: CodeIgniter\Debug\Exceptions->errorHandler(2, 'pg_query(): Que...', 'C:\\xampp\\htdocs...', 135)
#1 C:\xampp\htdocs\dfpyme\system\Database\Postgre\Connection.php(135): pg_query(Resource id #148, 'SELECT 1\nFROM "...')
#2 C:\xampp\htdocs\dfpyme\system\Database\BaseConnection.php(670): CodeIgniter\Database\Postgre\Connection->execute('SELECT 1\nFROM "...')
#3 C:\xampp\htdocs\dfpyme\system\Database\BaseConnection.php(598): CodeIgniter\Database\BaseConnection->simpleQuery('SELECT 1\nFROM "...')
#4 C:\xampp\htdocs\dfpyme\system\Database\BaseBuilder.php(1455): CodeIgniter\Database\BaseConnection->query('SELECT 1\nFROM "...', Array, false)
#5 C:\xampp\htdocs\dfpyme\system\Validation\Rules.php(104): CodeIgniter\Database\BaseBuilder->get()
#6 C:\xampp\htdocs\dfpyme\system\Validation\Validation.php(292): CodeIgniter\Validation\Rules->is_not_unique('8888', 'pinusuario_sist...', Array, NULL)
#7 C:\xampp\htdocs\dfpyme\system\Validation\Validation.php(157): CodeIgniter\Validation\Validation->processRules('pin', 'pin', '8888', Array, Array)
#8 C:\xampp\htdocs\dfpyme\system\Controller.php(160): CodeIgniter\Validation\Validation->run()
#9 C:\xampp\htdocs\dfpyme\app\Controllers\login\loginController.php(19): CodeIgniter\Controller->validate(Array)
#10 C:\xampp\htdocs\dfpyme\system\CodeIgniter.php(832): App\Controllers\login\loginController->login()
#11 C:\xampp\htdocs\dfpyme\system\CodeIgniter.php(419): CodeIgniter\CodeIgniter->runController(Object(App\Controllers\login\loginController))
#12 C:\xampp\htdocs\dfpyme\system\CodeIgniter.php(326): CodeIgniter\CodeIgniter->handleRequest(NULL, Object(Config\Cache), false)
#13 C:\xampp\htdocs\dfpyme\index.php(37): CodeIgniter\CodeIgniter->run()
#14 {main}
ERROR - 2025-02-06 08:27:21 --> ErrorException: pg_query(): Query failed: ERROR:  no existe la columna «orden»
LINE 4: ORDER BY &quot;orden&quot; ASC
                 ^ in C:\xampp\htdocs\dfpyme\system\Database\Postgre\Connection.php:135
Stack trace:
#0 [internal function]: CodeIgniter\Debug\Exceptions->errorHandler(2, 'pg_query(): Que...', 'C:\\xampp\\htdocs...', 135)
#1 C:\xampp\htdocs\dfpyme\system\Database\Postgre\Connection.php(135): pg_query(Resource id #157, 'SELECT *\nFROM "...')
#2 C:\xampp\htdocs\dfpyme\system\Database\BaseConnection.php(670): CodeIgniter\Database\Postgre\Connection->execute('SELECT *\nFROM "...')
#3 C:\xampp\htdocs\dfpyme\system\Database\BaseConnection.php(598): CodeIgniter\Database\BaseConnection->simpleQuery('SELECT *\nFROM "...')
#4 C:\xampp\htdocs\dfpyme\system\Database\BaseBuilder.php(1455): CodeIgniter\Database\BaseConnection->query('SELECT *\nFROM "...', Array, false)
#5 C:\xampp\htdocs\dfpyme\system\Model.php(183): CodeIgniter\Database\BaseBuilder->get()
#6 C:\xampp\htdocs\dfpyme\system\BaseModel.php(584): CodeIgniter\Model->doFindAll(0, 0)
#7 C:\xampp\htdocs\dfpyme\app\Controllers\pedidos\Mesas.php(17): CodeIgniter\BaseModel->findAll()
#8 C:\xampp\htdocs\dfpyme\system\CodeIgniter.php(832): App\Controllers\pedidos\Mesas->index()
#9 C:\xampp\htdocs\dfpyme\system\CodeIgniter.php(419): CodeIgniter\CodeIgniter->runController(Object(App\Controllers\pedidos\Mesas))
#10 C:\xampp\htdocs\dfpyme\system\CodeIgniter.php(326): CodeIgniter\CodeIgniter->handleRequest(NULL, Object(Config\Cache), false)
#11 C:\xampp\htdocs\dfpyme\index.php(37): CodeIgniter\CodeIgniter->run()
#12 {main}
CRITICAL - 2025-02-06 08:27:21 --> pg_query(): Query failed: ERROR:  no existe la columna «orden»
LINE 4: ORDER BY &quot;orden&quot; ASC
                 ^
#0 [internal function]: CodeIgniter\Debug\Exceptions->errorHandler(2, 'pg_query(): Que...', 'C:\\xampp\\htdocs...', 135)
#1 C:\xampp\htdocs\dfpyme\system\Database\Postgre\Connection.php(135): pg_query(Resource id #157, 'SELECT *\nFROM "...')
#2 C:\xampp\htdocs\dfpyme\system\Database\BaseConnection.php(670): CodeIgniter\Database\Postgre\Connection->execute('SELECT *\nFROM "...')
#3 C:\xampp\htdocs\dfpyme\system\Database\BaseConnection.php(598): CodeIgniter\Database\BaseConnection->simpleQuery('SELECT *\nFROM "...')
#4 C:\xampp\htdocs\dfpyme\system\Database\BaseBuilder.php(1455): CodeIgniter\Database\BaseConnection->query('SELECT *\nFROM "...', Array, false)
#5 C:\xampp\htdocs\dfpyme\system\Model.php(183): CodeIgniter\Database\BaseBuilder->get()
#6 C:\xampp\htdocs\dfpyme\system\BaseModel.php(584): CodeIgniter\Model->doFindAll(0, 0)
#7 C:\xampp\htdocs\dfpyme\app\Controllers\pedidos\Mesas.php(17): CodeIgniter\BaseModel->findAll()
#8 C:\xampp\htdocs\dfpyme\system\CodeIgniter.php(832): App\Controllers\pedidos\Mesas->index()
#9 C:\xampp\htdocs\dfpyme\system\CodeIgniter.php(419): CodeIgniter\CodeIgniter->runController(Object(App\Controllers\pedidos\Mesas))
#10 C:\xampp\htdocs\dfpyme\system\CodeIgniter.php(326): CodeIgniter\CodeIgniter->handleRequest(NULL, Object(Config\Cache), false)
#11 C:\xampp\htdocs\dfpyme\index.php(37): CodeIgniter\CodeIgniter->run()
#12 {main}
ERROR - 2025-02-06 08:27:49 --> ErrorException: pg_query(): Query failed: ERROR:  no existe la columna «altura»
LINE 1: SELECT &quot;altura&quot;
               ^ in C:\xampp\htdocs\dfpyme\system\Database\Postgre\Connection.php:135
Stack trace:
#0 [internal function]: CodeIgniter\Debug\Exceptions->errorHandler(2, 'pg_query(): Que...', 'C:\\xampp\\htdocs...', 135)
#1 C:\xampp\htdocs\dfpyme\system\Database\Postgre\Connection.php(135): pg_query(Resource id #157, 'SELECT "altura"...')
#2 C:\xampp\htdocs\dfpyme\system\Database\BaseConnection.php(670): CodeIgniter\Database\Postgre\Connection->execute('SELECT "altura"...')
#3 C:\xampp\htdocs\dfpyme\system\Database\BaseConnection.php(598): CodeIgniter\Database\BaseConnection->simpleQuery('SELECT "altura"...')
#4 C:\xampp\htdocs\dfpyme\system\Database\BaseBuilder.php(1455): CodeIgniter\Database\BaseConnection->query('SELECT "altura"...', Array, false)
#5 C:\xampp\htdocs\dfpyme\system\Model.php(210): CodeIgniter\Database\BaseBuilder->get()
#6 C:\xampp\htdocs\dfpyme\system\BaseModel.php(622): CodeIgniter\Model->doFirst()
#7 C:\xampp\htdocs\dfpyme\app\Views\pedidos\mesas.php(165): CodeIgniter\BaseModel->first()
#8 C:\xampp\htdocs\dfpyme\system\View\View.php(210): include('C:\\xampp\\htdocs...')
#9 C:\xampp\htdocs\dfpyme\system\View\View.php(213): CodeIgniter\View\View->CodeIgniter\View\{closure}()
#10 C:\xampp\htdocs\dfpyme\system\Common.php(1089): CodeIgniter\View\View->render('pedidos/mesas', Array, true)
#11 C:\xampp\htdocs\dfpyme\app\Controllers\pedidos\Mesas.php(37): view('pedidos/mesas', Array)
#12 C:\xampp\htdocs\dfpyme\system\CodeIgniter.php(832): App\Controllers\pedidos\Mesas->index()
#13 C:\xampp\htdocs\dfpyme\system\CodeIgniter.php(419): CodeIgniter\CodeIgniter->runController(Object(App\Controllers\pedidos\Mesas))
#14 C:\xampp\htdocs\dfpyme\system\CodeIgniter.php(326): CodeIgniter\CodeIgniter->handleRequest(NULL, Object(Config\Cache), false)
#15 C:\xampp\htdocs\dfpyme\index.php(37): CodeIgniter\CodeIgniter->run()
#16 {main}
CRITICAL - 2025-02-06 08:27:49 --> pg_query(): Query failed: ERROR:  no existe la columna «altura»
LINE 1: SELECT &quot;altura&quot;
               ^
#0 [internal function]: CodeIgniter\Debug\Exceptions->errorHandler(2, 'pg_query(): Que...', 'C:\\xampp\\htdocs...', 135)
#1 C:\xampp\htdocs\dfpyme\system\Database\Postgre\Connection.php(135): pg_query(Resource id #157, 'SELECT "altura"...')
#2 C:\xampp\htdocs\dfpyme\system\Database\BaseConnection.php(670): CodeIgniter\Database\Postgre\Connection->execute('SELECT "altura"...')
#3 C:\xampp\htdocs\dfpyme\system\Database\BaseConnection.php(598): CodeIgniter\Database\BaseConnection->simpleQuery('SELECT "altura"...')
#4 C:\xampp\htdocs\dfpyme\system\Database\BaseBuilder.php(1455): CodeIgniter\Database\BaseConnection->query('SELECT "altura"...', Array, false)
#5 C:\xampp\htdocs\dfpyme\system\Model.php(210): CodeIgniter\Database\BaseBuilder->get()
#6 C:\xampp\htdocs\dfpyme\system\BaseModel.php(622): CodeIgniter\Model->doFirst()
#7 C:\xampp\htdocs\dfpyme\app\Views\pedidos\mesas.php(165): CodeIgniter\BaseModel->first()
#8 C:\xampp\htdocs\dfpyme\system\View\View.php(210): include('C:\\xampp\\htdocs...')
#9 C:\xampp\htdocs\dfpyme\system\View\View.php(213): CodeIgniter\View\View->CodeIgniter\View\{closure}()
#10 C:\xampp\htdocs\dfpyme\system\Common.php(1089): CodeIgniter\View\View->render('pedidos/mesas', Array, true)
#11 C:\xampp\htdocs\dfpyme\app\Controllers\pedidos\Mesas.php(37): view('pedidos/mesas', Array)
#12 C:\xampp\htdocs\dfpyme\system\CodeIgniter.php(832): App\Controllers\pedidos\Mesas->index()
#13 C:\xampp\htdocs\dfpyme\system\CodeIgniter.php(419): CodeIgniter\CodeIgniter->runController(Object(App\Controllers\pedidos\Mesas))
#14 C:\xampp\htdocs\dfpyme\system\CodeIgniter.php(326): CodeIgniter\CodeIgniter->handleRequest(NULL, Object(Config\Cache), false)
#15 C:\xampp\htdocs\dfpyme\index.php(37): CodeIgniter\CodeIgniter->run()
#16 {main}
CRITICAL - 2025-02-06 08:28:37 --> Undefined array key "nombre_comercial"
#0 C:\xampp\htdocs\dfpyme\app\Views\pedidos\modal_finaliza_venta.php(124): CodeIgniter\Debug\Exceptions->errorHandler(2, 'Undefined array...', 'C:\\xampp\\htdocs...', 124)
#1 C:\xampp\htdocs\dfpyme\system\View\View.php(210): include('C:\\xampp\\htdocs...')
#2 C:\xampp\htdocs\dfpyme\system\View\View.php(213): CodeIgniter\View\View->CodeIgniter\View\{closure}()
#3 C:\xampp\htdocs\dfpyme\system\View\View.php(424): CodeIgniter\View\View->render('pedidos/modal_f...', NULL, true)
#4 C:\xampp\htdocs\dfpyme\app\Views\pedidos\template_mesa.php(124): CodeIgniter\View\View->include('pedidos/modal_f...')
#5 C:\xampp\htdocs\dfpyme\system\View\View.php(210): include('C:\\xampp\\htdocs...')
#6 C:\xampp\htdocs\dfpyme\system\View\View.php(213): CodeIgniter\View\View->CodeIgniter\View\{closure}()
#7 C:\xampp\htdocs\dfpyme\system\View\View.php(226): CodeIgniter\View\View->render('pedidos/templat...', Array, true)
#8 C:\xampp\htdocs\dfpyme\system\Common.php(1089): CodeIgniter\View\View->render('pedidos/mesas', Array, true)
#9 C:\xampp\htdocs\dfpyme\app\Controllers\pedidos\Mesas.php(37): view('pedidos/mesas', Array)
#10 C:\xampp\htdocs\dfpyme\system\CodeIgniter.php(832): App\Controllers\pedidos\Mesas->index()
#11 C:\xampp\htdocs\dfpyme\system\CodeIgniter.php(419): CodeIgniter\CodeIgniter->runController(Object(App\Controllers\pedidos\Mesas))
#12 C:\xampp\htdocs\dfpyme\system\CodeIgniter.php(326): CodeIgniter\CodeIgniter->handleRequest(NULL, Object(Config\Cache), false)
#13 C:\xampp\htdocs\dfpyme\index.php(37): CodeIgniter\CodeIgniter->run()
#14 {main}
CRITICAL - 2025-02-06 12:53:49 --> Too few arguments to function App\Models\productoPedidoModel::insertar(), 8 passed in C:\xampp\htdocs\dfpyme\app\Controllers\pedidos\Mesas.php on line 518 and exactly 9 expected
#0 C:\xampp\htdocs\dfpyme\app\Controllers\pedidos\Mesas.php(518): App\Models\productoPedidoModel->insertar(7759, '14000', 't', '7', '43', '', '2025-02-06', '12:02:53')
#1 C:\xampp\htdocs\dfpyme\system\CodeIgniter.php(832): App\Controllers\pedidos\Mesas->agregar_producto()
#2 C:\xampp\htdocs\dfpyme\system\CodeIgniter.php(419): CodeIgniter\CodeIgniter->runController(Object(App\Controllers\pedidos\Mesas))
#3 C:\xampp\htdocs\dfpyme\system\CodeIgniter.php(326): CodeIgniter\CodeIgniter->handleRequest(NULL, Object(Config\Cache), false)
#4 C:\xampp\htdocs\dfpyme\index.php(37): CodeIgniter\CodeIgniter->run()
#5 {main}
CRITICAL - 2025-02-06 12:55:41 --> Too few arguments to function App\Models\productoPedidoModel::insertar(), 8 passed in C:\xampp\htdocs\dfpyme\app\Controllers\pedidos\Mesas.php on line 518 and exactly 9 expected
#0 C:\xampp\htdocs\dfpyme\app\Controllers\pedidos\Mesas.php(518): App\Models\productoPedidoModel->insertar(7760, '8000', 'f', '8', '159', '', '2025-02-06', '12:02:55')
#1 C:\xampp\htdocs\dfpyme\system\CodeIgniter.php(832): App\Controllers\pedidos\Mesas->agregar_producto()
#2 C:\xampp\htdocs\dfpyme\system\CodeIgniter.php(419): CodeIgniter\CodeIgniter->runController(Object(App\Controllers\pedidos\Mesas))
#3 C:\xampp\htdocs\dfpyme\system\CodeIgniter.php(326): CodeIgniter\CodeIgniter->handleRequest(NULL, Object(Config\Cache), false)
#4 C:\xampp\htdocs\dfpyme\index.php(37): CodeIgniter\CodeIgniter->run()
#5 {main}
CRITICAL - 2025-02-06 12:59:53 --> Too few arguments to function App\Models\productoPedidoModel::insertar(), 8 passed in C:\xampp\htdocs\dfpyme\app\Controllers\pedidos\Mesas.php on line 518 and exactly 9 expected
#0 C:\xampp\htdocs\dfpyme\app\Controllers\pedidos\Mesas.php(518): App\Models\productoPedidoModel->insertar(7761, '8000', 'f', '8', '159', '', '2025-02-06', '12:02:59')
#1 C:\xampp\htdocs\dfpyme\system\CodeIgniter.php(832): App\Controllers\pedidos\Mesas->agregar_producto()
#2 C:\xampp\htdocs\dfpyme\system\CodeIgniter.php(419): CodeIgniter\CodeIgniter->runController(Object(App\Controllers\pedidos\Mesas))
#3 C:\xampp\htdocs\dfpyme\system\CodeIgniter.php(326): CodeIgniter\CodeIgniter->handleRequest(NULL, Object(Config\Cache), false)
#4 C:\xampp\htdocs\dfpyme\index.php(37): CodeIgniter\CodeIgniter->run()
#5 {main}
CRITICAL - 2025-02-06 13:08:15 --> Undefined variable $id_mesa
#0 C:\xampp\htdocs\dfpyme\app\Controllers\pedidos\Mesas.php(469): CodeIgniter\Debug\Exceptions->errorHandler(2, 'Undefined varia...', 'C:\\xampp\\htdocs...', 469)
#1 C:\xampp\htdocs\dfpyme\system\CodeIgniter.php(832): App\Controllers\pedidos\Mesas->agregar_producto()
#2 C:\xampp\htdocs\dfpyme\system\CodeIgniter.php(419): CodeIgniter\CodeIgniter->runController(Object(App\Controllers\pedidos\Mesas))
#3 C:\xampp\htdocs\dfpyme\system\CodeIgniter.php(326): CodeIgniter\CodeIgniter->handleRequest(NULL, Object(Config\Cache), false)
#4 C:\xampp\htdocs\dfpyme\index.php(37): CodeIgniter\CodeIgniter->run()
#5 {main}
CRITICAL - 2025-02-06 13:09:05 --> Trying to access array offset on value of type null
#0 C:\xampp\htdocs\dfpyme\app\Controllers\pedidos\Mesas.php(484): CodeIgniter\Debug\Exceptions->errorHandler(2, 'Trying to acces...', 'C:\\xampp\\htdocs...', 484)
#1 C:\xampp\htdocs\dfpyme\system\CodeIgniter.php(832): App\Controllers\pedidos\Mesas->agregar_producto()
#2 C:\xampp\htdocs\dfpyme\system\CodeIgniter.php(419): CodeIgniter\CodeIgniter->runController(Object(App\Controllers\pedidos\Mesas))
#3 C:\xampp\htdocs\dfpyme\system\CodeIgniter.php(326): CodeIgniter\CodeIgniter->handleRequest(NULL, Object(Config\Cache), false)
#4 C:\xampp\htdocs\dfpyme\index.php(37): CodeIgniter\CodeIgniter->run()
#5 {main}
CRITICAL - 2025-02-06 13:09:53 --> Trying to access array offset on value of type null
#0 C:\xampp\htdocs\dfpyme\app\Controllers\pedidos\Mesas.php(484): CodeIgniter\Debug\Exceptions->errorHandler(2, 'Trying to acces...', 'C:\\xampp\\htdocs...', 484)
#1 C:\xampp\htdocs\dfpyme\system\CodeIgniter.php(832): App\Controllers\pedidos\Mesas->agregar_producto()
#2 C:\xampp\htdocs\dfpyme\system\CodeIgniter.php(419): CodeIgniter\CodeIgniter->runController(Object(App\Controllers\pedidos\Mesas))
#3 C:\xampp\htdocs\dfpyme\system\CodeIgniter.php(326): CodeIgniter\CodeIgniter->handleRequest(NULL, Object(Config\Cache), false)
#4 C:\xampp\htdocs\dfpyme\index.php(37): CodeIgniter\CodeIgniter->run()
#5 {main}
CRITICAL - 2025-02-06 13:10:40 --> Too few arguments to function App\Models\productoPedidoModel::insertar(), 8 passed in C:\xampp\htdocs\dfpyme\app\Controllers\pedidos\Mesas.php on line 522 and exactly 9 expected
#0 C:\xampp\htdocs\dfpyme\app\Controllers\pedidos\Mesas.php(522): App\Models\productoPedidoModel->insertar(7762, '20000', 't', '1', '1', NULL, '2025-02-06', '13:02:10')
#1 C:\xampp\htdocs\dfpyme\system\CodeIgniter.php(832): App\Controllers\pedidos\Mesas->agregar_producto()
#2 C:\xampp\htdocs\dfpyme\system\CodeIgniter.php(419): CodeIgniter\CodeIgniter->runController(Object(App\Controllers\pedidos\Mesas))
#3 C:\xampp\htdocs\dfpyme\system\CodeIgniter.php(326): CodeIgniter\CodeIgniter->handleRequest(NULL, Object(Config\Cache), false)
#4 C:\xampp\htdocs\dfpyme\index.php(37): CodeIgniter\CodeIgniter->run()
#5 {main}
CRITICAL - 2025-02-06 13:13:14 --> Too few arguments to function App\Models\productoPedidoModel::insertar(), 8 passed in C:\xampp\htdocs\dfpyme\app\Controllers\pedidos\Mesas.php on line 522 and exactly 9 expected
#0 C:\xampp\htdocs\dfpyme\app\Controllers\pedidos\Mesas.php(522): App\Models\productoPedidoModel->insertar(7763, '20000', 't', '1', '1', NULL, '2025-02-06', '13:02:13')
#1 C:\xampp\htdocs\dfpyme\system\CodeIgniter.php(832): App\Controllers\pedidos\Mesas->agregar_producto()
#2 C:\xampp\htdocs\dfpyme\system\CodeIgniter.php(419): CodeIgniter\CodeIgniter->runController(Object(App\Controllers\pedidos\Mesas))
#3 C:\xampp\htdocs\dfpyme\system\CodeIgniter.php(326): CodeIgniter\CodeIgniter->handleRequest(NULL, Object(Config\Cache), false)
#4 C:\xampp\htdocs\dfpyme\index.php(37): CodeIgniter\CodeIgniter->run()
#5 {main}
CRITICAL - 2025-02-06 13:17:54 --> Too few arguments to function App\Models\productoPedidoModel::insertar(), 8 passed in C:\xampp\htdocs\dfpyme\app\Controllers\pedidos\Mesas.php on line 522 and exactly 9 expected
#0 C:\xampp\htdocs\dfpyme\app\Controllers\pedidos\Mesas.php(522): App\Models\productoPedidoModel->insertar(0, '20000', 't', '1', '1', NULL, '2025-02-06', '13:02:17')
#1 C:\xampp\htdocs\dfpyme\system\CodeIgniter.php(832): App\Controllers\pedidos\Mesas->agregar_producto()
#2 C:\xampp\htdocs\dfpyme\system\CodeIgniter.php(419): CodeIgniter\CodeIgniter->runController(Object(App\Controllers\pedidos\Mesas))
#3 C:\xampp\htdocs\dfpyme\system\CodeIgniter.php(326): CodeIgniter\CodeIgniter->handleRequest(NULL, Object(Config\Cache), false)
#4 C:\xampp\htdocs\dfpyme\index.php(37): CodeIgniter\CodeIgniter->run()
#5 {main}
CRITICAL - 2025-02-06 13:18:07 --> Too few arguments to function App\Models\productoPedidoModel::insertar(), 7 passed in C:\xampp\htdocs\dfpyme\app\Controllers\pedidos\Mesas.php on line 521 and exactly 9 expected
#0 C:\xampp\htdocs\dfpyme\app\Controllers\pedidos\Mesas.php(521): App\Models\productoPedidoModel->insertar(0, '20000', 't', '1', '1', NULL, '2025-02-06')
#1 C:\xampp\htdocs\dfpyme\system\CodeIgniter.php(832): App\Controllers\pedidos\Mesas->agregar_producto()
#2 C:\xampp\htdocs\dfpyme\system\CodeIgniter.php(419): CodeIgniter\CodeIgniter->runController(Object(App\Controllers\pedidos\Mesas))
#3 C:\xampp\htdocs\dfpyme\system\CodeIgniter.php(326): CodeIgniter\CodeIgniter->handleRequest(NULL, Object(Config\Cache), false)
#4 C:\xampp\htdocs\dfpyme\index.php(37): CodeIgniter\CodeIgniter->run()
#5 {main}
CRITICAL - 2025-02-06 13:18:17 --> Too few arguments to function App\Models\productoPedidoModel::insertar(), 5 passed in C:\xampp\htdocs\dfpyme\app\Controllers\pedidos\Mesas.php on line 519 and exactly 9 expected
#0 C:\xampp\htdocs\dfpyme\app\Controllers\pedidos\Mesas.php(519): App\Models\productoPedidoModel->insertar(0, '20000', 't', '1', '1')
#1 C:\xampp\htdocs\dfpyme\system\CodeIgniter.php(832): App\Controllers\pedidos\Mesas->agregar_producto()
#2 C:\xampp\htdocs\dfpyme\system\CodeIgniter.php(419): CodeIgniter\CodeIgniter->runController(Object(App\Controllers\pedidos\Mesas))
#3 C:\xampp\htdocs\dfpyme\system\CodeIgniter.php(326): CodeIgniter\CodeIgniter->handleRequest(NULL, Object(Config\Cache), false)
#4 C:\xampp\htdocs\dfpyme\index.php(37): CodeIgniter\CodeIgniter->run()
#5 {main}
ERROR - 2025-02-06 13:22:20 --> ErrorException: pg_query(): Query failed: ERROR:  no existe la columna «idUser» en la relación «producto_pedido»
LINE 1: ...roducto&quot;, &quot;numero_productos_impresos_en_comanda&quot;, &quot;idUser&quot;, ...
                                                             ^ in C:\xampp\htdocs\dfpyme\system\Database\Postgre\Connection.php:135
Stack trace:
#0 [internal function]: CodeIgniter\Debug\Exceptions->errorHandler(2, 'pg_query(): Que...', 'C:\\xampp\\htdocs...', 135)
#1 C:\xampp\htdocs\dfpyme\system\Database\Postgre\Connection.php(135): pg_query(Resource id #158, 'INSERT INTO "pr...')
#2 C:\xampp\htdocs\dfpyme\system\Database\BaseConnection.php(670): CodeIgniter\Database\Postgre\Connection->execute('INSERT INTO "pr...')
#3 C:\xampp\htdocs\dfpyme\system\Database\BaseConnection.php(598): CodeIgniter\Database\BaseConnection->simpleQuery('INSERT INTO "pr...')
#4 C:\xampp\htdocs\dfpyme\system\Database\BaseBuilder.php(1771): CodeIgniter\Database\BaseConnection->query('INSERT INTO "pr...', Array, false)
#5 C:\xampp\htdocs\dfpyme\app\Models\productoPedidoModel.php(550): CodeIgniter\Database\BaseBuilder->insert(Array)
#6 C:\xampp\htdocs\dfpyme\app\Controllers\pedidos\Mesas.php(523): App\Models\productoPedidoModel->insertar(0, '20000', 't', '1', '1', 1, NULL, '2025-02-06', '13:02:22')
#7 C:\xampp\htdocs\dfpyme\system\CodeIgniter.php(832): App\Controllers\pedidos\Mesas->agregar_producto()
#8 C:\xampp\htdocs\dfpyme\system\CodeIgniter.php(419): CodeIgniter\CodeIgniter->runController(Object(App\Controllers\pedidos\Mesas))
#9 C:\xampp\htdocs\dfpyme\system\CodeIgniter.php(326): CodeIgniter\CodeIgniter->handleRequest(NULL, Object(Config\Cache), false)
#10 C:\xampp\htdocs\dfpyme\index.php(37): CodeIgniter\CodeIgniter->run()
#11 {main}
CRITICAL - 2025-02-06 13:22:20 --> pg_query(): Query failed: ERROR:  no existe la columna «idUser» en la relación «producto_pedido»
LINE 1: ...roducto&quot;, &quot;numero_productos_impresos_en_comanda&quot;, &quot;idUser&quot;, ...
                                                             ^
#0 [internal function]: CodeIgniter\Debug\Exceptions->errorHandler(2, 'pg_query(): Que...', 'C:\\xampp\\htdocs...', 135)
#1 C:\xampp\htdocs\dfpyme\system\Database\Postgre\Connection.php(135): pg_query(Resource id #158, 'INSERT INTO "pr...')
#2 C:\xampp\htdocs\dfpyme\system\Database\BaseConnection.php(670): CodeIgniter\Database\Postgre\Connection->execute('INSERT INTO "pr...')
#3 C:\xampp\htdocs\dfpyme\system\Database\BaseConnection.php(598): CodeIgniter\Database\BaseConnection->simpleQuery('INSERT INTO "pr...')
#4 C:\xampp\htdocs\dfpyme\system\Database\BaseBuilder.php(1771): CodeIgniter\Database\BaseConnection->query('INSERT INTO "pr...', Array, false)
#5 C:\xampp\htdocs\dfpyme\app\Models\productoPedidoModel.php(550): CodeIgniter\Database\BaseBuilder->insert(Array)
#6 C:\xampp\htdocs\dfpyme\app\Controllers\pedidos\Mesas.php(523): App\Models\productoPedidoModel->insertar(0, '20000', 't', '1', '1', 1, NULL, '2025-02-06', '13:02:22')
#7 C:\xampp\htdocs\dfpyme\system\CodeIgniter.php(832): App\Controllers\pedidos\Mesas->agregar_producto()
#8 C:\xampp\htdocs\dfpyme\system\CodeIgniter.php(419): CodeIgniter\CodeIgniter->runController(Object(App\Controllers\pedidos\Mesas))
#9 C:\xampp\htdocs\dfpyme\system\CodeIgniter.php(326): CodeIgniter\CodeIgniter->handleRequest(NULL, Object(Config\Cache), false)
#10 C:\xampp\htdocs\dfpyme\index.php(37): CodeIgniter\CodeIgniter->run()
#11 {main}
ERROR - 2025-02-06 13:22:58 --> ErrorException: pg_query(): Query failed: ERROR:  inserción o actualización en la tabla «producto_pedido» viola la llave foránea «fk_pedido»
DETAIL:  La llave (numero_de_pedido)=(0) no está presente en la tabla «pedido». in C:\xampp\htdocs\dfpyme\system\Database\Postgre\Connection.php:135
Stack trace:
#0 [internal function]: CodeIgniter\Debug\Exceptions->errorHandler(2, 'pg_query(): Que...', 'C:\\xampp\\htdocs...', 135)
#1 C:\xampp\htdocs\dfpyme\system\Database\Postgre\Connection.php(135): pg_query(Resource id #157, 'INSERT INTO "pr...')
#2 C:\xampp\htdocs\dfpyme\system\Database\BaseConnection.php(670): CodeIgniter\Database\Postgre\Connection->execute('INSERT INTO "pr...')
#3 C:\xampp\htdocs\dfpyme\system\Database\BaseConnection.php(598): CodeIgniter\Database\BaseConnection->simpleQuery('INSERT INTO "pr...')
#4 C:\xampp\htdocs\dfpyme\system\Database\BaseBuilder.php(1771): CodeIgniter\Database\BaseConnection->query('INSERT INTO "pr...', Array, false)
#5 C:\xampp\htdocs\dfpyme\app\Models\productoPedidoModel.php(550): CodeIgniter\Database\BaseBuilder->insert(Array)
#6 C:\xampp\htdocs\dfpyme\app\Controllers\pedidos\Mesas.php(523): App\Models\productoPedidoModel->insertar(0, '20000', 't', '1', '1', 1, NULL, '2025-02-06', '13:02:22')
#7 C:\xampp\htdocs\dfpyme\system\CodeIgniter.php(832): App\Controllers\pedidos\Mesas->agregar_producto()
#8 C:\xampp\htdocs\dfpyme\system\CodeIgniter.php(419): CodeIgniter\CodeIgniter->runController(Object(App\Controllers\pedidos\Mesas))
#9 C:\xampp\htdocs\dfpyme\system\CodeIgniter.php(326): CodeIgniter\CodeIgniter->handleRequest(NULL, Object(Config\Cache), false)
#10 C:\xampp\htdocs\dfpyme\index.php(37): CodeIgniter\CodeIgniter->run()
#11 {main}
CRITICAL - 2025-02-06 13:22:58 --> pg_query(): Query failed: ERROR:  inserción o actualización en la tabla «producto_pedido» viola la llave foránea «fk_pedido»
DETAIL:  La llave (numero_de_pedido)=(0) no está presente en la tabla «pedido».
#0 [internal function]: CodeIgniter\Debug\Exceptions->errorHandler(2, 'pg_query(): Que...', 'C:\\xampp\\htdocs...', 135)
#1 C:\xampp\htdocs\dfpyme\system\Database\Postgre\Connection.php(135): pg_query(Resource id #157, 'INSERT INTO "pr...')
#2 C:\xampp\htdocs\dfpyme\system\Database\BaseConnection.php(670): CodeIgniter\Database\Postgre\Connection->execute('INSERT INTO "pr...')
#3 C:\xampp\htdocs\dfpyme\system\Database\BaseConnection.php(598): CodeIgniter\Database\BaseConnection->simpleQuery('INSERT INTO "pr...')
#4 C:\xampp\htdocs\dfpyme\system\Database\BaseBuilder.php(1771): CodeIgniter\Database\BaseConnection->query('INSERT INTO "pr...', Array, false)
#5 C:\xampp\htdocs\dfpyme\app\Models\productoPedidoModel.php(550): CodeIgniter\Database\BaseBuilder->insert(Array)
#6 C:\xampp\htdocs\dfpyme\app\Controllers\pedidos\Mesas.php(523): App\Models\productoPedidoModel->insertar(0, '20000', 't', '1', '1', 1, NULL, '2025-02-06', '13:02:22')
#7 C:\xampp\htdocs\dfpyme\system\CodeIgniter.php(832): App\Controllers\pedidos\Mesas->agregar_producto()
#8 C:\xampp\htdocs\dfpyme\system\CodeIgniter.php(419): CodeIgniter\CodeIgniter->runController(Object(App\Controllers\pedidos\Mesas))
#9 C:\xampp\htdocs\dfpyme\system\CodeIgniter.php(326): CodeIgniter\CodeIgniter->handleRequest(NULL, Object(Config\Cache), false)
#10 C:\xampp\htdocs\dfpyme\index.php(37): CodeIgniter\CodeIgniter->run()
#11 {main}
ERROR - 2025-02-06 13:23:27 --> ErrorException: pg_query(): Query failed: ERROR:  inserción o actualización en la tabla «producto_pedido» viola la llave foránea «fk_pedido»
DETAIL:  La llave (numero_de_pedido)=(0) no está presente en la tabla «pedido». in C:\xampp\htdocs\dfpyme\system\Database\Postgre\Connection.php:135
Stack trace:
#0 [internal function]: CodeIgniter\Debug\Exceptions->errorHandler(2, 'pg_query(): Que...', 'C:\\xampp\\htdocs...', 135)
#1 C:\xampp\htdocs\dfpyme\system\Database\Postgre\Connection.php(135): pg_query(Resource id #157, 'INSERT INTO "pr...')
#2 C:\xampp\htdocs\dfpyme\system\Database\BaseConnection.php(670): CodeIgniter\Database\Postgre\Connection->execute('INSERT INTO "pr...')
#3 C:\xampp\htdocs\dfpyme\system\Database\BaseConnection.php(598): CodeIgniter\Database\BaseConnection->simpleQuery('INSERT INTO "pr...')
#4 C:\xampp\htdocs\dfpyme\system\Database\BaseBuilder.php(1771): CodeIgniter\Database\BaseConnection->query('INSERT INTO "pr...', Array, false)
#5 C:\xampp\htdocs\dfpyme\app\Models\productoPedidoModel.php(550): CodeIgniter\Database\BaseBuilder->insert(Array)
#6 C:\xampp\htdocs\dfpyme\app\Controllers\pedidos\Mesas.php(523): App\Models\productoPedidoModel->insertar(0, '20000', 't', '1', '1', 1, NULL, '2025-02-06', '13:02:23')
#7 C:\xampp\htdocs\dfpyme\system\CodeIgniter.php(832): App\Controllers\pedidos\Mesas->agregar_producto()
#8 C:\xampp\htdocs\dfpyme\system\CodeIgniter.php(419): CodeIgniter\CodeIgniter->runController(Object(App\Controllers\pedidos\Mesas))
#9 C:\xampp\htdocs\dfpyme\system\CodeIgniter.php(326): CodeIgniter\CodeIgniter->handleRequest(NULL, Object(Config\Cache), false)
#10 C:\xampp\htdocs\dfpyme\index.php(37): CodeIgniter\CodeIgniter->run()
#11 {main}
CRITICAL - 2025-02-06 13:23:27 --> pg_query(): Query failed: ERROR:  inserción o actualización en la tabla «producto_pedido» viola la llave foránea «fk_pedido»
DETAIL:  La llave (numero_de_pedido)=(0) no está presente en la tabla «pedido».
#0 [internal function]: CodeIgniter\Debug\Exceptions->errorHandler(2, 'pg_query(): Que...', 'C:\\xampp\\htdocs...', 135)
#1 C:\xampp\htdocs\dfpyme\system\Database\Postgre\Connection.php(135): pg_query(Resource id #157, 'INSERT INTO "pr...')
#2 C:\xampp\htdocs\dfpyme\system\Database\BaseConnection.php(670): CodeIgniter\Database\Postgre\Connection->execute('INSERT INTO "pr...')
#3 C:\xampp\htdocs\dfpyme\system\Database\BaseConnection.php(598): CodeIgniter\Database\BaseConnection->simpleQuery('INSERT INTO "pr...')
#4 C:\xampp\htdocs\dfpyme\system\Database\BaseBuilder.php(1771): CodeIgniter\Database\BaseConnection->query('INSERT INTO "pr...', Array, false)
#5 C:\xampp\htdocs\dfpyme\app\Models\productoPedidoModel.php(550): CodeIgniter\Database\BaseBuilder->insert(Array)
#6 C:\xampp\htdocs\dfpyme\app\Controllers\pedidos\Mesas.php(523): App\Models\productoPedidoModel->insertar(0, '20000', 't', '1', '1', 1, NULL, '2025-02-06', '13:02:23')
#7 C:\xampp\htdocs\dfpyme\system\CodeIgniter.php(832): App\Controllers\pedidos\Mesas->agregar_producto()
#8 C:\xampp\htdocs\dfpyme\system\CodeIgniter.php(419): CodeIgniter\CodeIgniter->runController(Object(App\Controllers\pedidos\Mesas))
#9 C:\xampp\htdocs\dfpyme\system\CodeIgniter.php(326): CodeIgniter\CodeIgniter->handleRequest(NULL, Object(Config\Cache), false)
#10 C:\xampp\htdocs\dfpyme\index.php(37): CodeIgniter\CodeIgniter->run()
#11 {main}
